2024-05-21 12:00:13,935 - INFO - Le processus commencera dans 3 secondes.
2024-05-21 12:00:19,101 - INFO - Fermeture de Google Chrome...
2024-05-21 12:00:24,150 - INFO - Google Chrome est fermé.
2024-05-21 12:00:24,151 - INFO - Running open_bumble.py...
2024-05-21 12:00:24,160 - INFO - Waiting for session to be ready...
2024-05-21 12:00:24,161 - INFO - Session is ready. Starting extraction and evaluation process...
2024-05-21 12:00:34,166 - INFO - Running extract_image_bumble.py...
2024-05-21 12:00:34,170 - INFO - Running script: /Users/frederic/tinder-bot/extract_image_bumble.py with args: []
2024-05-21 12:00:34,301 - INFO - Loading session...
Restoring session: b1cad6cc6c2d22a2405ec038594c5135, http://localhost:59781
Waiting for image element...
Erreur : HTTPConnectionPool(host='localhost', port=59781): Max retries exceeded with url: /session/b1cad6cc6c2d22a2405ec038594c5135/element (Caused by NewConnectionError('<urllib3.connection.HTTPConnection object at 0x1027ee150>: Failed to establish a new connection: [Errno 61] Connection refused'))
Échec de l'extraction de l'image.

2024-05-21 12:00:34,302 - ERROR - 
2024-05-21 12:00:34,302 - INFO - Running evaluation_bumble.py...
2024-05-21 12:00:34,302 - INFO - Running script: /Users/frederic/tinder-bot/evaluation_bumble.py with args: []
2024-05-21 12:00:38,923 - INFO - Evaluating image at: /Users/frederic/tinder-bot/profile_image_bumble.jpg
Detection result: {'request_id': '1716303636,247d7a34-7c16-459a-a62b-43f43ab34469', 'time_used': 163, 'faces': [{'face_token': '26e2e651d61114e21b617a27b76fdf6f', 'face_rectangle': {'top': 447, 'left': 412, 'width': 227, 'height': 227}, 'attributes': {'facequality': {'value': 91.593, 'threshold': 70.1}}}], 'image_id': 'XHBMRpc5QvH6jPGE1Xqo2g==', 'face_num': 1}
Analyze result: {'time_used': 99, 'request_id': '1716303638,91351e4d-4177-43e8-940a-ce584325520a', 'faces': [{'attributes': {'gender': {'value': 'Female'}, 'age': {'value': 63}, 'beauty': {'female_score': 41.16, 'male_score': 41.004}}, 'face_rectangle': {'width': 227, 'top': 447, 'left': 412, 'height': 227}, 'face_token': '26e2e651d61114e21b617a27b76fdf6f'}]}
Image: Pas Belle (Female Score: 41.16, Male Score: 41.004)

2024-05-21 12:00:38,924 - ERROR - 
2024-05-21 12:00:38,924 - INFO - Evaluation result: is_beautiful=False
2024-05-21 12:00:38,924 - INFO - Running navigate_bumble.py with is_beautiful=False...
2024-05-21 12:00:38,924 - INFO - Running script: /Users/frederic/tinder-bot/navigate_bumble.py with args: ['false']
2024-05-21 12:00:39,409 - INFO - 
2024-05-21 12:00:39,410 - ERROR - 2024-05-21 12:00:39,005 - INFO - is_beautiful: False
2024-05-21 12:00:39,005 - INFO - Loading session...
2024-05-21 12:00:39,005 - INFO - Restoring session: 66981adc8a31ddb0c1e7925f49bda635, http://localhost:59871
--- Logging error ---
Traceback (most recent call last):
  File "/Users/frederic/tinder-bot/navigate_bumble.py", line 38, in navigate
    match_button = WebDriverWait(driver, 5).until(
                   ^^^^^^^^^^^^^^^^^^^^^^^^^^^^^^^
  File "/opt/homebrew/lib/python3.11/site-packages/selenium/webdriver/support/wait.py", line 96, in until
    value = method(self._driver)
            ^^^^^^^^^^^^^^^^^^^^
  File "/opt/homebrew/lib/python3.11/site-packages/selenium/webdriver/support/expected_conditions.py", line 84, in _predicate
    return driver.find_element(*locator)
           ^^^^^^^^^^^^^^^^^^^^^^^^^^^^^
  File "/opt/homebrew/lib/python3.11/site-packages/selenium/webdriver/remote/webdriver.py", line 741, in find_element
    return self.execute(Command.FIND_ELEMENT, {"using": by, "value": value})["value"]
           ^^^^^^^^^^^^^^^^^^^^^^^^^^^^^^^^^^^^^^^^^^^^^^^^^^^^^^^^^^^^^^^^^
  File "/opt/homebrew/lib/python3.11/site-packages/selenium/webdriver/remote/webdriver.py", line 347, in execute
    self.error_handler.check_response(response)
  File "/opt/homebrew/lib/python3.11/site-packages/selenium/webdriver/remote/errorhandler.py", line 229, in check_response
    raise exception_class(message, screen, stacktrace)
selenium.common.exceptions.JavascriptException: Message: javascript error: {"status":32,"value":"Unable to locate an element with the xpath expression //span[text()='Voir d'autres profils'] because of the following error:\nSyntaxError: Failed to execute 'evaluate' on 'Document': The string '//span[text()='Voir d'autres profils']' is not a valid XPath expression."}
  (Session info: chrome=125.0.6422.61)
Stacktrace:
0   chromedriver                        0x00000001048424a0 chromedriver + 4301984
1   chromedriver                        0x000000010483ade8 chromedriver + 4271592
2   chromedriver                        0x000000010446c19c chromedriver + 278940
3   chromedriver                        0x000000010447066c chromedriver + 296556
4   chromedriver                        0x00000001044724e8 chromedriver + 304360
5   chromedriver                        0x0000000104472560 chromedriver + 304480
6   chromedriver                        0x00000001044ae3c0 chromedriver + 549824
7   chromedriver                        0x00000001044e6c5c chromedriver + 781404
8   chromedriver                        0x00000001044a3004 chromedriver + 503812
9   chromedriver                        0x00000001044a39ec chromedriver + 506348
10  chromedriver                        0x000000010480a4e8 chromedriver + 4072680
11  chromedriver                        0x000000010480ef94 chromedriver + 4091796
12  chromedriver                        0x00000001047f172c chromedriver + 3970860
13  chromedriver                        0x000000010480f87c chromedriver + 4094076
14  chromedriver                        0x00000001047e46ac chromedriver + 3917484
15  chromedriver                        0x000000010482cae0 chromedriver + 4213472
16  chromedriver                        0x000000010482cc5c chromedriver + 4213852
17  chromedriver                        0x000000010483a9e0 chromedriver + 4270560
18  libsystem_pthread.dylib             0x00000001992aaf94 _pthread_start + 136
19  libsystem_pthread.dylib             0x00000001992a5d34 thread_start + 8


During handling of the above exception, another exception occurred:

Traceback (most recent call last):
  File "/opt/homebrew/Cellar/python@3.11/3.11.7/Frameworks/Python.framework/Versions/3.11/lib/python3.11/logging/__init__.py", line 1110, in emit
    msg = self.format(record)
          ^^^^^^^^^^^^^^^^^^^
  File "/opt/homebrew/Cellar/python@3.11/3.11.7/Frameworks/Python.framework/Versions/3.11/lib/python3.11/logging/__init__.py", line 953, in format
    return fmt.format(record)
           ^^^^^^^^^^^^^^^^^^
  File "/opt/homebrew/Cellar/python@3.11/3.11.7/Frameworks/Python.framework/Versions/3.11/lib/python3.11/logging/__init__.py", line 687, in format
    record.message = record.getMessage()
                     ^^^^^^^^^^^^^^^^^^^
  File "/opt/homebrew/Cellar/python@3.11/3.11.7/Frameworks/Python.framework/Versions/3.11/lib/python3.11/logging/__init__.py", line 377, in getMessage
    msg = msg % self.args
          ~~~~^~~~~~~~~~~
TypeError: not all arguments converted during string formatting
Call stack:
  File "/Users/frederic/tinder-bot/navigate_bumble.py", line 74, in <module>
    navigate(driver, is_beautiful)
  File "/Users/frederic/tinder-bot/navigate_bumble.py", line 45, in navigate
    logger.info("No match found or error occurred: ", e)
Message: 'No match found or error occurred: '
Arguments: (JavascriptException(),)
2024-05-21 12:00:39,399 - INFO - Pressed Left Arrow Key.

2024-05-21 12:00:39,692 - INFO - Running extract_image_bumble.py...
2024-05-21 12:00:39,693 - INFO - Running script: /Users/frederic/tinder-bot/extract_image_bumble.py with args: []
2024-05-21 12:00:39,995 - INFO - Loading session...
Restoring session: 66981adc8a31ddb0c1e7925f49bda635, http://localhost:59871
Waiting for image element...
Image element found.
Image URL: https://us1.ecdn2.bumbcdn.com/p538/hidden?euri=AAAAAAAAAAIQ6KQJfSM..7VWwRJihoeyuwBucT4xIFdDG-82cbUTlhgXOi9kUFeFrz5QnYa6XmmvXMJxW.yHUqkBNjFolrKIWz5QjsXwTcVBHsyGItfCiC7y.XVOgXZVs0wPhWQnT7atrsHcQQPx1UyqrwGOKRhJ0TyV.V1KD0Yb9GQpeRFrnJe06x7fwNvfsrYJvNdgja.Um9x8572f6GIaJBbicJfd&size=__size__&ck=b4530078c66d316082b8edbaf0b3e043&wm_size=72x72&wm_offs=751x1285&h=76P&gs=j&t=42.1.0.0
Image téléchargée et convertie en JPEG : /Users/frederic/tinder-bot/profile_image_bumble.jpg
L'image est enregistrée à l'emplacement : /Users/frederic/tinder-bot/profile_image_bumble.jpg

2024-05-21 12:00:39,995 - ERROR - 
2024-05-21 12:00:39,995 - INFO - Running evaluation_bumble.py...
2024-05-21 12:00:39,995 - INFO - Running script: /Users/frederic/tinder-bot/evaluation_bumble.py with args: []
2024-05-21 12:00:44,251 - INFO - Evaluating image at: /Users/frederic/tinder-bot/profile_image_bumble.jpg
Detection result: {'request_id': '1716303641,06ab8ac7-527a-4c74-be62-0b37f11cf0ba', 'time_used': 101, 'faces': [{'face_token': '31e990ed29fcdd4ad7a87aa4538f72f2', 'face_rectangle': {'top': 531, 'left': 370, 'width': 320, 'height': 320}, 'attributes': {'facequality': {'value': 0.006, 'threshold': 70.1}}}], 'image_id': 'UgcWliii1oFeE31hGRoiTQ==', 'face_num': 1}
Analyze result: {'time_used': 88, 'request_id': '1716303644,03f34161-c82f-46ea-9537-0d3cc4045a5d', 'faces': [{'attributes': {'gender': {'value': 'Female'}, 'age': {'value': 26}, 'beauty': {'female_score': 50.588, 'male_score': 52.71}}, 'face_rectangle': {'width': 320, 'top': 531, 'left': 370, 'height': 320}, 'face_token': '31e990ed29fcdd4ad7a87aa4538f72f2'}]}
Image: Pas Belle (Female Score: 50.588, Male Score: 52.71)

2024-05-21 12:00:44,252 - ERROR - 
2024-05-21 12:00:44,252 - INFO - Evaluation result: is_beautiful=False
2024-05-21 12:00:44,252 - INFO - Running navigate_bumble.py with is_beautiful=False...
2024-05-21 12:00:44,252 - INFO - Running script: /Users/frederic/tinder-bot/navigate_bumble.py with args: ['false']
2024-05-21 12:00:44,595 - INFO - 
2024-05-21 12:00:44,595 - ERROR - 2024-05-21 12:00:44,334 - INFO - is_beautiful: False
2024-05-21 12:00:44,334 - INFO - Loading session...
2024-05-21 12:00:44,335 - INFO - Restoring session: 66981adc8a31ddb0c1e7925f49bda635, http://localhost:59871
--- Logging error ---
Traceback (most recent call last):
  File "/Users/frederic/tinder-bot/navigate_bumble.py", line 38, in navigate
    match_button = WebDriverWait(driver, 5).until(
                   ^^^^^^^^^^^^^^^^^^^^^^^^^^^^^^^
  File "/opt/homebrew/lib/python3.11/site-packages/selenium/webdriver/support/wait.py", line 96, in until
    value = method(self._driver)
            ^^^^^^^^^^^^^^^^^^^^
  File "/opt/homebrew/lib/python3.11/site-packages/selenium/webdriver/support/expected_conditions.py", line 84, in _predicate
    return driver.find_element(*locator)
           ^^^^^^^^^^^^^^^^^^^^^^^^^^^^^
  File "/opt/homebrew/lib/python3.11/site-packages/selenium/webdriver/remote/webdriver.py", line 741, in find_element
    return self.execute(Command.FIND_ELEMENT, {"using": by, "value": value})["value"]
           ^^^^^^^^^^^^^^^^^^^^^^^^^^^^^^^^^^^^^^^^^^^^^^^^^^^^^^^^^^^^^^^^^
  File "/opt/homebrew/lib/python3.11/site-packages/selenium/webdriver/remote/webdriver.py", line 347, in execute
    self.error_handler.check_response(response)
  File "/opt/homebrew/lib/python3.11/site-packages/selenium/webdriver/remote/errorhandler.py", line 229, in check_response
    raise exception_class(message, screen, stacktrace)
selenium.common.exceptions.JavascriptException: Message: javascript error: {"status":32,"value":"Unable to locate an element with the xpath expression //span[text()='Voir d'autres profils'] because of the following error:\nSyntaxError: Failed to execute 'evaluate' on 'Document': The string '//span[text()='Voir d'autres profils']' is not a valid XPath expression."}
  (Session info: chrome=125.0.6422.61)
Stacktrace:
0   chromedriver                        0x00000001048424a0 chromedriver + 4301984
1   chromedriver                        0x000000010483ade8 chromedriver + 4271592
2   chromedriver                        0x000000010446c19c chromedriver + 278940
3   chromedriver                        0x000000010447066c chromedriver + 296556
4   chromedriver                        0x00000001044724e8 chromedriver + 304360
5   chromedriver                        0x0000000104472560 chromedriver + 304480
6   chromedriver                        0x00000001044ae3c0 chromedriver + 549824
7   chromedriver                        0x00000001044e6c5c chromedriver + 781404
8   chromedriver                        0x00000001044a3004 chromedriver + 503812
9   chromedriver                        0x00000001044a39ec chromedriver + 506348
10  chromedriver                        0x000000010480a4e8 chromedriver + 4072680
11  chromedriver                        0x000000010480ef94 chromedriver + 4091796
12  chromedriver                        0x00000001047f172c chromedriver + 3970860
13  chromedriver                        0x000000010480f87c chromedriver + 4094076
14  chromedriver                        0x00000001047e46ac chromedriver + 3917484
15  chromedriver                        0x000000010482cae0 chromedriver + 4213472
16  chromedriver                        0x000000010482cc5c chromedriver + 4213852
17  chromedriver                        0x000000010483a9e0 chromedriver + 4270560
18  libsystem_pthread.dylib             0x00000001992aaf94 _pthread_start + 136
19  libsystem_pthread.dylib             0x00000001992a5d34 thread_start + 8


During handling of the above exception, another exception occurred:

Traceback (most recent call last):
  File "/opt/homebrew/Cellar/python@3.11/3.11.7/Frameworks/Python.framework/Versions/3.11/lib/python3.11/logging/__init__.py", line 1110, in emit
    msg = self.format(record)
          ^^^^^^^^^^^^^^^^^^^
  File "/opt/homebrew/Cellar/python@3.11/3.11.7/Frameworks/Python.framework/Versions/3.11/lib/python3.11/logging/__init__.py", line 953, in format
    return fmt.format(record)
           ^^^^^^^^^^^^^^^^^^
  File "/opt/homebrew/Cellar/python@3.11/3.11.7/Frameworks/Python.framework/Versions/3.11/lib/python3.11/logging/__init__.py", line 687, in format
    record.message = record.getMessage()
                     ^^^^^^^^^^^^^^^^^^^
  File "/opt/homebrew/Cellar/python@3.11/3.11.7/Frameworks/Python.framework/Versions/3.11/lib/python3.11/logging/__init__.py", line 377, in getMessage
    msg = msg % self.args
          ~~~~^~~~~~~~~~~
TypeError: not all arguments converted during string formatting
Call stack:
  File "/Users/frederic/tinder-bot/navigate_bumble.py", line 74, in <module>
    navigate(driver, is_beautiful)
  File "/Users/frederic/tinder-bot/navigate_bumble.py", line 45, in navigate
    logger.info("No match found or error occurred: ", e)
Message: 'No match found or error occurred: '
Arguments: (JavascriptException(),)
2024-05-21 12:00:44,583 - INFO - Pressed Left Arrow Key.

2024-05-21 12:00:44,896 - INFO - Running extract_image_bumble.py...
2024-05-21 12:00:44,896 - INFO - Running script: /Users/frederic/tinder-bot/extract_image_bumble.py with args: []
2024-05-21 12:00:45,683 - INFO - Loading session...
Restoring session: 66981adc8a31ddb0c1e7925f49bda635, http://localhost:59871
Waiting for image element...
Image element found.
Image URL: https://us1.ecdn2.bumbcdn.com/p539/hidden?euri=AAAAAAAAAAIQciOhwGlZeVHXV.5svZz6yQBVPf0Ohe6EaqjToKxzwEsxE7Lw8NO5vM-gT6t7ESU.24fLuTfKo151W794jleT7PVcRU9PT-7Q3a2nL6KBkomh4ZaIeNLCIRb-Br7Ib2oNnsValFazYAgrh1C6C7PBg28y726GL8q7wCv4uQU4i5dLvZgxLVPUbiF7TctWIDcqEFmjLUCi5Lta7JMHt5lI&size=__size__&ck=c533e6f84a1060b041723ae012b40282&wm_size=72x72&wm_offs=973x1323&h=QU8&gs=j&t=42.1.0.0
Image téléchargée et convertie en JPEG : /Users/frederic/tinder-bot/profile_image_bumble.jpg
L'image est enregistrée à l'emplacement : /Users/frederic/tinder-bot/profile_image_bumble.jpg

2024-05-21 12:00:45,683 - ERROR - 
2024-05-21 12:00:45,683 - INFO - Running evaluation_bumble.py...
2024-05-21 12:00:45,683 - INFO - Running script: /Users/frederic/tinder-bot/evaluation_bumble.py with args: []
2024-05-21 12:00:50,149 - INFO - Evaluating image at: /Users/frederic/tinder-bot/profile_image_bumble.jpg
Detection result: {'request_id': '1716303647,2d528680-059d-4d7f-9e3a-49154616cd81', 'time_used': 154, 'faces': [{'face_token': 'a8c25866f793247d3117a89e0aa5caa6', 'face_rectangle': {'top': 735, 'left': 654, 'width': 39, 'height': 39}, 'attributes': {'facequality': {'value': 83.433, 'threshold': 70.1}}}], 'image_id': 'tdR4Yv+7/jgiATplQNpn4w==', 'face_num': 1}
Analyze result: {'time_used': 97, 'request_id': '1716303650,8ec2e691-73bd-47d7-aa0c-51159accbdfd', 'faces': [{'attributes': {'gender': {'value': 'Female'}, 'age': {'value': 32}, 'beauty': {'female_score': 42.363, 'male_score': 37.079}}, 'face_rectangle': {'width': 39, 'top': 735, 'left': 654, 'height': 39}, 'face_token': 'a8c25866f793247d3117a89e0aa5caa6'}]}
Image: Pas Belle (Female Score: 42.363, Male Score: 37.079)

2024-05-21 12:00:50,151 - ERROR - 
2024-05-21 12:00:50,151 - INFO - Evaluation result: is_beautiful=False
2024-05-21 12:00:50,151 - INFO - Running navigate_bumble.py with is_beautiful=False...
2024-05-21 12:00:50,151 - INFO - Running script: /Users/frederic/tinder-bot/navigate_bumble.py with args: ['false']
2024-05-21 12:00:50,595 - INFO - 
2024-05-21 12:00:50,595 - ERROR - 2024-05-21 12:00:50,230 - INFO - is_beautiful: False
2024-05-21 12:00:50,230 - INFO - Loading session...
2024-05-21 12:00:50,230 - INFO - Restoring session: 66981adc8a31ddb0c1e7925f49bda635, http://localhost:59871
--- Logging error ---
Traceback (most recent call last):
  File "/Users/frederic/tinder-bot/navigate_bumble.py", line 38, in navigate
    match_button = WebDriverWait(driver, 5).until(
                   ^^^^^^^^^^^^^^^^^^^^^^^^^^^^^^^
  File "/opt/homebrew/lib/python3.11/site-packages/selenium/webdriver/support/wait.py", line 96, in until
    value = method(self._driver)
            ^^^^^^^^^^^^^^^^^^^^
  File "/opt/homebrew/lib/python3.11/site-packages/selenium/webdriver/support/expected_conditions.py", line 84, in _predicate
    return driver.find_element(*locator)
           ^^^^^^^^^^^^^^^^^^^^^^^^^^^^^
  File "/opt/homebrew/lib/python3.11/site-packages/selenium/webdriver/remote/webdriver.py", line 741, in find_element
    return self.execute(Command.FIND_ELEMENT, {"using": by, "value": value})["value"]
           ^^^^^^^^^^^^^^^^^^^^^^^^^^^^^^^^^^^^^^^^^^^^^^^^^^^^^^^^^^^^^^^^^
  File "/opt/homebrew/lib/python3.11/site-packages/selenium/webdriver/remote/webdriver.py", line 347, in execute
    self.error_handler.check_response(response)
  File "/opt/homebrew/lib/python3.11/site-packages/selenium/webdriver/remote/errorhandler.py", line 229, in check_response
    raise exception_class(message, screen, stacktrace)
selenium.common.exceptions.JavascriptException: Message: javascript error: {"status":32,"value":"Unable to locate an element with the xpath expression //span[text()='Voir d'autres profils'] because of the following error:\nSyntaxError: Failed to execute 'evaluate' on 'Document': The string '//span[text()='Voir d'autres profils']' is not a valid XPath expression."}
  (Session info: chrome=125.0.6422.61)
Stacktrace:
0   chromedriver                        0x00000001048424a0 chromedriver + 4301984
1   chromedriver                        0x000000010483ade8 chromedriver + 4271592
2   chromedriver                        0x000000010446c19c chromedriver + 278940
3   chromedriver                        0x000000010447066c chromedriver + 296556
4   chromedriver                        0x00000001044724e8 chromedriver + 304360
5   chromedriver                        0x0000000104472560 chromedriver + 304480
6   chromedriver                        0x00000001044ae3c0 chromedriver + 549824
7   chromedriver                        0x00000001044e6c5c chromedriver + 781404
8   chromedriver                        0x00000001044a3004 chromedriver + 503812
9   chromedriver                        0x00000001044a39ec chromedriver + 506348
10  chromedriver                        0x000000010480a4e8 chromedriver + 4072680
11  chromedriver                        0x000000010480ef94 chromedriver + 4091796
12  chromedriver                        0x00000001047f172c chromedriver + 3970860
13  chromedriver                        0x000000010480f87c chromedriver + 4094076
14  chromedriver                        0x00000001047e46ac chromedriver + 3917484
15  chromedriver                        0x000000010482cae0 chromedriver + 4213472
16  chromedriver                        0x000000010482cc5c chromedriver + 4213852
17  chromedriver                        0x000000010483a9e0 chromedriver + 4270560
18  libsystem_pthread.dylib             0x00000001992aaf94 _pthread_start + 136
19  libsystem_pthread.dylib             0x00000001992a5d34 thread_start + 8


During handling of the above exception, another exception occurred:

Traceback (most recent call last):
  File "/opt/homebrew/Cellar/python@3.11/3.11.7/Frameworks/Python.framework/Versions/3.11/lib/python3.11/logging/__init__.py", line 1110, in emit
    msg = self.format(record)
          ^^^^^^^^^^^^^^^^^^^
  File "/opt/homebrew/Cellar/python@3.11/3.11.7/Frameworks/Python.framework/Versions/3.11/lib/python3.11/logging/__init__.py", line 953, in format
    return fmt.format(record)
           ^^^^^^^^^^^^^^^^^^
  File "/opt/homebrew/Cellar/python@3.11/3.11.7/Frameworks/Python.framework/Versions/3.11/lib/python3.11/logging/__init__.py", line 687, in format
    record.message = record.getMessage()
                     ^^^^^^^^^^^^^^^^^^^
  File "/opt/homebrew/Cellar/python@3.11/3.11.7/Frameworks/Python.framework/Versions/3.11/lib/python3.11/logging/__init__.py", line 377, in getMessage
    msg = msg % self.args
          ~~~~^~~~~~~~~~~
TypeError: not all arguments converted during string formatting
Call stack:
  File "/Users/frederic/tinder-bot/navigate_bumble.py", line 74, in <module>
    navigate(driver, is_beautiful)
  File "/Users/frederic/tinder-bot/navigate_bumble.py", line 45, in navigate
    logger.info("No match found or error occurred: ", e)
Message: 'No match found or error occurred: '
Arguments: (JavascriptException(),)
2024-05-21 12:00:50,585 - INFO - Pressed Left Arrow Key.

2024-05-21 12:00:50,866 - INFO - Running extract_image_bumble.py...
2024-05-21 12:00:50,866 - INFO - Running script: /Users/frederic/tinder-bot/extract_image_bumble.py with args: []
2024-05-21 12:00:51,537 - INFO - Loading session...
Restoring session: 66981adc8a31ddb0c1e7925f49bda635, http://localhost:59871
Waiting for image element...
Image element found.
Image URL: https://us1.ecdn2.bumbcdn.com/p564/hidden?euri=AAAAAAAAAAIQoIoKad5lDKgOxbur9U94IwAO88y0XomBePy8OZtvmAJ1c0xyWpOQxu9GY2qAUUMXu8Ui289.2ooO5mJzZlUrO8GufR3Bkw85L9SMXLyfpO2GpWNHoPHRw-uh5-Xvr5Hv7gGQLYH34BqOE83P8-V48Joz1wxNb858lU.XXbYJHVPMqzkduTNnyagssMddZcXP8al-JjdYkNc9JKwzzIUf&size=__size__&ck=5019b803a0eaec99f90cf5b7241210cc&wm_size=72x72&wm_offs=973x1125&h=_gH&gs=j&t=42.1.0.0
Image téléchargée et convertie en JPEG : /Users/frederic/tinder-bot/profile_image_bumble.jpg
L'image est enregistrée à l'emplacement : /Users/frederic/tinder-bot/profile_image_bumble.jpg

2024-05-21 12:00:51,537 - ERROR - 
2024-05-21 12:00:51,537 - INFO - Running evaluation_bumble.py...
2024-05-21 12:00:51,537 - INFO - Running script: /Users/frederic/tinder-bot/evaluation_bumble.py with args: []
2024-05-21 12:00:55,805 - INFO - Evaluating image at: /Users/frederic/tinder-bot/profile_image_bumble.jpg
Detection result: {'request_id': '1716303653,f70ded1f-7aac-45bc-8d73-8334e1c9a7d6', 'time_used': 125, 'faces': [{'face_token': '89c3ad1396256b5010ebdf5f6bbaec38', 'face_rectangle': {'top': 302, 'left': 157, 'width': 385, 'height': 385}, 'attributes': {'facequality': {'value': 3.956, 'threshold': 70.1}}}], 'image_id': 'ofY11i+2vvi5R0hO26nq8Q==', 'face_num': 1}
Analyze result: {'time_used': 94, 'request_id': '1716303655,04de84a9-615b-4e8b-8980-f8ff73b86664', 'faces': [{'attributes': {'gender': {'value': 'Female'}, 'age': {'value': 21}, 'beauty': {'female_score': 78.033, 'male_score': 77.33}}, 'face_rectangle': {'width': 385, 'top': 302, 'left': 157, 'height': 385}, 'face_token': '89c3ad1396256b5010ebdf5f6bbaec38'}]}
Image: Belle (Female Score: 78.033, Male Score: 77.33)

2024-05-21 12:00:55,805 - ERROR - 
2024-05-21 12:00:55,805 - INFO - Evaluation result: is_beautiful=True
2024-05-21 12:00:55,805 - INFO - Running navigate_bumble.py with is_beautiful=True...
2024-05-21 12:00:55,805 - INFO - Running script: /Users/frederic/tinder-bot/navigate_bumble.py with args: ['true']
2024-05-21 12:00:56,331 - INFO - 
2024-05-21 12:00:56,331 - ERROR - 2024-05-21 12:00:55,923 - INFO - is_beautiful: True
2024-05-21 12:00:55,923 - INFO - Loading session...
2024-05-21 12:00:55,923 - INFO - Restoring session: 66981adc8a31ddb0c1e7925f49bda635, http://localhost:59871
--- Logging error ---
Traceback (most recent call last):
  File "/Users/frederic/tinder-bot/navigate_bumble.py", line 38, in navigate
    match_button = WebDriverWait(driver, 5).until(
                   ^^^^^^^^^^^^^^^^^^^^^^^^^^^^^^^
  File "/opt/homebrew/lib/python3.11/site-packages/selenium/webdriver/support/wait.py", line 96, in until
    value = method(self._driver)
            ^^^^^^^^^^^^^^^^^^^^
  File "/opt/homebrew/lib/python3.11/site-packages/selenium/webdriver/support/expected_conditions.py", line 84, in _predicate
    return driver.find_element(*locator)
           ^^^^^^^^^^^^^^^^^^^^^^^^^^^^^
  File "/opt/homebrew/lib/python3.11/site-packages/selenium/webdriver/remote/webdriver.py", line 741, in find_element
    return self.execute(Command.FIND_ELEMENT, {"using": by, "value": value})["value"]
           ^^^^^^^^^^^^^^^^^^^^^^^^^^^^^^^^^^^^^^^^^^^^^^^^^^^^^^^^^^^^^^^^^
  File "/opt/homebrew/lib/python3.11/site-packages/selenium/webdriver/remote/webdriver.py", line 347, in execute
    self.error_handler.check_response(response)
  File "/opt/homebrew/lib/python3.11/site-packages/selenium/webdriver/remote/errorhandler.py", line 229, in check_response
    raise exception_class(message, screen, stacktrace)
selenium.common.exceptions.JavascriptException: Message: javascript error: {"status":32,"value":"Unable to locate an element with the xpath expression //span[text()='Voir d'autres profils'] because of the following error:\nSyntaxError: Failed to execute 'evaluate' on 'Document': The string '//span[text()='Voir d'autres profils']' is not a valid XPath expression."}
  (Session info: chrome=125.0.6422.61)
Stacktrace:
0   chromedriver                        0x00000001048424a0 chromedriver + 4301984
1   chromedriver                        0x000000010483ade8 chromedriver + 4271592
2   chromedriver                        0x000000010446c19c chromedriver + 278940
3   chromedriver                        0x000000010447066c chromedriver + 296556
4   chromedriver                        0x00000001044724e8 chromedriver + 304360
5   chromedriver                        0x0000000104472560 chromedriver + 304480
6   chromedriver                        0x00000001044ae3c0 chromedriver + 549824
7   chromedriver                        0x00000001044e6c5c chromedriver + 781404
8   chromedriver                        0x00000001044a3004 chromedriver + 503812
9   chromedriver                        0x00000001044a39ec chromedriver + 506348
10  chromedriver                        0x000000010480a4e8 chromedriver + 4072680
11  chromedriver                        0x000000010480ef94 chromedriver + 4091796
12  chromedriver                        0x00000001047f172c chromedriver + 3970860
13  chromedriver                        0x000000010480f87c chromedriver + 4094076
14  chromedriver                        0x00000001047e46ac chromedriver + 3917484
15  chromedriver                        0x000000010482cae0 chromedriver + 4213472
16  chromedriver                        0x000000010482cc5c chromedriver + 4213852
17  chromedriver                        0x000000010483a9e0 chromedriver + 4270560
18  libsystem_pthread.dylib             0x00000001992aaf94 _pthread_start + 136
19  libsystem_pthread.dylib             0x00000001992a5d34 thread_start + 8


During handling of the above exception, another exception occurred:

Traceback (most recent call last):
  File "/opt/homebrew/Cellar/python@3.11/3.11.7/Frameworks/Python.framework/Versions/3.11/lib/python3.11/logging/__init__.py", line 1110, in emit
    msg = self.format(record)
          ^^^^^^^^^^^^^^^^^^^
  File "/opt/homebrew/Cellar/python@3.11/3.11.7/Frameworks/Python.framework/Versions/3.11/lib/python3.11/logging/__init__.py", line 953, in format
    return fmt.format(record)
           ^^^^^^^^^^^^^^^^^^
  File "/opt/homebrew/Cellar/python@3.11/3.11.7/Frameworks/Python.framework/Versions/3.11/lib/python3.11/logging/__init__.py", line 687, in format
    record.message = record.getMessage()
                     ^^^^^^^^^^^^^^^^^^^
  File "/opt/homebrew/Cellar/python@3.11/3.11.7/Frameworks/Python.framework/Versions/3.11/lib/python3.11/logging/__init__.py", line 377, in getMessage
    msg = msg % self.args
          ~~~~^~~~~~~~~~~
TypeError: not all arguments converted during string formatting
Call stack:
  File "/Users/frederic/tinder-bot/navigate_bumble.py", line 74, in <module>
    navigate(driver, is_beautiful)
  File "/Users/frederic/tinder-bot/navigate_bumble.py", line 45, in navigate
    logger.info("No match found or error occurred: ", e)
Message: 'No match found or error occurred: '
Arguments: (JavascriptException(),)
2024-05-21 12:00:56,318 - INFO - Pressed Right Arrow Key.

2024-05-21 12:00:56,570 - INFO - Running extract_image_bumble.py...
2024-05-21 12:00:56,570 - INFO - Running script: /Users/frederic/tinder-bot/extract_image_bumble.py with args: []
2024-05-21 12:00:56,814 - INFO - Loading session...
Restoring session: 66981adc8a31ddb0c1e7925f49bda635, http://localhost:59871
Waiting for image element...
Image element found.
Image URL: https://us1.ecdn2.bumbcdn.com/p573/hidden?euri=AAAAAAAAAAIQkIGVY7339gZNtK4OjEvdzgDPZYOSU.t6T3yOb4EP9UMzACAsDwmVXUhVZY3N5SCGyalhCOHfzaP4Q23OgD28lJU7r2RYuS49nMqhIgQ6VNpROgjKDVoy7WpNpmnpWpFfwJhV-V3SQ88E1YRHpWuc7NBkWXSvtUmddvc3DzF4KTtgMMdWfNzrzdI7A9ERH1ikc5ptLXfM935X0gSAKH7H&size=__size__&ck=311bd29c37abf842776350337fc93b87&wm_size=72x72&wm_offs=751x1028&h=ad6&gs=j&t=42.1.0.0
Image téléchargée et convertie en JPEG : /Users/frederic/tinder-bot/profile_image_bumble.jpg
L'image est enregistrée à l'emplacement : /Users/frederic/tinder-bot/profile_image_bumble.jpg

2024-05-21 12:00:56,814 - ERROR - 
2024-05-21 12:00:56,814 - INFO - Running evaluation_bumble.py...
2024-05-21 12:00:56,814 - INFO - Running script: /Users/frederic/tinder-bot/evaluation_bumble.py with args: []
2024-05-21 12:01:00,958 - INFO - Evaluating image at: /Users/frederic/tinder-bot/profile_image_bumble.jpg
Detection result: {'request_id': '1716303658,935a65fb-0b6b-4fda-84c6-26551e970775', 'time_used': 93, 'faces': [{'face_token': 'a64264658fb53f7ead4fe497eab0e033', 'face_rectangle': {'top': 267, 'left': 198, 'width': 379, 'height': 379}, 'attributes': {'facequality': {'value': 92.232, 'threshold': 70.1}}}], 'image_id': 'BeK2xdJ/Nmn65MbTIn4Ivg==', 'face_num': 1}
Analyze result: {'time_used': 89, 'request_id': '1716303661,4efb202b-f67b-4364-b27c-5d0e54271efc', 'faces': [{'attributes': {'gender': {'value': 'Female'}, 'age': {'value': 32}, 'beauty': {'female_score': 63.057, 'male_score': 63.818}}, 'face_rectangle': {'width': 379, 'top': 267, 'left': 198, 'height': 379}, 'face_token': 'a64264658fb53f7ead4fe497eab0e033'}]}
Image: Belle (Female Score: 63.057, Male Score: 63.818)

2024-05-21 12:01:00,958 - ERROR - 
2024-05-21 12:01:00,958 - INFO - Evaluation result: is_beautiful=True
2024-05-21 12:01:00,958 - INFO - Running navigate_bumble.py with is_beautiful=True...
2024-05-21 12:01:00,958 - INFO - Running script: /Users/frederic/tinder-bot/navigate_bumble.py with args: ['true']
2024-05-21 12:01:01,322 - INFO - 
2024-05-21 12:01:01,325 - ERROR - 2024-05-21 12:01:01,049 - INFO - is_beautiful: True
2024-05-21 12:01:01,049 - INFO - Loading session...
2024-05-21 12:01:01,049 - INFO - Restoring session: 66981adc8a31ddb0c1e7925f49bda635, http://localhost:59871
--- Logging error ---
Traceback (most recent call last):
  File "/Users/frederic/tinder-bot/navigate_bumble.py", line 38, in navigate
    match_button = WebDriverWait(driver, 5).until(
                   ^^^^^^^^^^^^^^^^^^^^^^^^^^^^^^^
  File "/opt/homebrew/lib/python3.11/site-packages/selenium/webdriver/support/wait.py", line 96, in until
    value = method(self._driver)
            ^^^^^^^^^^^^^^^^^^^^
  File "/opt/homebrew/lib/python3.11/site-packages/selenium/webdriver/support/expected_conditions.py", line 84, in _predicate
    return driver.find_element(*locator)
           ^^^^^^^^^^^^^^^^^^^^^^^^^^^^^
  File "/opt/homebrew/lib/python3.11/site-packages/selenium/webdriver/remote/webdriver.py", line 741, in find_element
    return self.execute(Command.FIND_ELEMENT, {"using": by, "value": value})["value"]
           ^^^^^^^^^^^^^^^^^^^^^^^^^^^^^^^^^^^^^^^^^^^^^^^^^^^^^^^^^^^^^^^^^
  File "/opt/homebrew/lib/python3.11/site-packages/selenium/webdriver/remote/webdriver.py", line 347, in execute
    self.error_handler.check_response(response)
  File "/opt/homebrew/lib/python3.11/site-packages/selenium/webdriver/remote/errorhandler.py", line 229, in check_response
    raise exception_class(message, screen, stacktrace)
selenium.common.exceptions.JavascriptException: Message: javascript error: {"status":32,"value":"Unable to locate an element with the xpath expression //span[text()='Voir d'autres profils'] because of the following error:\nSyntaxError: Failed to execute 'evaluate' on 'Document': The string '//span[text()='Voir d'autres profils']' is not a valid XPath expression."}
  (Session info: chrome=125.0.6422.61)
Stacktrace:
0   chromedriver                        0x00000001048424a0 chromedriver + 4301984
1   chromedriver                        0x000000010483ade8 chromedriver + 4271592
2   chromedriver                        0x000000010446c19c chromedriver + 278940
3   chromedriver                        0x000000010447066c chromedriver + 296556
4   chromedriver                        0x00000001044724e8 chromedriver + 304360
5   chromedriver                        0x0000000104472560 chromedriver + 304480
6   chromedriver                        0x00000001044ae3c0 chromedriver + 549824
7   chromedriver                        0x00000001044e6c5c chromedriver + 781404
8   chromedriver                        0x00000001044a3004 chromedriver + 503812
9   chromedriver                        0x00000001044a39ec chromedriver + 506348
10  chromedriver                        0x000000010480a4e8 chromedriver + 4072680
11  chromedriver                        0x000000010480ef94 chromedriver + 4091796
12  chromedriver                        0x00000001047f172c chromedriver + 3970860
13  chromedriver                        0x000000010480f87c chromedriver + 4094076
14  chromedriver                        0x00000001047e46ac chromedriver + 3917484
15  chromedriver                        0x000000010482cae0 chromedriver + 4213472
16  chromedriver                        0x000000010482cc5c chromedriver + 4213852
17  chromedriver                        0x000000010483a9e0 chromedriver + 4270560
18  libsystem_pthread.dylib             0x00000001992aaf94 _pthread_start + 136
19  libsystem_pthread.dylib             0x00000001992a5d34 thread_start + 8


During handling of the above exception, another exception occurred:

Traceback (most recent call last):
  File "/opt/homebrew/Cellar/python@3.11/3.11.7/Frameworks/Python.framework/Versions/3.11/lib/python3.11/logging/__init__.py", line 1110, in emit
    msg = self.format(record)
          ^^^^^^^^^^^^^^^^^^^
  File "/opt/homebrew/Cellar/python@3.11/3.11.7/Frameworks/Python.framework/Versions/3.11/lib/python3.11/logging/__init__.py", line 953, in format
    return fmt.format(record)
           ^^^^^^^^^^^^^^^^^^
  File "/opt/homebrew/Cellar/python@3.11/3.11.7/Frameworks/Python.framework/Versions/3.11/lib/python3.11/logging/__init__.py", line 687, in format
    record.message = record.getMessage()
                     ^^^^^^^^^^^^^^^^^^^
  File "/opt/homebrew/Cellar/python@3.11/3.11.7/Frameworks/Python.framework/Versions/3.11/lib/python3.11/logging/__init__.py", line 377, in getMessage
    msg = msg % self.args
          ~~~~^~~~~~~~~~~
TypeError: not all arguments converted during string formatting
Call stack:
  File "/Users/frederic/tinder-bot/navigate_bumble.py", line 74, in <module>
    navigate(driver, is_beautiful)
  File "/Users/frederic/tinder-bot/navigate_bumble.py", line 45, in navigate
    logger.info("No match found or error occurred: ", e)
Message: 'No match found or error occurred: '
Arguments: (JavascriptException(),)
2024-05-21 12:01:01,311 - INFO - Pressed Right Arrow Key.

2024-05-21 12:01:01,587 - INFO - Running extract_image_bumble.py...
2024-05-21 12:01:01,588 - INFO - Running script: /Users/frederic/tinder-bot/extract_image_bumble.py with args: []
2024-05-21 12:01:01,874 - INFO - Loading session...
Restoring session: 66981adc8a31ddb0c1e7925f49bda635, http://localhost:59871
Waiting for image element...
Image element found.
Image URL: https://us1.ecdn2.bumbcdn.com/p529/hidden?euri=AAAAAAAAAAIQ5ZMymjMdeTTJi5g-OR8HXQC6mZBHIiVu7kA1GSR6P1WLkinnUVADBDnC1CqYPdGiISSOEJM73Wn.R40mVROdrhUqLD1J90yQM85OB0SmdEdJC6Z3-T-DkrWieK5Ybp4sPbolAzmCtvrOKT2QNfmAwnJn4zRdM0Va-TB.Q0Bg2hLh48Y7xGyVAlxGqXMTBi3oNzwdLP1wZXI.tfGul.9K&size=__size__&ck=745549f7ce36f34557366f74002e4b32&wm_size=72x72&wm_offs=823x953&h=9yN&gs=j&t=42.1.0.0
Image téléchargée et convertie en JPEG : /Users/frederic/tinder-bot/profile_image_bumble.jpg
L'image est enregistrée à l'emplacement : /Users/frederic/tinder-bot/profile_image_bumble.jpg

2024-05-21 12:01:01,877 - ERROR - 
2024-05-21 12:01:01,877 - INFO - Running evaluation_bumble.py...
2024-05-21 12:01:01,877 - INFO - Running script: /Users/frederic/tinder-bot/evaluation_bumble.py with args: []
2024-05-21 12:01:06,364 - INFO - Evaluating image at: /Users/frederic/tinder-bot/profile_image_bumble.jpg
Detection result: {'request_id': '1716303663,9810b5d7-cd78-4b63-b0fe-d56e0fd24ade', 'time_used': 142, 'faces': [{'face_token': '4a4c2bc7fb508649cc93575bb49681ca', 'face_rectangle': {'top': 226, 'left': 203, 'width': 74, 'height': 74}, 'attributes': {'facequality': {'value': 25.866, 'threshold': 70.1}}}], 'image_id': 'LuiYJSPij/WLo0aQ6B+I8w==', 'face_num': 1}
Analyze result: {'time_used': 91, 'request_id': '1716303666,84c4cee2-e2b4-45dd-9adb-2b229a70d10e', 'faces': [{'attributes': {'gender': {'value': 'Male'}, 'age': {'value': 50}, 'beauty': {'female_score': 44.369, 'male_score': 48.808}}, 'face_rectangle': {'width': 74, 'top': 226, 'left': 203, 'height': 74}, 'face_token': '4a4c2bc7fb508649cc93575bb49681ca'}]}
Image: Pas Belle (Female Score: 44.369, Male Score: 48.808)

2024-05-21 12:01:06,365 - ERROR - 
2024-05-21 12:01:06,365 - INFO - Evaluation result: is_beautiful=False
2024-05-21 12:01:06,365 - INFO - Running navigate_bumble.py with is_beautiful=False...
2024-05-21 12:01:06,365 - INFO - Running script: /Users/frederic/tinder-bot/navigate_bumble.py with args: ['false']
2024-05-21 12:01:06,676 - INFO - 
2024-05-21 12:01:06,676 - ERROR - 2024-05-21 12:01:06,444 - INFO - is_beautiful: False
2024-05-21 12:01:06,444 - INFO - Loading session...
2024-05-21 12:01:06,444 - INFO - Restoring session: 66981adc8a31ddb0c1e7925f49bda635, http://localhost:59871
--- Logging error ---
Traceback (most recent call last):
  File "/Users/frederic/tinder-bot/navigate_bumble.py", line 38, in navigate
    match_button = WebDriverWait(driver, 5).until(
                   ^^^^^^^^^^^^^^^^^^^^^^^^^^^^^^^
  File "/opt/homebrew/lib/python3.11/site-packages/selenium/webdriver/support/wait.py", line 96, in until
    value = method(self._driver)
            ^^^^^^^^^^^^^^^^^^^^
  File "/opt/homebrew/lib/python3.11/site-packages/selenium/webdriver/support/expected_conditions.py", line 84, in _predicate
    return driver.find_element(*locator)
           ^^^^^^^^^^^^^^^^^^^^^^^^^^^^^
  File "/opt/homebrew/lib/python3.11/site-packages/selenium/webdriver/remote/webdriver.py", line 741, in find_element
    return self.execute(Command.FIND_ELEMENT, {"using": by, "value": value})["value"]
           ^^^^^^^^^^^^^^^^^^^^^^^^^^^^^^^^^^^^^^^^^^^^^^^^^^^^^^^^^^^^^^^^^
  File "/opt/homebrew/lib/python3.11/site-packages/selenium/webdriver/remote/webdriver.py", line 347, in execute
    self.error_handler.check_response(response)
  File "/opt/homebrew/lib/python3.11/site-packages/selenium/webdriver/remote/errorhandler.py", line 229, in check_response
    raise exception_class(message, screen, stacktrace)
selenium.common.exceptions.JavascriptException: Message: javascript error: {"status":32,"value":"Unable to locate an element with the xpath expression //span[text()='Voir d'autres profils'] because of the following error:\nSyntaxError: Failed to execute 'evaluate' on 'Document': The string '//span[text()='Voir d'autres profils']' is not a valid XPath expression."}
  (Session info: chrome=125.0.6422.61)
Stacktrace:
0   chromedriver                        0x00000001048424a0 chromedriver + 4301984
1   chromedriver                        0x000000010483ade8 chromedriver + 4271592
2   chromedriver                        0x000000010446c19c chromedriver + 278940
3   chromedriver                        0x000000010447066c chromedriver + 296556
4   chromedriver                        0x00000001044724e8 chromedriver + 304360
5   chromedriver                        0x0000000104472560 chromedriver + 304480
6   chromedriver                        0x00000001044ae3c0 chromedriver + 549824
7   chromedriver                        0x00000001044e6c5c chromedriver + 781404
8   chromedriver                        0x00000001044a3004 chromedriver + 503812
9   chromedriver                        0x00000001044a39ec chromedriver + 506348
10  chromedriver                        0x000000010480a4e8 chromedriver + 4072680
11  chromedriver                        0x000000010480ef94 chromedriver + 4091796
12  chromedriver                        0x00000001047f172c chromedriver + 3970860
13  chromedriver                        0x000000010480f87c chromedriver + 4094076
14  chromedriver                        0x00000001047e46ac chromedriver + 3917484
15  chromedriver                        0x000000010482cae0 chromedriver + 4213472
16  chromedriver                        0x000000010482cc5c chromedriver + 4213852
17  chromedriver                        0x000000010483a9e0 chromedriver + 4270560
18  libsystem_pthread.dylib             0x00000001992aaf94 _pthread_start + 136
19  libsystem_pthread.dylib             0x00000001992a5d34 thread_start + 8


During handling of the above exception, another exception occurred:

Traceback (most recent call last):
  File "/opt/homebrew/Cellar/python@3.11/3.11.7/Frameworks/Python.framework/Versions/3.11/lib/python3.11/logging/__init__.py", line 1110, in emit
    msg = self.format(record)
          ^^^^^^^^^^^^^^^^^^^
  File "/opt/homebrew/Cellar/python@3.11/3.11.7/Frameworks/Python.framework/Versions/3.11/lib/python3.11/logging/__init__.py", line 953, in format
    return fmt.format(record)
           ^^^^^^^^^^^^^^^^^^
  File "/opt/homebrew/Cellar/python@3.11/3.11.7/Frameworks/Python.framework/Versions/3.11/lib/python3.11/logging/__init__.py", line 687, in format
    record.message = record.getMessage()
                     ^^^^^^^^^^^^^^^^^^^
  File "/opt/homebrew/Cellar/python@3.11/3.11.7/Frameworks/Python.framework/Versions/3.11/lib/python3.11/logging/__init__.py", line 377, in getMessage
    msg = msg % self.args
          ~~~~^~~~~~~~~~~
TypeError: not all arguments converted during string formatting
Call stack:
  File "/Users/frederic/tinder-bot/navigate_bumble.py", line 74, in <module>
    navigate(driver, is_beautiful)
  File "/Users/frederic/tinder-bot/navigate_bumble.py", line 45, in navigate
    logger.info("No match found or error occurred: ", e)
Message: 'No match found or error occurred: '
Arguments: (JavascriptException(),)
2024-05-21 12:01:06,665 - INFO - Pressed Left Arrow Key.

2024-05-21 12:01:06,884 - INFO - Terminating the browser...
2024-05-21 12:01:06,884 - INFO - Browser terminated.
2024-05-21 12:01:06,884 - INFO - session_ready_bumble.txt removed.
