2024-05-23 11:39:56,380 - INFO - Le processus commencera dans 3 secondes.
2024-05-23 11:40:01,584 - INFO - Fermeture de Google Chrome...
2024-05-23 11:40:06,630 - INFO - Google Chrome est fermé.
2024-05-23 11:40:06,631 - INFO - Running open_bumble.py...
2024-05-23 11:40:06,640 - INFO - Waiting for session to be ready...
2024-05-23 11:40:06,640 - INFO - Session is ready. Starting extraction and evaluation process...
2024-05-23 11:40:16,642 - INFO - Running extract_image_bumble.py...
2024-05-23 11:40:16,642 - INFO - Running script: /Users/frederic/tinder-bot/extract_image_bumble.py with args: []
2024-05-23 11:40:16,774 - INFO - Loading session...
Restoring session: 46c62e6286c1e6d8529f6e6cea834513, http://localhost:53681
Waiting for image element...
Erreur : HTTPConnectionPool(host='localhost', port=53681): Max retries exceeded with url: /session/46c62e6286c1e6d8529f6e6cea834513/element (Caused by NewConnectionError('<urllib3.connection.HTTPConnection object at 0x1078c1f10>: Failed to establish a new connection: [Errno 61] Connection refused'))
Échec de l'extraction de l'image.

2024-05-23 11:40:16,775 - ERROR - 
2024-05-23 11:40:16,775 - INFO - Running evaluation_bumble.py...
2024-05-23 11:40:16,775 - INFO - Running script: /Users/frederic/tinder-bot/evaluation_bumble.py with args: []
2024-05-23 11:40:21,714 - INFO - Evaluating image at: /Users/frederic/tinder-bot/profile_image_bumble.jpg
Detection result: {'request_id': '1716475218,6033b2cd-d75b-4b68-b00d-2d8226551b2e', 'time_used': 174, 'faces': [{'face_token': '9b8df6003f56394f5858682757325715', 'face_rectangle': {'top': 407, 'left': 336, 'width': 59, 'height': 59}, 'attributes': {'facequality': {'value': 93.634, 'threshold': 70.1}}}], 'image_id': 'qIp73WbjZGoq/zV+TpAaBQ==', 'face_num': 1}
Analyze result: {'time_used': 118, 'request_id': '1716475221,db91b6c4-21f5-4363-8302-0b1293dcea36', 'faces': [{'attributes': {'gender': {'value': 'Female'}, 'age': {'value': 35}, 'beauty': {'female_score': 37.767, 'male_score': 39.408}}, 'face_rectangle': {'width': 59, 'top': 407, 'left': 336, 'height': 59}, 'face_token': '9b8df6003f56394f5858682757325715'}]}
Image: Pas Belle (Female Score: 37.767, Male Score: 39.408)

2024-05-23 11:40:21,715 - ERROR - 
2024-05-23 11:40:21,715 - INFO - Evaluation result: is_beautiful=False
2024-05-23 11:40:21,715 - INFO - Running navigate_bumble.py with is_beautiful=False...
2024-05-23 11:40:21,715 - INFO - Running script: /Users/frederic/tinder-bot/navigate_bumble.py with args: ['false']
2024-05-23 11:40:22,231 - INFO - 
2024-05-23 11:40:22,232 - ERROR - 2024-05-23 11:40:21,798 - INFO - is_beautiful: False
2024-05-23 11:40:21,798 - INFO - Loading session...
2024-05-23 11:40:21,798 - INFO - Restoring session: 46c62e6286c1e6d8529f6e6cea834513, http://localhost:53681
2024-05-23 11:40:22,200 - WARNING - Retrying (Retry(total=2, connect=None, read=None, redirect=None, status=None)) after connection broken by 'NewConnectionError('<urllib3.connection.HTTPConnection object at 0x10417d550>: Failed to establish a new connection: [Errno 61] Connection refused')': /session/46c62e6286c1e6d8529f6e6cea834513/element
2024-05-23 11:40:22,202 - WARNING - Retrying (Retry(total=1, connect=None, read=None, redirect=None, status=None)) after connection broken by 'NewConnectionError('<urllib3.connection.HTTPConnection object at 0x104191210>: Failed to establish a new connection: [Errno 61] Connection refused')': /session/46c62e6286c1e6d8529f6e6cea834513/element
2024-05-23 11:40:22,203 - WARNING - Retrying (Retry(total=0, connect=None, read=None, redirect=None, status=None)) after connection broken by 'NewConnectionError('<urllib3.connection.HTTPConnection object at 0x104191d90>: Failed to establish a new connection: [Errno 61] Connection refused')': /session/46c62e6286c1e6d8529f6e6cea834513/element
--- Logging error ---
Traceback (most recent call last):
  File "/opt/homebrew/lib/python3.11/site-packages/urllib3/connection.py", line 203, in _new_conn
    sock = connection.create_connection(
           ^^^^^^^^^^^^^^^^^^^^^^^^^^^^^
  File "/opt/homebrew/lib/python3.11/site-packages/urllib3/util/connection.py", line 85, in create_connection
    raise err
  File "/opt/homebrew/lib/python3.11/site-packages/urllib3/util/connection.py", line 73, in create_connection
    sock.connect(sa)
ConnectionRefusedError: [Errno 61] Connection refused

The above exception was the direct cause of the following exception:

Traceback (most recent call last):
  File "/opt/homebrew/lib/python3.11/site-packages/urllib3/connectionpool.py", line 790, in urlopen
    response = self._make_request(
               ^^^^^^^^^^^^^^^^^^^
  File "/opt/homebrew/lib/python3.11/site-packages/urllib3/connectionpool.py", line 496, in _make_request
    conn.request(
  File "/opt/homebrew/lib/python3.11/site-packages/urllib3/connection.py", line 395, in request
    self.endheaders()
  File "/opt/homebrew/Cellar/python@3.11/3.11.7/Frameworks/Python.framework/Versions/3.11/lib/python3.11/http/client.py", line 1289, in endheaders
    self._send_output(message_body, encode_chunked=encode_chunked)
  File "/opt/homebrew/Cellar/python@3.11/3.11.7/Frameworks/Python.framework/Versions/3.11/lib/python3.11/http/client.py", line 1048, in _send_output
    self.send(msg)
  File "/opt/homebrew/Cellar/python@3.11/3.11.7/Frameworks/Python.framework/Versions/3.11/lib/python3.11/http/client.py", line 986, in send
    self.connect()
  File "/opt/homebrew/lib/python3.11/site-packages/urllib3/connection.py", line 243, in connect
    self.sock = self._new_conn()
                ^^^^^^^^^^^^^^^^
  File "/opt/homebrew/lib/python3.11/site-packages/urllib3/connection.py", line 218, in _new_conn
    raise NewConnectionError(
urllib3.exceptions.NewConnectionError: <urllib3.connection.HTTPConnection object at 0x104192910>: Failed to establish a new connection: [Errno 61] Connection refused

The above exception was the direct cause of the following exception:

Traceback (most recent call last):
  File "/Users/frederic/tinder-bot/navigate_bumble.py", line 38, in navigate
    match_button = WebDriverWait(driver, 5).until(
                   ^^^^^^^^^^^^^^^^^^^^^^^^^^^^^^^
  File "/opt/homebrew/lib/python3.11/site-packages/selenium/webdriver/support/wait.py", line 96, in until
    value = method(self._driver)
            ^^^^^^^^^^^^^^^^^^^^
  File "/opt/homebrew/lib/python3.11/site-packages/selenium/webdriver/support/expected_conditions.py", line 84, in _predicate
    return driver.find_element(*locator)
           ^^^^^^^^^^^^^^^^^^^^^^^^^^^^^
  File "/opt/homebrew/lib/python3.11/site-packages/selenium/webdriver/remote/webdriver.py", line 741, in find_element
    return self.execute(Command.FIND_ELEMENT, {"using": by, "value": value})["value"]
           ^^^^^^^^^^^^^^^^^^^^^^^^^^^^^^^^^^^^^^^^^^^^^^^^^^^^^^^^^^^^^^^^^
  File "/opt/homebrew/lib/python3.11/site-packages/selenium/webdriver/remote/webdriver.py", line 345, in execute
    response = self.command_executor.execute(driver_command, params)
               ^^^^^^^^^^^^^^^^^^^^^^^^^^^^^^^^^^^^^^^^^^^^^^^^^^^^^
  File "/opt/homebrew/lib/python3.11/site-packages/selenium/webdriver/remote/remote_connection.py", line 302, in execute
    return self._request(command_info[0], url, body=data)
           ^^^^^^^^^^^^^^^^^^^^^^^^^^^^^^^^^^^^^^^^^^^^^^
  File "/opt/homebrew/lib/python3.11/site-packages/selenium/webdriver/remote/remote_connection.py", line 322, in _request
    response = self._conn.request(method, url, body=body, headers=headers)
               ^^^^^^^^^^^^^^^^^^^^^^^^^^^^^^^^^^^^^^^^^^^^^^^^^^^^^^^^^^^
  File "/opt/homebrew/lib/python3.11/site-packages/urllib3/_request_methods.py", line 118, in request
    return self.request_encode_body(
           ^^^^^^^^^^^^^^^^^^^^^^^^^
  File "/opt/homebrew/lib/python3.11/site-packages/urllib3/_request_methods.py", line 217, in request_encode_body
    return self.urlopen(method, url, **extra_kw)
           ^^^^^^^^^^^^^^^^^^^^^^^^^^^^^^^^^^^^^
  File "/opt/homebrew/lib/python3.11/site-packages/urllib3/poolmanager.py", line 444, in urlopen
    response = conn.urlopen(method, u.request_uri, **kw)
               ^^^^^^^^^^^^^^^^^^^^^^^^^^^^^^^^^^^^^^^^^
  File "/opt/homebrew/lib/python3.11/site-packages/urllib3/connectionpool.py", line 874, in urlopen
    return self.urlopen(
           ^^^^^^^^^^^^^
  File "/opt/homebrew/lib/python3.11/site-packages/urllib3/connectionpool.py", line 874, in urlopen
    return self.urlopen(
           ^^^^^^^^^^^^^
  File "/opt/homebrew/lib/python3.11/site-packages/urllib3/connectionpool.py", line 874, in urlopen
    return self.urlopen(
           ^^^^^^^^^^^^^
  File "/opt/homebrew/lib/python3.11/site-packages/urllib3/connectionpool.py", line 844, in urlopen
    retries = retries.increment(
              ^^^^^^^^^^^^^^^^^^
  File "/opt/homebrew/lib/python3.11/site-packages/urllib3/util/retry.py", line 515, in increment
    raise MaxRetryError(_pool, url, reason) from reason  # type: ignore[arg-type]
    ^^^^^^^^^^^^^^^^^^^^^^^^^^^^^^^^^^^^^^^^^^^^^^^^^^^
urllib3.exceptions.MaxRetryError: HTTPConnectionPool(host='localhost', port=53681): Max retries exceeded with url: /session/46c62e6286c1e6d8529f6e6cea834513/element (Caused by NewConnectionError('<urllib3.connection.HTTPConnection object at 0x104192910>: Failed to establish a new connection: [Errno 61] Connection refused'))

During handling of the above exception, another exception occurred:

Traceback (most recent call last):
  File "/opt/homebrew/Cellar/python@3.11/3.11.7/Frameworks/Python.framework/Versions/3.11/lib/python3.11/logging/__init__.py", line 1110, in emit
    msg = self.format(record)
          ^^^^^^^^^^^^^^^^^^^
  File "/opt/homebrew/Cellar/python@3.11/3.11.7/Frameworks/Python.framework/Versions/3.11/lib/python3.11/logging/__init__.py", line 953, in format
    return fmt.format(record)
           ^^^^^^^^^^^^^^^^^^
  File "/opt/homebrew/Cellar/python@3.11/3.11.7/Frameworks/Python.framework/Versions/3.11/lib/python3.11/logging/__init__.py", line 687, in format
    record.message = record.getMessage()
                     ^^^^^^^^^^^^^^^^^^^
  File "/opt/homebrew/Cellar/python@3.11/3.11.7/Frameworks/Python.framework/Versions/3.11/lib/python3.11/logging/__init__.py", line 377, in getMessage
    msg = msg % self.args
          ~~~~^~~~~~~~~~~
TypeError: not all arguments converted during string formatting
Call stack:
  File "/Users/frederic/tinder-bot/navigate_bumble.py", line 74, in <module>
    navigate(driver, is_beautiful)
  File "/Users/frederic/tinder-bot/navigate_bumble.py", line 45, in navigate
    logger.info("No match found or error occurred: ", e)
Message: 'No match found or error occurred: '
Arguments: (MaxRetryError("HTTPConnectionPool(host='localhost', port=53681): Max retries exceeded with url: /session/46c62e6286c1e6d8529f6e6cea834513/element (Caused by NewConnectionError('<urllib3.connection.HTTPConnection object at 0x104192910>: Failed to establish a new connection: [Errno 61] Connection refused'))"),)
2024-05-23 11:40:22,210 - WARNING - Retrying (Retry(total=2, connect=None, read=None, redirect=None, status=None)) after connection broken by 'NewConnectionError('<urllib3.connection.HTTPConnection object at 0x1041936d0>: Failed to establish a new connection: [Errno 61] Connection refused')': /session/46c62e6286c1e6d8529f6e6cea834513/element
2024-05-23 11:40:22,211 - WARNING - Retrying (Retry(total=1, connect=None, read=None, redirect=None, status=None)) after connection broken by 'NewConnectionError('<urllib3.connection.HTTPConnection object at 0x104264790>: Failed to establish a new connection: [Errno 61] Connection refused')': /session/46c62e6286c1e6d8529f6e6cea834513/element
2024-05-23 11:40:22,211 - WARNING - Retrying (Retry(total=0, connect=None, read=None, redirect=None, status=None)) after connection broken by 'NewConnectionError('<urllib3.connection.HTTPConnection object at 0x104265410>: Failed to establish a new connection: [Errno 61] Connection refused')': /session/46c62e6286c1e6d8529f6e6cea834513/element
2024-05-23 11:40:22,212 - ERROR - Erreur : HTTPConnectionPool(host='localhost', port=53681): Max retries exceeded with url: /session/46c62e6286c1e6d8529f6e6cea834513/element (Caused by NewConnectionError('<urllib3.connection.HTTPConnection object at 0x104266050>: Failed to establish a new connection: [Errno 61] Connection refused'))

2024-05-23 11:40:22,514 - INFO - Running extract_image_bumble.py...
2024-05-23 11:40:22,514 - INFO - Running script: /Users/frederic/tinder-bot/extract_image_bumble.py with args: []
2024-05-23 11:40:22,632 - INFO - Loading session...
Restoring session: 46c62e6286c1e6d8529f6e6cea834513, http://localhost:53681
Waiting for image element...
Erreur : HTTPConnectionPool(host='localhost', port=53681): Max retries exceeded with url: /session/46c62e6286c1e6d8529f6e6cea834513/element (Caused by NewConnectionError('<urllib3.connection.HTTPConnection object at 0x102e4a050>: Failed to establish a new connection: [Errno 61] Connection refused'))
Échec de l'extraction de l'image.

2024-05-23 11:40:22,632 - ERROR - 
2024-05-23 11:40:22,632 - INFO - Running evaluation_bumble.py...
2024-05-23 11:40:22,632 - INFO - Running script: /Users/frederic/tinder-bot/evaluation_bumble.py with args: []
2024-05-23 11:40:27,456 - INFO - Evaluating image at: /Users/frederic/tinder-bot/profile_image_bumble.jpg
Detection result: {'request_id': '1716475224,3a969c8f-1a72-4b58-bf42-0953a61e52c5', 'time_used': 108, 'faces': [{'face_token': '393d9a930f1168495fbf4a27ef967308', 'face_rectangle': {'top': 407, 'left': 336, 'width': 59, 'height': 59}, 'attributes': {'facequality': {'value': 93.634, 'threshold': 70.1}}}], 'image_id': 'qIp73WbjZGoq/zV+TpAaBQ==', 'face_num': 1}
Analyze result: {'time_used': 157, 'request_id': '1716475227,cdc5b88a-a950-45cd-9fca-1bfd7573af2e', 'faces': [{'attributes': {'gender': {'value': 'Female'}, 'age': {'value': 35}, 'beauty': {'female_score': 37.767, 'male_score': 39.408}}, 'face_rectangle': {'width': 59, 'top': 407, 'left': 336, 'height': 59}, 'face_token': '393d9a930f1168495fbf4a27ef967308'}]}
Image: Pas Belle (Female Score: 37.767, Male Score: 39.408)

2024-05-23 11:40:27,457 - ERROR - 
2024-05-23 11:40:27,457 - INFO - Evaluation result: is_beautiful=False
2024-05-23 11:40:27,457 - INFO - Running navigate_bumble.py with is_beautiful=False...
2024-05-23 11:40:27,457 - INFO - Running script: /Users/frederic/tinder-bot/navigate_bumble.py with args: ['false']
2024-05-23 11:40:27,770 - INFO - 
2024-05-23 11:40:27,770 - ERROR - 2024-05-23 11:40:27,534 - INFO - is_beautiful: False
2024-05-23 11:40:27,535 - INFO - Loading session...
2024-05-23 11:40:27,535 - INFO - Restoring session: 46c62e6286c1e6d8529f6e6cea834513, http://localhost:53681
2024-05-23 11:40:27,740 - WARNING - Retrying (Retry(total=2, connect=None, read=None, redirect=None, status=None)) after connection broken by 'NewConnectionError('<urllib3.connection.HTTPConnection object at 0x105e45550>: Failed to establish a new connection: [Errno 61] Connection refused')': /session/46c62e6286c1e6d8529f6e6cea834513/element
2024-05-23 11:40:27,741 - WARNING - Retrying (Retry(total=1, connect=None, read=None, redirect=None, status=None)) after connection broken by 'NewConnectionError('<urllib3.connection.HTTPConnection object at 0x105e59210>: Failed to establish a new connection: [Errno 61] Connection refused')': /session/46c62e6286c1e6d8529f6e6cea834513/element
2024-05-23 11:40:27,742 - WARNING - Retrying (Retry(total=0, connect=None, read=None, redirect=None, status=None)) after connection broken by 'NewConnectionError('<urllib3.connection.HTTPConnection object at 0x105e59d90>: Failed to establish a new connection: [Errno 61] Connection refused')': /session/46c62e6286c1e6d8529f6e6cea834513/element
--- Logging error ---
Traceback (most recent call last):
  File "/opt/homebrew/lib/python3.11/site-packages/urllib3/connection.py", line 203, in _new_conn
    sock = connection.create_connection(
           ^^^^^^^^^^^^^^^^^^^^^^^^^^^^^
  File "/opt/homebrew/lib/python3.11/site-packages/urllib3/util/connection.py", line 85, in create_connection
    raise err
  File "/opt/homebrew/lib/python3.11/site-packages/urllib3/util/connection.py", line 73, in create_connection
    sock.connect(sa)
ConnectionRefusedError: [Errno 61] Connection refused

The above exception was the direct cause of the following exception:

Traceback (most recent call last):
  File "/opt/homebrew/lib/python3.11/site-packages/urllib3/connectionpool.py", line 790, in urlopen
    response = self._make_request(
               ^^^^^^^^^^^^^^^^^^^
  File "/opt/homebrew/lib/python3.11/site-packages/urllib3/connectionpool.py", line 496, in _make_request
    conn.request(
  File "/opt/homebrew/lib/python3.11/site-packages/urllib3/connection.py", line 395, in request
    self.endheaders()
  File "/opt/homebrew/Cellar/python@3.11/3.11.7/Frameworks/Python.framework/Versions/3.11/lib/python3.11/http/client.py", line 1289, in endheaders
    self._send_output(message_body, encode_chunked=encode_chunked)
  File "/opt/homebrew/Cellar/python@3.11/3.11.7/Frameworks/Python.framework/Versions/3.11/lib/python3.11/http/client.py", line 1048, in _send_output
    self.send(msg)
  File "/opt/homebrew/Cellar/python@3.11/3.11.7/Frameworks/Python.framework/Versions/3.11/lib/python3.11/http/client.py", line 986, in send
    self.connect()
  File "/opt/homebrew/lib/python3.11/site-packages/urllib3/connection.py", line 243, in connect
    self.sock = self._new_conn()
                ^^^^^^^^^^^^^^^^
  File "/opt/homebrew/lib/python3.11/site-packages/urllib3/connection.py", line 218, in _new_conn
    raise NewConnectionError(
urllib3.exceptions.NewConnectionError: <urllib3.connection.HTTPConnection object at 0x105e5a910>: Failed to establish a new connection: [Errno 61] Connection refused

The above exception was the direct cause of the following exception:

Traceback (most recent call last):
  File "/Users/frederic/tinder-bot/navigate_bumble.py", line 38, in navigate
    match_button = WebDriverWait(driver, 5).until(
                   ^^^^^^^^^^^^^^^^^^^^^^^^^^^^^^^
  File "/opt/homebrew/lib/python3.11/site-packages/selenium/webdriver/support/wait.py", line 96, in until
    value = method(self._driver)
            ^^^^^^^^^^^^^^^^^^^^
  File "/opt/homebrew/lib/python3.11/site-packages/selenium/webdriver/support/expected_conditions.py", line 84, in _predicate
    return driver.find_element(*locator)
           ^^^^^^^^^^^^^^^^^^^^^^^^^^^^^
  File "/opt/homebrew/lib/python3.11/site-packages/selenium/webdriver/remote/webdriver.py", line 741, in find_element
    return self.execute(Command.FIND_ELEMENT, {"using": by, "value": value})["value"]
           ^^^^^^^^^^^^^^^^^^^^^^^^^^^^^^^^^^^^^^^^^^^^^^^^^^^^^^^^^^^^^^^^^
  File "/opt/homebrew/lib/python3.11/site-packages/selenium/webdriver/remote/webdriver.py", line 345, in execute
    response = self.command_executor.execute(driver_command, params)
               ^^^^^^^^^^^^^^^^^^^^^^^^^^^^^^^^^^^^^^^^^^^^^^^^^^^^^
  File "/opt/homebrew/lib/python3.11/site-packages/selenium/webdriver/remote/remote_connection.py", line 302, in execute
    return self._request(command_info[0], url, body=data)
           ^^^^^^^^^^^^^^^^^^^^^^^^^^^^^^^^^^^^^^^^^^^^^^
  File "/opt/homebrew/lib/python3.11/site-packages/selenium/webdriver/remote/remote_connection.py", line 322, in _request
    response = self._conn.request(method, url, body=body, headers=headers)
               ^^^^^^^^^^^^^^^^^^^^^^^^^^^^^^^^^^^^^^^^^^^^^^^^^^^^^^^^^^^
  File "/opt/homebrew/lib/python3.11/site-packages/urllib3/_request_methods.py", line 118, in request
    return self.request_encode_body(
           ^^^^^^^^^^^^^^^^^^^^^^^^^
  File "/opt/homebrew/lib/python3.11/site-packages/urllib3/_request_methods.py", line 217, in request_encode_body
    return self.urlopen(method, url, **extra_kw)
           ^^^^^^^^^^^^^^^^^^^^^^^^^^^^^^^^^^^^^
  File "/opt/homebrew/lib/python3.11/site-packages/urllib3/poolmanager.py", line 444, in urlopen
    response = conn.urlopen(method, u.request_uri, **kw)
               ^^^^^^^^^^^^^^^^^^^^^^^^^^^^^^^^^^^^^^^^^
  File "/opt/homebrew/lib/python3.11/site-packages/urllib3/connectionpool.py", line 874, in urlopen
    return self.urlopen(
           ^^^^^^^^^^^^^
  File "/opt/homebrew/lib/python3.11/site-packages/urllib3/connectionpool.py", line 874, in urlopen
    return self.urlopen(
           ^^^^^^^^^^^^^
  File "/opt/homebrew/lib/python3.11/site-packages/urllib3/connectionpool.py", line 874, in urlopen
    return self.urlopen(
           ^^^^^^^^^^^^^
  File "/opt/homebrew/lib/python3.11/site-packages/urllib3/connectionpool.py", line 844, in urlopen
    retries = retries.increment(
              ^^^^^^^^^^^^^^^^^^
  File "/opt/homebrew/lib/python3.11/site-packages/urllib3/util/retry.py", line 515, in increment
    raise MaxRetryError(_pool, url, reason) from reason  # type: ignore[arg-type]
    ^^^^^^^^^^^^^^^^^^^^^^^^^^^^^^^^^^^^^^^^^^^^^^^^^^^
urllib3.exceptions.MaxRetryError: HTTPConnectionPool(host='localhost', port=53681): Max retries exceeded with url: /session/46c62e6286c1e6d8529f6e6cea834513/element (Caused by NewConnectionError('<urllib3.connection.HTTPConnection object at 0x105e5a910>: Failed to establish a new connection: [Errno 61] Connection refused'))

During handling of the above exception, another exception occurred:

Traceback (most recent call last):
  File "/opt/homebrew/Cellar/python@3.11/3.11.7/Frameworks/Python.framework/Versions/3.11/lib/python3.11/logging/__init__.py", line 1110, in emit
    msg = self.format(record)
          ^^^^^^^^^^^^^^^^^^^
  File "/opt/homebrew/Cellar/python@3.11/3.11.7/Frameworks/Python.framework/Versions/3.11/lib/python3.11/logging/__init__.py", line 953, in format
    return fmt.format(record)
           ^^^^^^^^^^^^^^^^^^
  File "/opt/homebrew/Cellar/python@3.11/3.11.7/Frameworks/Python.framework/Versions/3.11/lib/python3.11/logging/__init__.py", line 687, in format
    record.message = record.getMessage()
                     ^^^^^^^^^^^^^^^^^^^
  File "/opt/homebrew/Cellar/python@3.11/3.11.7/Frameworks/Python.framework/Versions/3.11/lib/python3.11/logging/__init__.py", line 377, in getMessage
    msg = msg % self.args
          ~~~~^~~~~~~~~~~
TypeError: not all arguments converted during string formatting
Call stack:
  File "/Users/frederic/tinder-bot/navigate_bumble.py", line 74, in <module>
    navigate(driver, is_beautiful)
  File "/Users/frederic/tinder-bot/navigate_bumble.py", line 45, in navigate
    logger.info("No match found or error occurred: ", e)
Message: 'No match found or error occurred: '
Arguments: (MaxRetryError("HTTPConnectionPool(host='localhost', port=53681): Max retries exceeded with url: /session/46c62e6286c1e6d8529f6e6cea834513/element (Caused by NewConnectionError('<urllib3.connection.HTTPConnection object at 0x105e5a910>: Failed to establish a new connection: [Errno 61] Connection refused'))"),)
2024-05-23 11:40:27,749 - WARNING - Retrying (Retry(total=2, connect=None, read=None, redirect=None, status=None)) after connection broken by 'NewConnectionError('<urllib3.connection.HTTPConnection object at 0x105e5b6d0>: Failed to establish a new connection: [Errno 61] Connection refused')': /session/46c62e6286c1e6d8529f6e6cea834513/element
2024-05-23 11:40:27,750 - WARNING - Retrying (Retry(total=1, connect=None, read=None, redirect=None, status=None)) after connection broken by 'NewConnectionError('<urllib3.connection.HTTPConnection object at 0x105f2c790>: Failed to establish a new connection: [Errno 61] Connection refused')': /session/46c62e6286c1e6d8529f6e6cea834513/element
2024-05-23 11:40:27,751 - WARNING - Retrying (Retry(total=0, connect=None, read=None, redirect=None, status=None)) after connection broken by 'NewConnectionError('<urllib3.connection.HTTPConnection object at 0x105f2d410>: Failed to establish a new connection: [Errno 61] Connection refused')': /session/46c62e6286c1e6d8529f6e6cea834513/element
2024-05-23 11:40:27,752 - ERROR - Erreur : HTTPConnectionPool(host='localhost', port=53681): Max retries exceeded with url: /session/46c62e6286c1e6d8529f6e6cea834513/element (Caused by NewConnectionError('<urllib3.connection.HTTPConnection object at 0x105f2e050>: Failed to establish a new connection: [Errno 61] Connection refused'))

2024-05-23 11:40:28,004 - INFO - Running extract_image_bumble.py...
2024-05-23 11:40:28,005 - INFO - Running script: /Users/frederic/tinder-bot/extract_image_bumble.py with args: []
2024-05-23 11:40:28,134 - INFO - Loading session...
Restoring session: 46c62e6286c1e6d8529f6e6cea834513, http://localhost:53681
Waiting for image element...
Erreur : HTTPConnectionPool(host='localhost', port=53681): Max retries exceeded with url: /session/46c62e6286c1e6d8529f6e6cea834513/element (Caused by NewConnectionError('<urllib3.connection.HTTPConnection object at 0x107966050>: Failed to establish a new connection: [Errno 61] Connection refused'))
Échec de l'extraction de l'image.

2024-05-23 11:40:28,134 - ERROR - 
2024-05-23 11:40:28,134 - INFO - Running evaluation_bumble.py...
2024-05-23 11:40:28,134 - INFO - Running script: /Users/frederic/tinder-bot/evaluation_bumble.py with args: []
2024-05-23 11:40:32,697 - INFO - Evaluating image at: /Users/frederic/tinder-bot/profile_image_bumble.jpg
Detection result: {'request_id': '1716475229,cfb31dbe-6dbe-471f-b1f3-1ad4ddf95e70', 'time_used': 236, 'faces': [{'face_token': '7dec450447c3a3042d133eb6bf00383a', 'face_rectangle': {'top': 407, 'left': 336, 'width': 59, 'height': 59}, 'attributes': {'facequality': {'value': 93.634, 'threshold': 70.1}}}], 'image_id': 'qIp73WbjZGoq/zV+TpAaBQ==', 'face_num': 1}
Analyze result: {'time_used': 126, 'request_id': '1716475232,0f003df2-8b34-418f-b7ca-9042db39606d', 'faces': [{'attributes': {'gender': {'value': 'Female'}, 'age': {'value': 35}, 'beauty': {'female_score': 37.767, 'male_score': 39.408}}, 'face_rectangle': {'width': 59, 'top': 407, 'left': 336, 'height': 59}, 'face_token': '7dec450447c3a3042d133eb6bf00383a'}]}
Image: Pas Belle (Female Score: 37.767, Male Score: 39.408)

2024-05-23 11:40:32,697 - ERROR - 
2024-05-23 11:40:32,697 - INFO - Evaluation result: is_beautiful=False
2024-05-23 11:40:32,697 - INFO - Running navigate_bumble.py with is_beautiful=False...
2024-05-23 11:40:32,698 - INFO - Running script: /Users/frederic/tinder-bot/navigate_bumble.py with args: ['false']
2024-05-23 11:40:32,924 - INFO - 
2024-05-23 11:40:32,924 - ERROR - 2024-05-23 11:40:32,779 - INFO - is_beautiful: False
2024-05-23 11:40:32,779 - INFO - Loading session...
2024-05-23 11:40:32,779 - INFO - Restoring session: 46c62e6286c1e6d8529f6e6cea834513, http://localhost:53681
2024-05-23 11:40:32,901 - WARNING - Retrying (Retry(total=2, connect=None, read=None, redirect=None, status=None)) after connection broken by 'NewConnectionError('<urllib3.connection.HTTPConnection object at 0x1024e1550>: Failed to establish a new connection: [Errno 61] Connection refused')': /session/46c62e6286c1e6d8529f6e6cea834513/element
2024-05-23 11:40:32,902 - WARNING - Retrying (Retry(total=1, connect=None, read=None, redirect=None, status=None)) after connection broken by 'NewConnectionError('<urllib3.connection.HTTPConnection object at 0x1024f5210>: Failed to establish a new connection: [Errno 61] Connection refused')': /session/46c62e6286c1e6d8529f6e6cea834513/element
2024-05-23 11:40:32,903 - WARNING - Retrying (Retry(total=0, connect=None, read=None, redirect=None, status=None)) after connection broken by 'NewConnectionError('<urllib3.connection.HTTPConnection object at 0x1024f5d90>: Failed to establish a new connection: [Errno 61] Connection refused')': /session/46c62e6286c1e6d8529f6e6cea834513/element
--- Logging error ---
Traceback (most recent call last):
  File "/opt/homebrew/lib/python3.11/site-packages/urllib3/connection.py", line 203, in _new_conn
    sock = connection.create_connection(
           ^^^^^^^^^^^^^^^^^^^^^^^^^^^^^
  File "/opt/homebrew/lib/python3.11/site-packages/urllib3/util/connection.py", line 85, in create_connection
    raise err
  File "/opt/homebrew/lib/python3.11/site-packages/urllib3/util/connection.py", line 73, in create_connection
    sock.connect(sa)
ConnectionRefusedError: [Errno 61] Connection refused

The above exception was the direct cause of the following exception:

Traceback (most recent call last):
  File "/opt/homebrew/lib/python3.11/site-packages/urllib3/connectionpool.py", line 790, in urlopen
    response = self._make_request(
               ^^^^^^^^^^^^^^^^^^^
  File "/opt/homebrew/lib/python3.11/site-packages/urllib3/connectionpool.py", line 496, in _make_request
    conn.request(
  File "/opt/homebrew/lib/python3.11/site-packages/urllib3/connection.py", line 395, in request
    self.endheaders()
  File "/opt/homebrew/Cellar/python@3.11/3.11.7/Frameworks/Python.framework/Versions/3.11/lib/python3.11/http/client.py", line 1289, in endheaders
    self._send_output(message_body, encode_chunked=encode_chunked)
  File "/opt/homebrew/Cellar/python@3.11/3.11.7/Frameworks/Python.framework/Versions/3.11/lib/python3.11/http/client.py", line 1048, in _send_output
    self.send(msg)
  File "/opt/homebrew/Cellar/python@3.11/3.11.7/Frameworks/Python.framework/Versions/3.11/lib/python3.11/http/client.py", line 986, in send
    self.connect()
  File "/opt/homebrew/lib/python3.11/site-packages/urllib3/connection.py", line 243, in connect
    self.sock = self._new_conn()
                ^^^^^^^^^^^^^^^^
  File "/opt/homebrew/lib/python3.11/site-packages/urllib3/connection.py", line 218, in _new_conn
    raise NewConnectionError(
urllib3.exceptions.NewConnectionError: <urllib3.connection.HTTPConnection object at 0x1024f6910>: Failed to establish a new connection: [Errno 61] Connection refused

The above exception was the direct cause of the following exception:

Traceback (most recent call last):
  File "/Users/frederic/tinder-bot/navigate_bumble.py", line 38, in navigate
    match_button = WebDriverWait(driver, 5).until(
                   ^^^^^^^^^^^^^^^^^^^^^^^^^^^^^^^
  File "/opt/homebrew/lib/python3.11/site-packages/selenium/webdriver/support/wait.py", line 96, in until
    value = method(self._driver)
            ^^^^^^^^^^^^^^^^^^^^
  File "/opt/homebrew/lib/python3.11/site-packages/selenium/webdriver/support/expected_conditions.py", line 84, in _predicate
    return driver.find_element(*locator)
           ^^^^^^^^^^^^^^^^^^^^^^^^^^^^^
  File "/opt/homebrew/lib/python3.11/site-packages/selenium/webdriver/remote/webdriver.py", line 741, in find_element
    return self.execute(Command.FIND_ELEMENT, {"using": by, "value": value})["value"]
           ^^^^^^^^^^^^^^^^^^^^^^^^^^^^^^^^^^^^^^^^^^^^^^^^^^^^^^^^^^^^^^^^^
  File "/opt/homebrew/lib/python3.11/site-packages/selenium/webdriver/remote/webdriver.py", line 345, in execute
    response = self.command_executor.execute(driver_command, params)
               ^^^^^^^^^^^^^^^^^^^^^^^^^^^^^^^^^^^^^^^^^^^^^^^^^^^^^
  File "/opt/homebrew/lib/python3.11/site-packages/selenium/webdriver/remote/remote_connection.py", line 302, in execute
    return self._request(command_info[0], url, body=data)
           ^^^^^^^^^^^^^^^^^^^^^^^^^^^^^^^^^^^^^^^^^^^^^^
  File "/opt/homebrew/lib/python3.11/site-packages/selenium/webdriver/remote/remote_connection.py", line 322, in _request
    response = self._conn.request(method, url, body=body, headers=headers)
               ^^^^^^^^^^^^^^^^^^^^^^^^^^^^^^^^^^^^^^^^^^^^^^^^^^^^^^^^^^^
  File "/opt/homebrew/lib/python3.11/site-packages/urllib3/_request_methods.py", line 118, in request
    return self.request_encode_body(
           ^^^^^^^^^^^^^^^^^^^^^^^^^
  File "/opt/homebrew/lib/python3.11/site-packages/urllib3/_request_methods.py", line 217, in request_encode_body
    return self.urlopen(method, url, **extra_kw)
           ^^^^^^^^^^^^^^^^^^^^^^^^^^^^^^^^^^^^^
  File "/opt/homebrew/lib/python3.11/site-packages/urllib3/poolmanager.py", line 444, in urlopen
    response = conn.urlopen(method, u.request_uri, **kw)
               ^^^^^^^^^^^^^^^^^^^^^^^^^^^^^^^^^^^^^^^^^
  File "/opt/homebrew/lib/python3.11/site-packages/urllib3/connectionpool.py", line 874, in urlopen
    return self.urlopen(
           ^^^^^^^^^^^^^
  File "/opt/homebrew/lib/python3.11/site-packages/urllib3/connectionpool.py", line 874, in urlopen
    return self.urlopen(
           ^^^^^^^^^^^^^
  File "/opt/homebrew/lib/python3.11/site-packages/urllib3/connectionpool.py", line 874, in urlopen
    return self.urlopen(
           ^^^^^^^^^^^^^
  File "/opt/homebrew/lib/python3.11/site-packages/urllib3/connectionpool.py", line 844, in urlopen
    retries = retries.increment(
              ^^^^^^^^^^^^^^^^^^
  File "/opt/homebrew/lib/python3.11/site-packages/urllib3/util/retry.py", line 515, in increment
    raise MaxRetryError(_pool, url, reason) from reason  # type: ignore[arg-type]
    ^^^^^^^^^^^^^^^^^^^^^^^^^^^^^^^^^^^^^^^^^^^^^^^^^^^
urllib3.exceptions.MaxRetryError: HTTPConnectionPool(host='localhost', port=53681): Max retries exceeded with url: /session/46c62e6286c1e6d8529f6e6cea834513/element (Caused by NewConnectionError('<urllib3.connection.HTTPConnection object at 0x1024f6910>: Failed to establish a new connection: [Errno 61] Connection refused'))

During handling of the above exception, another exception occurred:

Traceback (most recent call last):
  File "/opt/homebrew/Cellar/python@3.11/3.11.7/Frameworks/Python.framework/Versions/3.11/lib/python3.11/logging/__init__.py", line 1110, in emit
    msg = self.format(record)
          ^^^^^^^^^^^^^^^^^^^
  File "/opt/homebrew/Cellar/python@3.11/3.11.7/Frameworks/Python.framework/Versions/3.11/lib/python3.11/logging/__init__.py", line 953, in format
    return fmt.format(record)
           ^^^^^^^^^^^^^^^^^^
  File "/opt/homebrew/Cellar/python@3.11/3.11.7/Frameworks/Python.framework/Versions/3.11/lib/python3.11/logging/__init__.py", line 687, in format
    record.message = record.getMessage()
                     ^^^^^^^^^^^^^^^^^^^
  File "/opt/homebrew/Cellar/python@3.11/3.11.7/Frameworks/Python.framework/Versions/3.11/lib/python3.11/logging/__init__.py", line 377, in getMessage
    msg = msg % self.args
          ~~~~^~~~~~~~~~~
TypeError: not all arguments converted during string formatting
Call stack:
  File "/Users/frederic/tinder-bot/navigate_bumble.py", line 74, in <module>
    navigate(driver, is_beautiful)
  File "/Users/frederic/tinder-bot/navigate_bumble.py", line 45, in navigate
    logger.info("No match found or error occurred: ", e)
Message: 'No match found or error occurred: '
Arguments: (MaxRetryError("HTTPConnectionPool(host='localhost', port=53681): Max retries exceeded with url: /session/46c62e6286c1e6d8529f6e6cea834513/element (Caused by NewConnectionError('<urllib3.connection.HTTPConnection object at 0x1024f6910>: Failed to establish a new connection: [Errno 61] Connection refused'))"),)
2024-05-23 11:40:32,908 - WARNING - Retrying (Retry(total=2, connect=None, read=None, redirect=None, status=None)) after connection broken by 'NewConnectionError('<urllib3.connection.HTTPConnection object at 0x1024f76d0>: Failed to establish a new connection: [Errno 61] Connection refused')': /session/46c62e6286c1e6d8529f6e6cea834513/element
2024-05-23 11:40:32,909 - WARNING - Retrying (Retry(total=1, connect=None, read=None, redirect=None, status=None)) after connection broken by 'NewConnectionError('<urllib3.connection.HTTPConnection object at 0x1025c8790>: Failed to establish a new connection: [Errno 61] Connection refused')': /session/46c62e6286c1e6d8529f6e6cea834513/element
2024-05-23 11:40:32,909 - WARNING - Retrying (Retry(total=0, connect=None, read=None, redirect=None, status=None)) after connection broken by 'NewConnectionError('<urllib3.connection.HTTPConnection object at 0x1025c9410>: Failed to establish a new connection: [Errno 61] Connection refused')': /session/46c62e6286c1e6d8529f6e6cea834513/element
2024-05-23 11:40:32,910 - ERROR - Erreur : HTTPConnectionPool(host='localhost', port=53681): Max retries exceeded with url: /session/46c62e6286c1e6d8529f6e6cea834513/element (Caused by NewConnectionError('<urllib3.connection.HTTPConnection object at 0x1025ca050>: Failed to establish a new connection: [Errno 61] Connection refused'))

2024-05-23 11:40:33,180 - INFO - Running extract_image_bumble.py...
2024-05-23 11:40:33,180 - INFO - Running script: /Users/frederic/tinder-bot/extract_image_bumble.py with args: []
2024-05-23 11:40:33,316 - INFO - Loading session...
Restoring session: 46c62e6286c1e6d8529f6e6cea834513, http://localhost:53681
Waiting for image element...
Erreur : HTTPConnectionPool(host='localhost', port=53681): Max retries exceeded with url: /session/46c62e6286c1e6d8529f6e6cea834513/element (Caused by NewConnectionError('<urllib3.connection.HTTPConnection object at 0x102536050>: Failed to establish a new connection: [Errno 61] Connection refused'))
Échec de l'extraction de l'image.

2024-05-23 11:40:33,316 - ERROR - 
2024-05-23 11:40:33,316 - INFO - Running evaluation_bumble.py...
2024-05-23 11:40:33,316 - INFO - Running script: /Users/frederic/tinder-bot/evaluation_bumble.py with args: []
2024-05-23 11:40:37,783 - INFO - Evaluating image at: /Users/frederic/tinder-bot/profile_image_bumble.jpg
Detection result: {'request_id': '1716475234,9178f9cc-5bc6-4bb1-8b4b-041bb89c138e', 'time_used': 114, 'faces': [{'face_token': 'ff3cc1ca4e189544c5ab6aebc738848c', 'face_rectangle': {'top': 407, 'left': 336, 'width': 59, 'height': 59}, 'attributes': {'facequality': {'value': 93.634, 'threshold': 70.1}}}], 'image_id': 'qIp73WbjZGoq/zV+TpAaBQ==', 'face_num': 1}
Analyze result: {'time_used': 103, 'request_id': '1716475237,3a71164f-e593-4e77-a5d6-fb7e77ac90b9', 'faces': [{'attributes': {'gender': {'value': 'Female'}, 'age': {'value': 35}, 'beauty': {'female_score': 37.767, 'male_score': 39.408}}, 'face_rectangle': {'width': 59, 'top': 407, 'left': 336, 'height': 59}, 'face_token': 'ff3cc1ca4e189544c5ab6aebc738848c'}]}
Image: Pas Belle (Female Score: 37.767, Male Score: 39.408)

2024-05-23 11:40:37,783 - ERROR - 
2024-05-23 11:40:37,783 - INFO - Evaluation result: is_beautiful=False
2024-05-23 11:40:37,783 - INFO - Running navigate_bumble.py with is_beautiful=False...
2024-05-23 11:40:37,783 - INFO - Running script: /Users/frederic/tinder-bot/navigate_bumble.py with args: ['false']
2024-05-23 11:40:38,062 - INFO - 
2024-05-23 11:40:38,062 - ERROR - 2024-05-23 11:40:37,861 - INFO - is_beautiful: False
2024-05-23 11:40:37,861 - INFO - Loading session...
2024-05-23 11:40:37,861 - INFO - Restoring session: 46c62e6286c1e6d8529f6e6cea834513, http://localhost:53681
2024-05-23 11:40:38,033 - WARNING - Retrying (Retry(total=2, connect=None, read=None, redirect=None, status=None)) after connection broken by 'NewConnectionError('<urllib3.connection.HTTPConnection object at 0x105cd1550>: Failed to establish a new connection: [Errno 61] Connection refused')': /session/46c62e6286c1e6d8529f6e6cea834513/element
2024-05-23 11:40:38,035 - WARNING - Retrying (Retry(total=1, connect=None, read=None, redirect=None, status=None)) after connection broken by 'NewConnectionError('<urllib3.connection.HTTPConnection object at 0x105ce5210>: Failed to establish a new connection: [Errno 61] Connection refused')': /session/46c62e6286c1e6d8529f6e6cea834513/element
2024-05-23 11:40:38,035 - WARNING - Retrying (Retry(total=0, connect=None, read=None, redirect=None, status=None)) after connection broken by 'NewConnectionError('<urllib3.connection.HTTPConnection object at 0x105ce5d90>: Failed to establish a new connection: [Errno 61] Connection refused')': /session/46c62e6286c1e6d8529f6e6cea834513/element
--- Logging error ---
Traceback (most recent call last):
  File "/opt/homebrew/lib/python3.11/site-packages/urllib3/connection.py", line 203, in _new_conn
    sock = connection.create_connection(
           ^^^^^^^^^^^^^^^^^^^^^^^^^^^^^
  File "/opt/homebrew/lib/python3.11/site-packages/urllib3/util/connection.py", line 85, in create_connection
    raise err
  File "/opt/homebrew/lib/python3.11/site-packages/urllib3/util/connection.py", line 73, in create_connection
    sock.connect(sa)
ConnectionRefusedError: [Errno 61] Connection refused

The above exception was the direct cause of the following exception:

Traceback (most recent call last):
  File "/opt/homebrew/lib/python3.11/site-packages/urllib3/connectionpool.py", line 790, in urlopen
    response = self._make_request(
               ^^^^^^^^^^^^^^^^^^^
  File "/opt/homebrew/lib/python3.11/site-packages/urllib3/connectionpool.py", line 496, in _make_request
    conn.request(
  File "/opt/homebrew/lib/python3.11/site-packages/urllib3/connection.py", line 395, in request
    self.endheaders()
  File "/opt/homebrew/Cellar/python@3.11/3.11.7/Frameworks/Python.framework/Versions/3.11/lib/python3.11/http/client.py", line 1289, in endheaders
    self._send_output(message_body, encode_chunked=encode_chunked)
  File "/opt/homebrew/Cellar/python@3.11/3.11.7/Frameworks/Python.framework/Versions/3.11/lib/python3.11/http/client.py", line 1048, in _send_output
    self.send(msg)
  File "/opt/homebrew/Cellar/python@3.11/3.11.7/Frameworks/Python.framework/Versions/3.11/lib/python3.11/http/client.py", line 986, in send
    self.connect()
  File "/opt/homebrew/lib/python3.11/site-packages/urllib3/connection.py", line 243, in connect
    self.sock = self._new_conn()
                ^^^^^^^^^^^^^^^^
  File "/opt/homebrew/lib/python3.11/site-packages/urllib3/connection.py", line 218, in _new_conn
    raise NewConnectionError(
urllib3.exceptions.NewConnectionError: <urllib3.connection.HTTPConnection object at 0x105ce6910>: Failed to establish a new connection: [Errno 61] Connection refused

The above exception was the direct cause of the following exception:

Traceback (most recent call last):
  File "/Users/frederic/tinder-bot/navigate_bumble.py", line 38, in navigate
    match_button = WebDriverWait(driver, 5).until(
                   ^^^^^^^^^^^^^^^^^^^^^^^^^^^^^^^
  File "/opt/homebrew/lib/python3.11/site-packages/selenium/webdriver/support/wait.py", line 96, in until
    value = method(self._driver)
            ^^^^^^^^^^^^^^^^^^^^
  File "/opt/homebrew/lib/python3.11/site-packages/selenium/webdriver/support/expected_conditions.py", line 84, in _predicate
    return driver.find_element(*locator)
           ^^^^^^^^^^^^^^^^^^^^^^^^^^^^^
  File "/opt/homebrew/lib/python3.11/site-packages/selenium/webdriver/remote/webdriver.py", line 741, in find_element
    return self.execute(Command.FIND_ELEMENT, {"using": by, "value": value})["value"]
           ^^^^^^^^^^^^^^^^^^^^^^^^^^^^^^^^^^^^^^^^^^^^^^^^^^^^^^^^^^^^^^^^^
  File "/opt/homebrew/lib/python3.11/site-packages/selenium/webdriver/remote/webdriver.py", line 345, in execute
    response = self.command_executor.execute(driver_command, params)
               ^^^^^^^^^^^^^^^^^^^^^^^^^^^^^^^^^^^^^^^^^^^^^^^^^^^^^
  File "/opt/homebrew/lib/python3.11/site-packages/selenium/webdriver/remote/remote_connection.py", line 302, in execute
    return self._request(command_info[0], url, body=data)
           ^^^^^^^^^^^^^^^^^^^^^^^^^^^^^^^^^^^^^^^^^^^^^^
  File "/opt/homebrew/lib/python3.11/site-packages/selenium/webdriver/remote/remote_connection.py", line 322, in _request
    response = self._conn.request(method, url, body=body, headers=headers)
               ^^^^^^^^^^^^^^^^^^^^^^^^^^^^^^^^^^^^^^^^^^^^^^^^^^^^^^^^^^^
  File "/opt/homebrew/lib/python3.11/site-packages/urllib3/_request_methods.py", line 118, in request
    return self.request_encode_body(
           ^^^^^^^^^^^^^^^^^^^^^^^^^
  File "/opt/homebrew/lib/python3.11/site-packages/urllib3/_request_methods.py", line 217, in request_encode_body
    return self.urlopen(method, url, **extra_kw)
           ^^^^^^^^^^^^^^^^^^^^^^^^^^^^^^^^^^^^^
  File "/opt/homebrew/lib/python3.11/site-packages/urllib3/poolmanager.py", line 444, in urlopen
    response = conn.urlopen(method, u.request_uri, **kw)
               ^^^^^^^^^^^^^^^^^^^^^^^^^^^^^^^^^^^^^^^^^
  File "/opt/homebrew/lib/python3.11/site-packages/urllib3/connectionpool.py", line 874, in urlopen
    return self.urlopen(
           ^^^^^^^^^^^^^
  File "/opt/homebrew/lib/python3.11/site-packages/urllib3/connectionpool.py", line 874, in urlopen
    return self.urlopen(
           ^^^^^^^^^^^^^
  File "/opt/homebrew/lib/python3.11/site-packages/urllib3/connectionpool.py", line 874, in urlopen
    return self.urlopen(
           ^^^^^^^^^^^^^
  File "/opt/homebrew/lib/python3.11/site-packages/urllib3/connectionpool.py", line 844, in urlopen
    retries = retries.increment(
              ^^^^^^^^^^^^^^^^^^
  File "/opt/homebrew/lib/python3.11/site-packages/urllib3/util/retry.py", line 515, in increment
    raise MaxRetryError(_pool, url, reason) from reason  # type: ignore[arg-type]
    ^^^^^^^^^^^^^^^^^^^^^^^^^^^^^^^^^^^^^^^^^^^^^^^^^^^
urllib3.exceptions.MaxRetryError: HTTPConnectionPool(host='localhost', port=53681): Max retries exceeded with url: /session/46c62e6286c1e6d8529f6e6cea834513/element (Caused by NewConnectionError('<urllib3.connection.HTTPConnection object at 0x105ce6910>: Failed to establish a new connection: [Errno 61] Connection refused'))

During handling of the above exception, another exception occurred:

Traceback (most recent call last):
  File "/opt/homebrew/Cellar/python@3.11/3.11.7/Frameworks/Python.framework/Versions/3.11/lib/python3.11/logging/__init__.py", line 1110, in emit
    msg = self.format(record)
          ^^^^^^^^^^^^^^^^^^^
  File "/opt/homebrew/Cellar/python@3.11/3.11.7/Frameworks/Python.framework/Versions/3.11/lib/python3.11/logging/__init__.py", line 953, in format
    return fmt.format(record)
           ^^^^^^^^^^^^^^^^^^
  File "/opt/homebrew/Cellar/python@3.11/3.11.7/Frameworks/Python.framework/Versions/3.11/lib/python3.11/logging/__init__.py", line 687, in format
    record.message = record.getMessage()
                     ^^^^^^^^^^^^^^^^^^^
  File "/opt/homebrew/Cellar/python@3.11/3.11.7/Frameworks/Python.framework/Versions/3.11/lib/python3.11/logging/__init__.py", line 377, in getMessage
    msg = msg % self.args
          ~~~~^~~~~~~~~~~
TypeError: not all arguments converted during string formatting
Call stack:
  File "/Users/frederic/tinder-bot/navigate_bumble.py", line 74, in <module>
    navigate(driver, is_beautiful)
  File "/Users/frederic/tinder-bot/navigate_bumble.py", line 45, in navigate
    logger.info("No match found or error occurred: ", e)
Message: 'No match found or error occurred: '
Arguments: (MaxRetryError("HTTPConnectionPool(host='localhost', port=53681): Max retries exceeded with url: /session/46c62e6286c1e6d8529f6e6cea834513/element (Caused by NewConnectionError('<urllib3.connection.HTTPConnection object at 0x105ce6910>: Failed to establish a new connection: [Errno 61] Connection refused'))"),)
2024-05-23 11:40:38,042 - WARNING - Retrying (Retry(total=2, connect=None, read=None, redirect=None, status=None)) after connection broken by 'NewConnectionError('<urllib3.connection.HTTPConnection object at 0x105ce76d0>: Failed to establish a new connection: [Errno 61] Connection refused')': /session/46c62e6286c1e6d8529f6e6cea834513/element
2024-05-23 11:40:38,043 - WARNING - Retrying (Retry(total=1, connect=None, read=None, redirect=None, status=None)) after connection broken by 'NewConnectionError('<urllib3.connection.HTTPConnection object at 0x105db8790>: Failed to establish a new connection: [Errno 61] Connection refused')': /session/46c62e6286c1e6d8529f6e6cea834513/element
2024-05-23 11:40:38,043 - WARNING - Retrying (Retry(total=0, connect=None, read=None, redirect=None, status=None)) after connection broken by 'NewConnectionError('<urllib3.connection.HTTPConnection object at 0x105db9410>: Failed to establish a new connection: [Errno 61] Connection refused')': /session/46c62e6286c1e6d8529f6e6cea834513/element
2024-05-23 11:40:38,044 - ERROR - Erreur : HTTPConnectionPool(host='localhost', port=53681): Max retries exceeded with url: /session/46c62e6286c1e6d8529f6e6cea834513/element (Caused by NewConnectionError('<urllib3.connection.HTTPConnection object at 0x105dba050>: Failed to establish a new connection: [Errno 61] Connection refused'))

2024-05-23 11:40:38,292 - INFO - Running extract_image_bumble.py...
2024-05-23 11:40:38,292 - INFO - Running script: /Users/frederic/tinder-bot/extract_image_bumble.py with args: []
2024-05-23 11:40:38,448 - INFO - Loading session...
Restoring session: 46c62e6286c1e6d8529f6e6cea834513, http://localhost:53681
Waiting for image element...
Erreur : HTTPConnectionPool(host='localhost', port=53681): Max retries exceeded with url: /session/46c62e6286c1e6d8529f6e6cea834513/element (Caused by NewConnectionError('<urllib3.connection.HTTPConnection object at 0x112106190>: Failed to establish a new connection: [Errno 61] Connection refused'))
Échec de l'extraction de l'image.

2024-05-23 11:40:38,448 - ERROR - 
2024-05-23 11:40:38,448 - INFO - Running evaluation_bumble.py...
2024-05-23 11:40:38,448 - INFO - Running script: /Users/frederic/tinder-bot/evaluation_bumble.py with args: []
2024-05-23 11:40:42,871 - INFO - Evaluating image at: /Users/frederic/tinder-bot/profile_image_bumble.jpg
Detection result: {'request_id': '1716475239,d7b01ae4-ded5-4284-b60f-c5a91dd3f679', 'time_used': 143, 'faces': [{'face_token': '3c7c2dd5c0e9b56bcdd8b6f27bf5681b', 'face_rectangle': {'top': 407, 'left': 336, 'width': 59, 'height': 59}, 'attributes': {'facequality': {'value': 93.634, 'threshold': 70.1}}}], 'image_id': 'qIp73WbjZGoq/zV+TpAaBQ==', 'face_num': 1}
Analyze result: {'time_used': 71, 'request_id': '1716475242,9bd2fe70-726a-4cf6-a466-fc2ffa469c34', 'faces': [{'attributes': {'gender': {'value': 'Female'}, 'age': {'value': 35}, 'beauty': {'female_score': 37.767, 'male_score': 39.408}}, 'face_rectangle': {'width': 59, 'top': 407, 'left': 336, 'height': 59}, 'face_token': '3c7c2dd5c0e9b56bcdd8b6f27bf5681b'}]}
Image: Pas Belle (Female Score: 37.767, Male Score: 39.408)

2024-05-23 11:40:42,871 - ERROR - 
2024-05-23 11:40:42,871 - INFO - Evaluation result: is_beautiful=False
2024-05-23 11:40:42,871 - INFO - Running navigate_bumble.py with is_beautiful=False...
2024-05-23 11:40:42,871 - INFO - Running script: /Users/frederic/tinder-bot/navigate_bumble.py with args: ['false']
2024-05-23 11:40:43,261 - INFO - 
2024-05-23 11:40:43,261 - ERROR - 2024-05-23 11:40:42,952 - INFO - is_beautiful: False
2024-05-23 11:40:42,952 - INFO - Loading session...
2024-05-23 11:40:42,952 - INFO - Restoring session: 46c62e6286c1e6d8529f6e6cea834513, http://localhost:53681
2024-05-23 11:40:43,226 - WARNING - Retrying (Retry(total=2, connect=None, read=None, redirect=None, status=None)) after connection broken by 'NewConnectionError('<urllib3.connection.HTTPConnection object at 0x1065cd550>: Failed to establish a new connection: [Errno 61] Connection refused')': /session/46c62e6286c1e6d8529f6e6cea834513/element
2024-05-23 11:40:43,228 - WARNING - Retrying (Retry(total=1, connect=None, read=None, redirect=None, status=None)) after connection broken by 'NewConnectionError('<urllib3.connection.HTTPConnection object at 0x1065e1210>: Failed to establish a new connection: [Errno 61] Connection refused')': /session/46c62e6286c1e6d8529f6e6cea834513/element
2024-05-23 11:40:43,229 - WARNING - Retrying (Retry(total=0, connect=None, read=None, redirect=None, status=None)) after connection broken by 'NewConnectionError('<urllib3.connection.HTTPConnection object at 0x1065e1d90>: Failed to establish a new connection: [Errno 61] Connection refused')': /session/46c62e6286c1e6d8529f6e6cea834513/element
--- Logging error ---
Traceback (most recent call last):
  File "/opt/homebrew/lib/python3.11/site-packages/urllib3/connection.py", line 203, in _new_conn
    sock = connection.create_connection(
           ^^^^^^^^^^^^^^^^^^^^^^^^^^^^^
  File "/opt/homebrew/lib/python3.11/site-packages/urllib3/util/connection.py", line 85, in create_connection
    raise err
  File "/opt/homebrew/lib/python3.11/site-packages/urllib3/util/connection.py", line 73, in create_connection
    sock.connect(sa)
ConnectionRefusedError: [Errno 61] Connection refused

The above exception was the direct cause of the following exception:

Traceback (most recent call last):
  File "/opt/homebrew/lib/python3.11/site-packages/urllib3/connectionpool.py", line 790, in urlopen
    response = self._make_request(
               ^^^^^^^^^^^^^^^^^^^
  File "/opt/homebrew/lib/python3.11/site-packages/urllib3/connectionpool.py", line 496, in _make_request
    conn.request(
  File "/opt/homebrew/lib/python3.11/site-packages/urllib3/connection.py", line 395, in request
    self.endheaders()
  File "/opt/homebrew/Cellar/python@3.11/3.11.7/Frameworks/Python.framework/Versions/3.11/lib/python3.11/http/client.py", line 1289, in endheaders
    self._send_output(message_body, encode_chunked=encode_chunked)
  File "/opt/homebrew/Cellar/python@3.11/3.11.7/Frameworks/Python.framework/Versions/3.11/lib/python3.11/http/client.py", line 1048, in _send_output
    self.send(msg)
  File "/opt/homebrew/Cellar/python@3.11/3.11.7/Frameworks/Python.framework/Versions/3.11/lib/python3.11/http/client.py", line 986, in send
    self.connect()
  File "/opt/homebrew/lib/python3.11/site-packages/urllib3/connection.py", line 243, in connect
    self.sock = self._new_conn()
                ^^^^^^^^^^^^^^^^
  File "/opt/homebrew/lib/python3.11/site-packages/urllib3/connection.py", line 218, in _new_conn
    raise NewConnectionError(
urllib3.exceptions.NewConnectionError: <urllib3.connection.HTTPConnection object at 0x1065e2910>: Failed to establish a new connection: [Errno 61] Connection refused

The above exception was the direct cause of the following exception:

Traceback (most recent call last):
  File "/Users/frederic/tinder-bot/navigate_bumble.py", line 38, in navigate
    match_button = WebDriverWait(driver, 5).until(
                   ^^^^^^^^^^^^^^^^^^^^^^^^^^^^^^^
  File "/opt/homebrew/lib/python3.11/site-packages/selenium/webdriver/support/wait.py", line 96, in until
    value = method(self._driver)
            ^^^^^^^^^^^^^^^^^^^^
  File "/opt/homebrew/lib/python3.11/site-packages/selenium/webdriver/support/expected_conditions.py", line 84, in _predicate
    return driver.find_element(*locator)
           ^^^^^^^^^^^^^^^^^^^^^^^^^^^^^
  File "/opt/homebrew/lib/python3.11/site-packages/selenium/webdriver/remote/webdriver.py", line 741, in find_element
    return self.execute(Command.FIND_ELEMENT, {"using": by, "value": value})["value"]
           ^^^^^^^^^^^^^^^^^^^^^^^^^^^^^^^^^^^^^^^^^^^^^^^^^^^^^^^^^^^^^^^^^
  File "/opt/homebrew/lib/python3.11/site-packages/selenium/webdriver/remote/webdriver.py", line 345, in execute
    response = self.command_executor.execute(driver_command, params)
               ^^^^^^^^^^^^^^^^^^^^^^^^^^^^^^^^^^^^^^^^^^^^^^^^^^^^^
  File "/opt/homebrew/lib/python3.11/site-packages/selenium/webdriver/remote/remote_connection.py", line 302, in execute
    return self._request(command_info[0], url, body=data)
           ^^^^^^^^^^^^^^^^^^^^^^^^^^^^^^^^^^^^^^^^^^^^^^
  File "/opt/homebrew/lib/python3.11/site-packages/selenium/webdriver/remote/remote_connection.py", line 322, in _request
    response = self._conn.request(method, url, body=body, headers=headers)
               ^^^^^^^^^^^^^^^^^^^^^^^^^^^^^^^^^^^^^^^^^^^^^^^^^^^^^^^^^^^
  File "/opt/homebrew/lib/python3.11/site-packages/urllib3/_request_methods.py", line 118, in request
    return self.request_encode_body(
           ^^^^^^^^^^^^^^^^^^^^^^^^^
  File "/opt/homebrew/lib/python3.11/site-packages/urllib3/_request_methods.py", line 217, in request_encode_body
    return self.urlopen(method, url, **extra_kw)
           ^^^^^^^^^^^^^^^^^^^^^^^^^^^^^^^^^^^^^
  File "/opt/homebrew/lib/python3.11/site-packages/urllib3/poolmanager.py", line 444, in urlopen
    response = conn.urlopen(method, u.request_uri, **kw)
               ^^^^^^^^^^^^^^^^^^^^^^^^^^^^^^^^^^^^^^^^^
  File "/opt/homebrew/lib/python3.11/site-packages/urllib3/connectionpool.py", line 874, in urlopen
    return self.urlopen(
           ^^^^^^^^^^^^^
  File "/opt/homebrew/lib/python3.11/site-packages/urllib3/connectionpool.py", line 874, in urlopen
    return self.urlopen(
           ^^^^^^^^^^^^^
  File "/opt/homebrew/lib/python3.11/site-packages/urllib3/connectionpool.py", line 874, in urlopen
    return self.urlopen(
           ^^^^^^^^^^^^^
  File "/opt/homebrew/lib/python3.11/site-packages/urllib3/connectionpool.py", line 844, in urlopen
    retries = retries.increment(
              ^^^^^^^^^^^^^^^^^^
  File "/opt/homebrew/lib/python3.11/site-packages/urllib3/util/retry.py", line 515, in increment
    raise MaxRetryError(_pool, url, reason) from reason  # type: ignore[arg-type]
    ^^^^^^^^^^^^^^^^^^^^^^^^^^^^^^^^^^^^^^^^^^^^^^^^^^^
urllib3.exceptions.MaxRetryError: HTTPConnectionPool(host='localhost', port=53681): Max retries exceeded with url: /session/46c62e6286c1e6d8529f6e6cea834513/element (Caused by NewConnectionError('<urllib3.connection.HTTPConnection object at 0x1065e2910>: Failed to establish a new connection: [Errno 61] Connection refused'))

During handling of the above exception, another exception occurred:

Traceback (most recent call last):
  File "/opt/homebrew/Cellar/python@3.11/3.11.7/Frameworks/Python.framework/Versions/3.11/lib/python3.11/logging/__init__.py", line 1110, in emit
    msg = self.format(record)
          ^^^^^^^^^^^^^^^^^^^
  File "/opt/homebrew/Cellar/python@3.11/3.11.7/Frameworks/Python.framework/Versions/3.11/lib/python3.11/logging/__init__.py", line 953, in format
    return fmt.format(record)
           ^^^^^^^^^^^^^^^^^^
  File "/opt/homebrew/Cellar/python@3.11/3.11.7/Frameworks/Python.framework/Versions/3.11/lib/python3.11/logging/__init__.py", line 687, in format
    record.message = record.getMessage()
                     ^^^^^^^^^^^^^^^^^^^
  File "/opt/homebrew/Cellar/python@3.11/3.11.7/Frameworks/Python.framework/Versions/3.11/lib/python3.11/logging/__init__.py", line 377, in getMessage
    msg = msg % self.args
          ~~~~^~~~~~~~~~~
TypeError: not all arguments converted during string formatting
Call stack:
  File "/Users/frederic/tinder-bot/navigate_bumble.py", line 74, in <module>
    navigate(driver, is_beautiful)
  File "/Users/frederic/tinder-bot/navigate_bumble.py", line 45, in navigate
    logger.info("No match found or error occurred: ", e)
Message: 'No match found or error occurred: '
Arguments: (MaxRetryError("HTTPConnectionPool(host='localhost', port=53681): Max retries exceeded with url: /session/46c62e6286c1e6d8529f6e6cea834513/element (Caused by NewConnectionError('<urllib3.connection.HTTPConnection object at 0x1065e2910>: Failed to establish a new connection: [Errno 61] Connection refused'))"),)
2024-05-23 11:40:43,237 - WARNING - Retrying (Retry(total=2, connect=None, read=None, redirect=None, status=None)) after connection broken by 'NewConnectionError('<urllib3.connection.HTTPConnection object at 0x1065e36d0>: Failed to establish a new connection: [Errno 61] Connection refused')': /session/46c62e6286c1e6d8529f6e6cea834513/element
2024-05-23 11:40:43,239 - WARNING - Retrying (Retry(total=1, connect=None, read=None, redirect=None, status=None)) after connection broken by 'NewConnectionError('<urllib3.connection.HTTPConnection object at 0x1066b4790>: Failed to establish a new connection: [Errno 61] Connection refused')': /session/46c62e6286c1e6d8529f6e6cea834513/element
2024-05-23 11:40:43,240 - WARNING - Retrying (Retry(total=0, connect=None, read=None, redirect=None, status=None)) after connection broken by 'NewConnectionError('<urllib3.connection.HTTPConnection object at 0x1066b5410>: Failed to establish a new connection: [Errno 61] Connection refused')': /session/46c62e6286c1e6d8529f6e6cea834513/element
2024-05-23 11:40:43,240 - ERROR - Erreur : HTTPConnectionPool(host='localhost', port=53681): Max retries exceeded with url: /session/46c62e6286c1e6d8529f6e6cea834513/element (Caused by NewConnectionError('<urllib3.connection.HTTPConnection object at 0x1066b6050>: Failed to establish a new connection: [Errno 61] Connection refused'))

2024-05-23 11:40:43,528 - INFO - Running extract_image_bumble.py...
2024-05-23 11:40:43,529 - INFO - Running script: /Users/frederic/tinder-bot/extract_image_bumble.py with args: []
2024-05-23 11:40:43,653 - INFO - Loading session...
Restoring session: 46c62e6286c1e6d8529f6e6cea834513, http://localhost:53681
Waiting for image element...
Erreur : HTTPConnectionPool(host='localhost', port=53681): Max retries exceeded with url: /session/46c62e6286c1e6d8529f6e6cea834513/element (Caused by NewConnectionError('<urllib3.connection.HTTPConnection object at 0x1029c2050>: Failed to establish a new connection: [Errno 61] Connection refused'))
Échec de l'extraction de l'image.

2024-05-23 11:40:43,653 - ERROR - 
2024-05-23 11:40:43,653 - INFO - Running evaluation_bumble.py...
2024-05-23 11:40:43,653 - INFO - Running script: /Users/frederic/tinder-bot/evaluation_bumble.py with args: []
2024-05-23 11:40:48,428 - INFO - Evaluating image at: /Users/frederic/tinder-bot/profile_image_bumble.jpg
Detection result: {'request_id': '1716475245,94d18556-bb32-41d3-8be1-bba238af712c', 'time_used': 139, 'faces': [{'face_token': 'bc4ce259886364556909f30bd6f12d09', 'face_rectangle': {'top': 407, 'left': 336, 'width': 59, 'height': 59}, 'attributes': {'facequality': {'value': 93.634, 'threshold': 70.1}}}], 'image_id': 'qIp73WbjZGoq/zV+TpAaBQ==', 'face_num': 1}
Analyze result: {'time_used': 65, 'request_id': '1716475248,618547a6-92dd-4a45-8d2a-c77b4320c98c', 'faces': [{'attributes': {'gender': {'value': 'Female'}, 'age': {'value': 35}, 'beauty': {'female_score': 37.767, 'male_score': 39.408}}, 'face_rectangle': {'width': 59, 'top': 407, 'left': 336, 'height': 59}, 'face_token': 'bc4ce259886364556909f30bd6f12d09'}]}
Image: Pas Belle (Female Score: 37.767, Male Score: 39.408)

2024-05-23 11:40:48,428 - ERROR - 
2024-05-23 11:40:48,428 - INFO - Evaluation result: is_beautiful=False
2024-05-23 11:40:48,428 - INFO - Running navigate_bumble.py with is_beautiful=False...
2024-05-23 11:40:48,428 - INFO - Running script: /Users/frederic/tinder-bot/navigate_bumble.py with args: ['false']
2024-05-23 11:40:48,928 - INFO - 
2024-05-23 11:40:48,928 - ERROR - 2024-05-23 11:40:48,510 - INFO - is_beautiful: False
2024-05-23 11:40:48,510 - INFO - Loading session...
2024-05-23 11:40:48,510 - INFO - Restoring session: 8345ebf593c38af1d820dbf8fe65b084, http://localhost:53760
--- Logging error ---
Traceback (most recent call last):
  File "/Users/frederic/tinder-bot/navigate_bumble.py", line 38, in navigate
    match_button = WebDriverWait(driver, 5).until(
                   ^^^^^^^^^^^^^^^^^^^^^^^^^^^^^^^
  File "/opt/homebrew/lib/python3.11/site-packages/selenium/webdriver/support/wait.py", line 96, in until
    value = method(self._driver)
            ^^^^^^^^^^^^^^^^^^^^
  File "/opt/homebrew/lib/python3.11/site-packages/selenium/webdriver/support/expected_conditions.py", line 84, in _predicate
    return driver.find_element(*locator)
           ^^^^^^^^^^^^^^^^^^^^^^^^^^^^^
  File "/opt/homebrew/lib/python3.11/site-packages/selenium/webdriver/remote/webdriver.py", line 741, in find_element
    return self.execute(Command.FIND_ELEMENT, {"using": by, "value": value})["value"]
           ^^^^^^^^^^^^^^^^^^^^^^^^^^^^^^^^^^^^^^^^^^^^^^^^^^^^^^^^^^^^^^^^^
  File "/opt/homebrew/lib/python3.11/site-packages/selenium/webdriver/remote/webdriver.py", line 347, in execute
    self.error_handler.check_response(response)
  File "/opt/homebrew/lib/python3.11/site-packages/selenium/webdriver/remote/errorhandler.py", line 229, in check_response
    raise exception_class(message, screen, stacktrace)
selenium.common.exceptions.JavascriptException: Message: javascript error: {"status":32,"value":"Unable to locate an element with the xpath expression //span[text()='Voir d'autres profils'] because of the following error:\nSyntaxError: Failed to execute 'evaluate' on 'Document': The string '//span[text()='Voir d'autres profils']' is not a valid XPath expression."}
  (Session info: chrome=125.0.6422.61)
Stacktrace:
0   chromedriver                        0x000000010455a4a0 chromedriver + 4301984
1   chromedriver                        0x0000000104552de8 chromedriver + 4271592
2   chromedriver                        0x000000010418419c chromedriver + 278940
3   chromedriver                        0x000000010418866c chromedriver + 296556
4   chromedriver                        0x000000010418a4e8 chromedriver + 304360
5   chromedriver                        0x000000010418a560 chromedriver + 304480
6   chromedriver                        0x00000001041c63c0 chromedriver + 549824
7   chromedriver                        0x00000001041fec5c chromedriver + 781404
8   chromedriver                        0x00000001041bb004 chromedriver + 503812
9   chromedriver                        0x00000001041bb9ec chromedriver + 506348
10  chromedriver                        0x00000001045224e8 chromedriver + 4072680
11  chromedriver                        0x0000000104526f94 chromedriver + 4091796
12  chromedriver                        0x000000010450972c chromedriver + 3970860
13  chromedriver                        0x000000010452787c chromedriver + 4094076
14  chromedriver                        0x00000001044fc6ac chromedriver + 3917484
15  chromedriver                        0x0000000104544ae0 chromedriver + 4213472
16  chromedriver                        0x0000000104544c5c chromedriver + 4213852
17  chromedriver                        0x00000001045529e0 chromedriver + 4270560
18  libsystem_pthread.dylib             0x00000001992aaf94 _pthread_start + 136
19  libsystem_pthread.dylib             0x00000001992a5d34 thread_start + 8


During handling of the above exception, another exception occurred:

Traceback (most recent call last):
  File "/opt/homebrew/Cellar/python@3.11/3.11.7/Frameworks/Python.framework/Versions/3.11/lib/python3.11/logging/__init__.py", line 1110, in emit
    msg = self.format(record)
          ^^^^^^^^^^^^^^^^^^^
  File "/opt/homebrew/Cellar/python@3.11/3.11.7/Frameworks/Python.framework/Versions/3.11/lib/python3.11/logging/__init__.py", line 953, in format
    return fmt.format(record)
           ^^^^^^^^^^^^^^^^^^
  File "/opt/homebrew/Cellar/python@3.11/3.11.7/Frameworks/Python.framework/Versions/3.11/lib/python3.11/logging/__init__.py", line 687, in format
    record.message = record.getMessage()
                     ^^^^^^^^^^^^^^^^^^^
  File "/opt/homebrew/Cellar/python@3.11/3.11.7/Frameworks/Python.framework/Versions/3.11/lib/python3.11/logging/__init__.py", line 377, in getMessage
    msg = msg % self.args
          ~~~~^~~~~~~~~~~
TypeError: not all arguments converted during string formatting
Call stack:
  File "/Users/frederic/tinder-bot/navigate_bumble.py", line 74, in <module>
    navigate(driver, is_beautiful)
  File "/Users/frederic/tinder-bot/navigate_bumble.py", line 45, in navigate
    logger.info("No match found or error occurred: ", e)
Message: 'No match found or error occurred: '
Arguments: (JavascriptException(),)
2024-05-23 11:40:48,916 - INFO - Pressed Left Arrow Key.

2024-05-23 11:40:49,133 - INFO - Running extract_image_bumble.py...
2024-05-23 11:40:49,134 - INFO - Running script: /Users/frederic/tinder-bot/extract_image_bumble.py with args: []
2024-05-23 11:40:49,798 - INFO - Loading session...
Restoring session: 8345ebf593c38af1d820dbf8fe65b084, http://localhost:53760
Waiting for image element...
Image element found.
Image URL: https://us1.ecdn2.bumbcdn.com/p572/hidden?euri=AAAAAAAAAAIQEu0JMXl.f5cmSgAQva-fDQDskZ8ZZ8G-JpG5sPzV.0h.VELgHZ2m6kF.nTWRp8.GP7CoUz8RXdUGjfdXS3MZDCRHCcO2.I3vxHCELmmySj-ymJ-G2-O2gkNY7BJeQBxlMq7jIs5EcrNl8ynJIyZHQP0Iz37Il5WIeWggLsZNhGTpJ4n6G.TCk3ext9.PA9KgCyJ.DJuYMyTAbVmvZec4&size=__size__&ck=ca973c41cd1adbe7d3b432f4644a1cb8&wm_size=72x72&wm_offs=973x1322&h=-j_&gs=j&t=42.1.0.0
Image téléchargée et convertie en JPEG : /Users/frederic/tinder-bot/profile_image_bumble.jpg
L'image est enregistrée à l'emplacement : /Users/frederic/tinder-bot/profile_image_bumble.jpg

2024-05-23 11:40:49,799 - ERROR - 
2024-05-23 11:40:49,799 - INFO - Running evaluation_bumble.py...
2024-05-23 11:40:49,799 - INFO - Running script: /Users/frederic/tinder-bot/evaluation_bumble.py with args: []
2024-05-23 11:40:54,080 - INFO - Evaluating image at: /Users/frederic/tinder-bot/profile_image_bumble.jpg
Detection result: {'request_id': '1716475251,9d036c6d-bc00-4681-8218-a1c1d8330bab', 'time_used': 124, 'faces': [{'face_token': 'ffd39147b9993cfed365fb319a10fa31', 'face_rectangle': {'top': 339, 'left': 326, 'width': 274, 'height': 274}, 'attributes': {'facequality': {'value': 49.301, 'threshold': 70.1}}}], 'image_id': 'lJT2+3DbeZ/TjqOHt5oFtg==', 'face_num': 1}
Analyze result: {'time_used': 88, 'request_id': '1716475253,3c213e52-9671-4551-ab28-76fbe339eb99', 'faces': [{'attributes': {'gender': {'value': 'Female'}, 'age': {'value': 45}, 'beauty': {'female_score': 53.488, 'male_score': 49.572}}, 'face_rectangle': {'width': 274, 'top': 339, 'left': 326, 'height': 274}, 'face_token': 'ffd39147b9993cfed365fb319a10fa31'}]}
Image: Pas Belle (Female Score: 53.488, Male Score: 49.572)

2024-05-23 11:40:54,080 - ERROR - 
2024-05-23 11:40:54,080 - INFO - Evaluation result: is_beautiful=False
2024-05-23 11:40:54,080 - INFO - Running navigate_bumble.py with is_beautiful=False...
2024-05-23 11:40:54,080 - INFO - Running script: /Users/frederic/tinder-bot/navigate_bumble.py with args: ['false']
2024-05-23 11:40:54,499 - INFO - 
2024-05-23 11:40:54,499 - ERROR - 2024-05-23 11:40:54,162 - INFO - is_beautiful: False
2024-05-23 11:40:54,162 - INFO - Loading session...
2024-05-23 11:40:54,163 - INFO - Restoring session: 8345ebf593c38af1d820dbf8fe65b084, http://localhost:53760
--- Logging error ---
Traceback (most recent call last):
  File "/Users/frederic/tinder-bot/navigate_bumble.py", line 38, in navigate
    match_button = WebDriverWait(driver, 5).until(
                   ^^^^^^^^^^^^^^^^^^^^^^^^^^^^^^^
  File "/opt/homebrew/lib/python3.11/site-packages/selenium/webdriver/support/wait.py", line 96, in until
    value = method(self._driver)
            ^^^^^^^^^^^^^^^^^^^^
  File "/opt/homebrew/lib/python3.11/site-packages/selenium/webdriver/support/expected_conditions.py", line 84, in _predicate
    return driver.find_element(*locator)
           ^^^^^^^^^^^^^^^^^^^^^^^^^^^^^
  File "/opt/homebrew/lib/python3.11/site-packages/selenium/webdriver/remote/webdriver.py", line 741, in find_element
    return self.execute(Command.FIND_ELEMENT, {"using": by, "value": value})["value"]
           ^^^^^^^^^^^^^^^^^^^^^^^^^^^^^^^^^^^^^^^^^^^^^^^^^^^^^^^^^^^^^^^^^
  File "/opt/homebrew/lib/python3.11/site-packages/selenium/webdriver/remote/webdriver.py", line 347, in execute
    self.error_handler.check_response(response)
  File "/opt/homebrew/lib/python3.11/site-packages/selenium/webdriver/remote/errorhandler.py", line 229, in check_response
    raise exception_class(message, screen, stacktrace)
selenium.common.exceptions.JavascriptException: Message: javascript error: {"status":32,"value":"Unable to locate an element with the xpath expression //span[text()='Voir d'autres profils'] because of the following error:\nSyntaxError: Failed to execute 'evaluate' on 'Document': The string '//span[text()='Voir d'autres profils']' is not a valid XPath expression."}
  (Session info: chrome=125.0.6422.61)
Stacktrace:
0   chromedriver                        0x000000010455a4a0 chromedriver + 4301984
1   chromedriver                        0x0000000104552de8 chromedriver + 4271592
2   chromedriver                        0x000000010418419c chromedriver + 278940
3   chromedriver                        0x000000010418866c chromedriver + 296556
4   chromedriver                        0x000000010418a4e8 chromedriver + 304360
5   chromedriver                        0x000000010418a560 chromedriver + 304480
6   chromedriver                        0x00000001041c63c0 chromedriver + 549824
7   chromedriver                        0x00000001041fec5c chromedriver + 781404
8   chromedriver                        0x00000001041bb004 chromedriver + 503812
9   chromedriver                        0x00000001041bb9ec chromedriver + 506348
10  chromedriver                        0x00000001045224e8 chromedriver + 4072680
11  chromedriver                        0x0000000104526f94 chromedriver + 4091796
12  chromedriver                        0x000000010450972c chromedriver + 3970860
13  chromedriver                        0x000000010452787c chromedriver + 4094076
14  chromedriver                        0x00000001044fc6ac chromedriver + 3917484
15  chromedriver                        0x0000000104544ae0 chromedriver + 4213472
16  chromedriver                        0x0000000104544c5c chromedriver + 4213852
17  chromedriver                        0x00000001045529e0 chromedriver + 4270560
18  libsystem_pthread.dylib             0x00000001992aaf94 _pthread_start + 136
19  libsystem_pthread.dylib             0x00000001992a5d34 thread_start + 8


During handling of the above exception, another exception occurred:

Traceback (most recent call last):
  File "/opt/homebrew/Cellar/python@3.11/3.11.7/Frameworks/Python.framework/Versions/3.11/lib/python3.11/logging/__init__.py", line 1110, in emit
    msg = self.format(record)
          ^^^^^^^^^^^^^^^^^^^
  File "/opt/homebrew/Cellar/python@3.11/3.11.7/Frameworks/Python.framework/Versions/3.11/lib/python3.11/logging/__init__.py", line 953, in format
    return fmt.format(record)
           ^^^^^^^^^^^^^^^^^^
  File "/opt/homebrew/Cellar/python@3.11/3.11.7/Frameworks/Python.framework/Versions/3.11/lib/python3.11/logging/__init__.py", line 687, in format
    record.message = record.getMessage()
                     ^^^^^^^^^^^^^^^^^^^
  File "/opt/homebrew/Cellar/python@3.11/3.11.7/Frameworks/Python.framework/Versions/3.11/lib/python3.11/logging/__init__.py", line 377, in getMessage
    msg = msg % self.args
          ~~~~^~~~~~~~~~~
TypeError: not all arguments converted during string formatting
Call stack:
  File "/Users/frederic/tinder-bot/navigate_bumble.py", line 74, in <module>
    navigate(driver, is_beautiful)
  File "/Users/frederic/tinder-bot/navigate_bumble.py", line 45, in navigate
    logger.info("No match found or error occurred: ", e)
Message: 'No match found or error occurred: '
Arguments: (JavascriptException(),)
2024-05-23 11:40:54,484 - INFO - Pressed Left Arrow Key.

2024-05-23 11:40:54,712 - INFO - Running extract_image_bumble.py...
2024-05-23 11:40:54,712 - INFO - Running script: /Users/frederic/tinder-bot/extract_image_bumble.py with args: []
2024-05-23 11:40:55,577 - INFO - Loading session...
Restoring session: 8345ebf593c38af1d820dbf8fe65b084, http://localhost:53760
Waiting for image element...
Image element found.
Image URL: https://us1.ecdn2.bumbcdn.com/p541/hidden?euri=AAAAAAAAAAIQFypB3zwACrhbUgWxM..eogBs8GzbfnQXLw0qYD.p5-v0zguVZCVkNaHTffkrWdK5HmE92iiNTymnJ0.fqM6saXiYuWBajxIqtH3V7YsyiT1V0mFiJdvUjvrg3EEC40BJ5xvRhgqwGngTJnsKmhdlX1JwlU-TR1KZg0lan2CeLwJ.bIbHdxFc1oBXGlmzZlt9ED7i8wULfcEOnPBvhwY.&size=__size__&ck=9a32b7a73d6bdf4c5fbc8a50b5f31abf&wm_size=72x72&wm_offs=973x1322&h=tVc&gs=j&t=42.1.0.0
Image téléchargée et convertie en JPEG : /Users/frederic/tinder-bot/profile_image_bumble.jpg
L'image est enregistrée à l'emplacement : /Users/frederic/tinder-bot/profile_image_bumble.jpg

2024-05-23 11:40:55,577 - ERROR - 
2024-05-23 11:40:55,577 - INFO - Running evaluation_bumble.py...
2024-05-23 11:40:55,577 - INFO - Running script: /Users/frederic/tinder-bot/evaluation_bumble.py with args: []
2024-05-23 11:40:59,853 - INFO - Evaluating image at: /Users/frederic/tinder-bot/profile_image_bumble.jpg
Detection result: {'request_id': '1716475256,81b156c0-033e-4e31-b5d0-ec72cf596302', 'time_used': 129, 'faces': [{'face_token': '29cab46220eff47934e90fa9e856114f', 'face_rectangle': {'top': 365, 'left': 417, 'width': 156, 'height': 156}, 'attributes': {'facequality': {'value': 75.387, 'threshold': 70.1}}}], 'image_id': 'lCsGwyOzYl+ROTlc1gDnVQ==', 'face_num': 1}
Analyze result: {'time_used': 87, 'request_id': '1716475259,f81d4b7f-b783-4fdc-be71-a2f9b969d95f', 'faces': [{'attributes': {'gender': {'value': 'Female'}, 'age': {'value': 35}, 'beauty': {'female_score': 77.865, 'male_score': 67.512}}, 'face_rectangle': {'width': 156, 'top': 365, 'left': 417, 'height': 156}, 'face_token': '29cab46220eff47934e90fa9e856114f'}]}
Image: Belle (Female Score: 77.865, Male Score: 67.512)

2024-05-23 11:40:59,854 - ERROR - 
2024-05-23 11:40:59,854 - INFO - Evaluation result: is_beautiful=True
2024-05-23 11:40:59,854 - INFO - Running navigate_bumble.py with is_beautiful=True...
2024-05-23 11:40:59,854 - INFO - Running script: /Users/frederic/tinder-bot/navigate_bumble.py with args: ['true']
2024-05-23 11:41:00,320 - INFO - 
2024-05-23 11:41:00,320 - ERROR - 2024-05-23 11:40:59,935 - INFO - is_beautiful: True
2024-05-23 11:40:59,935 - INFO - Loading session...
2024-05-23 11:40:59,935 - INFO - Restoring session: 8345ebf593c38af1d820dbf8fe65b084, http://localhost:53760
--- Logging error ---
Traceback (most recent call last):
  File "/Users/frederic/tinder-bot/navigate_bumble.py", line 38, in navigate
    match_button = WebDriverWait(driver, 5).until(
                   ^^^^^^^^^^^^^^^^^^^^^^^^^^^^^^^
  File "/opt/homebrew/lib/python3.11/site-packages/selenium/webdriver/support/wait.py", line 96, in until
    value = method(self._driver)
            ^^^^^^^^^^^^^^^^^^^^
  File "/opt/homebrew/lib/python3.11/site-packages/selenium/webdriver/support/expected_conditions.py", line 84, in _predicate
    return driver.find_element(*locator)
           ^^^^^^^^^^^^^^^^^^^^^^^^^^^^^
  File "/opt/homebrew/lib/python3.11/site-packages/selenium/webdriver/remote/webdriver.py", line 741, in find_element
    return self.execute(Command.FIND_ELEMENT, {"using": by, "value": value})["value"]
           ^^^^^^^^^^^^^^^^^^^^^^^^^^^^^^^^^^^^^^^^^^^^^^^^^^^^^^^^^^^^^^^^^
  File "/opt/homebrew/lib/python3.11/site-packages/selenium/webdriver/remote/webdriver.py", line 347, in execute
    self.error_handler.check_response(response)
  File "/opt/homebrew/lib/python3.11/site-packages/selenium/webdriver/remote/errorhandler.py", line 229, in check_response
    raise exception_class(message, screen, stacktrace)
selenium.common.exceptions.JavascriptException: Message: javascript error: {"status":32,"value":"Unable to locate an element with the xpath expression //span[text()='Voir d'autres profils'] because of the following error:\nSyntaxError: Failed to execute 'evaluate' on 'Document': The string '//span[text()='Voir d'autres profils']' is not a valid XPath expression."}
  (Session info: chrome=125.0.6422.61)
Stacktrace:
0   chromedriver                        0x000000010455a4a0 chromedriver + 4301984
1   chromedriver                        0x0000000104552de8 chromedriver + 4271592
2   chromedriver                        0x000000010418419c chromedriver + 278940
3   chromedriver                        0x000000010418866c chromedriver + 296556
4   chromedriver                        0x000000010418a4e8 chromedriver + 304360
5   chromedriver                        0x000000010418a560 chromedriver + 304480
6   chromedriver                        0x00000001041c63c0 chromedriver + 549824
7   chromedriver                        0x00000001041fec5c chromedriver + 781404
8   chromedriver                        0x00000001041bb004 chromedriver + 503812
9   chromedriver                        0x00000001041bb9ec chromedriver + 506348
10  chromedriver                        0x00000001045224e8 chromedriver + 4072680
11  chromedriver                        0x0000000104526f94 chromedriver + 4091796
12  chromedriver                        0x000000010450972c chromedriver + 3970860
13  chromedriver                        0x000000010452787c chromedriver + 4094076
14  chromedriver                        0x00000001044fc6ac chromedriver + 3917484
15  chromedriver                        0x0000000104544ae0 chromedriver + 4213472
16  chromedriver                        0x0000000104544c5c chromedriver + 4213852
17  chromedriver                        0x00000001045529e0 chromedriver + 4270560
18  libsystem_pthread.dylib             0x00000001992aaf94 _pthread_start + 136
19  libsystem_pthread.dylib             0x00000001992a5d34 thread_start + 8


During handling of the above exception, another exception occurred:

Traceback (most recent call last):
  File "/opt/homebrew/Cellar/python@3.11/3.11.7/Frameworks/Python.framework/Versions/3.11/lib/python3.11/logging/__init__.py", line 1110, in emit
    msg = self.format(record)
          ^^^^^^^^^^^^^^^^^^^
  File "/opt/homebrew/Cellar/python@3.11/3.11.7/Frameworks/Python.framework/Versions/3.11/lib/python3.11/logging/__init__.py", line 953, in format
    return fmt.format(record)
           ^^^^^^^^^^^^^^^^^^
  File "/opt/homebrew/Cellar/python@3.11/3.11.7/Frameworks/Python.framework/Versions/3.11/lib/python3.11/logging/__init__.py", line 687, in format
    record.message = record.getMessage()
                     ^^^^^^^^^^^^^^^^^^^
  File "/opt/homebrew/Cellar/python@3.11/3.11.7/Frameworks/Python.framework/Versions/3.11/lib/python3.11/logging/__init__.py", line 377, in getMessage
    msg = msg % self.args
          ~~~~^~~~~~~~~~~
TypeError: not all arguments converted during string formatting
Call stack:
  File "/Users/frederic/tinder-bot/navigate_bumble.py", line 74, in <module>
    navigate(driver, is_beautiful)
  File "/Users/frederic/tinder-bot/navigate_bumble.py", line 45, in navigate
    logger.info("No match found or error occurred: ", e)
Message: 'No match found or error occurred: '
Arguments: (JavascriptException(),)
2024-05-23 11:41:00,306 - INFO - Pressed Right Arrow Key.

2024-05-23 11:41:00,610 - INFO - Running extract_image_bumble.py...
2024-05-23 11:41:00,610 - INFO - Running script: /Users/frederic/tinder-bot/extract_image_bumble.py with args: []
2024-05-23 11:41:01,157 - INFO - Loading session...
Restoring session: 8345ebf593c38af1d820dbf8fe65b084, http://localhost:53760
Waiting for image element...
Image element found.
Image URL: https://us1.ecdn2.bumbcdn.com/p568/hidden?euri=AAAAAAAAAAIQ8StUVseYRjrD1mS8egzDIgAVEhTxEqv5NPgT5G81fUaAHrcWVAnLIyeiplKueC5U64MPGqRQr0gH7RLawJYL6HaFgm7NimK7-ve0BOifJryahBpQeMXHdM3rubSNh7fdCJsAouKVPzj27G0rg4Q3Ba9hIwHFc3sC4hV2jvOkEy8m.GKH65vxSOYWWTuOqzvMIj.gOHH55IpOge-Cau3X&size=__size__&ck=992a32f950ca2b9f98666a23b834e086&wm_size=72x72&wm_offs=1176x866&h=wiO&gs=j&t=42.1.0.0
Image téléchargée et convertie en JPEG : /Users/frederic/tinder-bot/profile_image_bumble.jpg
L'image est enregistrée à l'emplacement : /Users/frederic/tinder-bot/profile_image_bumble.jpg

2024-05-23 11:41:01,157 - ERROR - 
2024-05-23 11:41:01,157 - INFO - Running evaluation_bumble.py...
2024-05-23 11:41:01,157 - INFO - Running script: /Users/frederic/tinder-bot/evaluation_bumble.py with args: []
2024-05-23 11:41:05,411 - INFO - Evaluating image at: /Users/frederic/tinder-bot/profile_image_bumble.jpg
Detection result: {'request_id': '1716475262,30562d56-5a1d-4fdb-86ac-667c1b13863f', 'time_used': 97, 'faces': [{'face_token': '1a7fe6e81ce2c89844b2c16c229064a3', 'face_rectangle': {'top': 302, 'left': 276, 'width': 304, 'height': 304}, 'attributes': {'facequality': {'value': 89.416, 'threshold': 70.1}}}], 'image_id': 'N8z7DXDmFvTB2A2oOT3P9Q==', 'face_num': 1}
Analyze result: {'time_used': 263, 'request_id': '1716475265,8f82e534-2477-4ac7-8024-c0bc566e0e31', 'faces': [{'attributes': {'gender': {'value': 'Female'}, 'age': {'value': 50}, 'beauty': {'female_score': 57.248, 'male_score': 53.247}}, 'face_rectangle': {'width': 304, 'top': 302, 'left': 276, 'height': 304}, 'face_token': '1a7fe6e81ce2c89844b2c16c229064a3'}]}
Image: Pas Belle (Female Score: 57.248, Male Score: 53.247)

2024-05-23 11:41:05,411 - ERROR - 
2024-05-23 11:41:05,411 - INFO - Evaluation result: is_beautiful=False
2024-05-23 11:41:05,411 - INFO - Running navigate_bumble.py with is_beautiful=False...
2024-05-23 11:41:05,411 - INFO - Running script: /Users/frederic/tinder-bot/navigate_bumble.py with args: ['false']
2024-05-23 11:41:05,909 - INFO - 
2024-05-23 11:41:05,909 - ERROR - 2024-05-23 11:41:05,492 - INFO - is_beautiful: False
2024-05-23 11:41:05,492 - INFO - Loading session...
2024-05-23 11:41:05,492 - INFO - Restoring session: 8345ebf593c38af1d820dbf8fe65b084, http://localhost:53760
--- Logging error ---
Traceback (most recent call last):
  File "/Users/frederic/tinder-bot/navigate_bumble.py", line 38, in navigate
    match_button = WebDriverWait(driver, 5).until(
                   ^^^^^^^^^^^^^^^^^^^^^^^^^^^^^^^
  File "/opt/homebrew/lib/python3.11/site-packages/selenium/webdriver/support/wait.py", line 96, in until
    value = method(self._driver)
            ^^^^^^^^^^^^^^^^^^^^
  File "/opt/homebrew/lib/python3.11/site-packages/selenium/webdriver/support/expected_conditions.py", line 84, in _predicate
    return driver.find_element(*locator)
           ^^^^^^^^^^^^^^^^^^^^^^^^^^^^^
  File "/opt/homebrew/lib/python3.11/site-packages/selenium/webdriver/remote/webdriver.py", line 741, in find_element
    return self.execute(Command.FIND_ELEMENT, {"using": by, "value": value})["value"]
           ^^^^^^^^^^^^^^^^^^^^^^^^^^^^^^^^^^^^^^^^^^^^^^^^^^^^^^^^^^^^^^^^^
  File "/opt/homebrew/lib/python3.11/site-packages/selenium/webdriver/remote/webdriver.py", line 347, in execute
    self.error_handler.check_response(response)
  File "/opt/homebrew/lib/python3.11/site-packages/selenium/webdriver/remote/errorhandler.py", line 229, in check_response
    raise exception_class(message, screen, stacktrace)
selenium.common.exceptions.JavascriptException: Message: javascript error: {"status":32,"value":"Unable to locate an element with the xpath expression //span[text()='Voir d'autres profils'] because of the following error:\nSyntaxError: Failed to execute 'evaluate' on 'Document': The string '//span[text()='Voir d'autres profils']' is not a valid XPath expression."}
  (Session info: chrome=125.0.6422.61)
Stacktrace:
0   chromedriver                        0x000000010455a4a0 chromedriver + 4301984
1   chromedriver                        0x0000000104552de8 chromedriver + 4271592
2   chromedriver                        0x000000010418419c chromedriver + 278940
3   chromedriver                        0x000000010418866c chromedriver + 296556
4   chromedriver                        0x000000010418a4e8 chromedriver + 304360
5   chromedriver                        0x000000010418a560 chromedriver + 304480
6   chromedriver                        0x00000001041c63c0 chromedriver + 549824
7   chromedriver                        0x00000001041fec5c chromedriver + 781404
8   chromedriver                        0x00000001041bb004 chromedriver + 503812
9   chromedriver                        0x00000001041bb9ec chromedriver + 506348
10  chromedriver                        0x00000001045224e8 chromedriver + 4072680
11  chromedriver                        0x0000000104526f94 chromedriver + 4091796
12  chromedriver                        0x000000010450972c chromedriver + 3970860
13  chromedriver                        0x000000010452787c chromedriver + 4094076
14  chromedriver                        0x00000001044fc6ac chromedriver + 3917484
15  chromedriver                        0x0000000104544ae0 chromedriver + 4213472
16  chromedriver                        0x0000000104544c5c chromedriver + 4213852
17  chromedriver                        0x00000001045529e0 chromedriver + 4270560
18  libsystem_pthread.dylib             0x00000001992aaf94 _pthread_start + 136
19  libsystem_pthread.dylib             0x00000001992a5d34 thread_start + 8


During handling of the above exception, another exception occurred:

Traceback (most recent call last):
  File "/opt/homebrew/Cellar/python@3.11/3.11.7/Frameworks/Python.framework/Versions/3.11/lib/python3.11/logging/__init__.py", line 1110, in emit
    msg = self.format(record)
          ^^^^^^^^^^^^^^^^^^^
  File "/opt/homebrew/Cellar/python@3.11/3.11.7/Frameworks/Python.framework/Versions/3.11/lib/python3.11/logging/__init__.py", line 953, in format
    return fmt.format(record)
           ^^^^^^^^^^^^^^^^^^
  File "/opt/homebrew/Cellar/python@3.11/3.11.7/Frameworks/Python.framework/Versions/3.11/lib/python3.11/logging/__init__.py", line 687, in format
    record.message = record.getMessage()
                     ^^^^^^^^^^^^^^^^^^^
  File "/opt/homebrew/Cellar/python@3.11/3.11.7/Frameworks/Python.framework/Versions/3.11/lib/python3.11/logging/__init__.py", line 377, in getMessage
    msg = msg % self.args
          ~~~~^~~~~~~~~~~
TypeError: not all arguments converted during string formatting
Call stack:
  File "/Users/frederic/tinder-bot/navigate_bumble.py", line 74, in <module>
    navigate(driver, is_beautiful)
  File "/Users/frederic/tinder-bot/navigate_bumble.py", line 45, in navigate
    logger.info("No match found or error occurred: ", e)
Message: 'No match found or error occurred: '
Arguments: (JavascriptException(),)
2024-05-23 11:41:05,897 - INFO - Pressed Left Arrow Key.

2024-05-23 11:41:06,128 - INFO - Running extract_image_bumble.py...
2024-05-23 11:41:06,128 - INFO - Running script: /Users/frederic/tinder-bot/extract_image_bumble.py with args: []
2024-05-23 11:41:06,396 - INFO - Loading session...
Restoring session: 8345ebf593c38af1d820dbf8fe65b084, http://localhost:53760
Waiting for image element...
Image element found.
Image URL: https://us1.ecdn2.bumbcdn.com/p573/hidden?euri=AAAAAAAAAAIQBtCFVuZd1drtr6iS6UHABwA2aCz5Rq6faWZ9RxoHavbv3CbhHxE7YObdIgKrHRZ08p0ThkhJ1XtYZaFfTG5NQJPabUdXoC0m4cS6w8qLiUMsk4oYHig5XdDesaT3MYDg4o2oFDJsR0-eEY.mZwBr8N8pSRoBkwK9AuHhJRxuJ6nGwjKnWb-ejNT2lMeMG6pjLAFtJ.rDbehiJVGKZVHo&size=__size__&ck=0a2356b7f1bd71fa05782e7ba89da483&wm_size=72x72&wm_offs=851x985&h=Iec&gs=j&t=42.1.0.0
Image téléchargée et convertie en JPEG : /Users/frederic/tinder-bot/profile_image_bumble.jpg
L'image est enregistrée à l'emplacement : /Users/frederic/tinder-bot/profile_image_bumble.jpg

2024-05-23 11:41:06,397 - ERROR - 
2024-05-23 11:41:06,397 - INFO - Running evaluation_bumble.py...
2024-05-23 11:41:06,397 - INFO - Running script: /Users/frederic/tinder-bot/evaluation_bumble.py with args: []
2024-05-23 11:41:10,971 - INFO - Evaluating image at: /Users/frederic/tinder-bot/profile_image_bumble.jpg
Detection result: {'request_id': '1716475267,510cdb50-4e2b-41e9-987a-bd494d7a5bf8', 'time_used': 114, 'faces': [{'face_token': '650635f7c3ce5a52b476a98b490d4fda', 'face_rectangle': {'top': 407, 'left': 336, 'width': 59, 'height': 59}, 'attributes': {'facequality': {'value': 93.634, 'threshold': 70.1}}}], 'image_id': 'qIp73WbjZGoq/zV+TpAaBQ==', 'face_num': 1}
Analyze result: {'time_used': 101, 'request_id': '1716475270,63ee6ac9-8213-43c9-ae4f-b2a9f16c8f8a', 'faces': [{'attributes': {'gender': {'value': 'Female'}, 'age': {'value': 35}, 'beauty': {'female_score': 37.767, 'male_score': 39.408}}, 'face_rectangle': {'width': 59, 'top': 407, 'left': 336, 'height': 59}, 'face_token': '650635f7c3ce5a52b476a98b490d4fda'}]}
Image: Pas Belle (Female Score: 37.767, Male Score: 39.408)

2024-05-23 11:41:10,971 - ERROR - 
2024-05-23 11:41:10,971 - INFO - Evaluation result: is_beautiful=False
2024-05-23 11:41:10,971 - INFO - Running navigate_bumble.py with is_beautiful=False...
2024-05-23 11:41:10,971 - INFO - Running script: /Users/frederic/tinder-bot/navigate_bumble.py with args: ['false']
2024-05-23 11:41:11,492 - INFO - 
2024-05-23 11:41:11,492 - ERROR - 2024-05-23 11:41:11,053 - INFO - is_beautiful: False
2024-05-23 11:41:11,053 - INFO - Loading session...
2024-05-23 11:41:11,053 - INFO - Restoring session: 8345ebf593c38af1d820dbf8fe65b084, http://localhost:53760
--- Logging error ---
Traceback (most recent call last):
  File "/Users/frederic/tinder-bot/navigate_bumble.py", line 38, in navigate
    match_button = WebDriverWait(driver, 5).until(
                   ^^^^^^^^^^^^^^^^^^^^^^^^^^^^^^^
  File "/opt/homebrew/lib/python3.11/site-packages/selenium/webdriver/support/wait.py", line 96, in until
    value = method(self._driver)
            ^^^^^^^^^^^^^^^^^^^^
  File "/opt/homebrew/lib/python3.11/site-packages/selenium/webdriver/support/expected_conditions.py", line 84, in _predicate
    return driver.find_element(*locator)
           ^^^^^^^^^^^^^^^^^^^^^^^^^^^^^
  File "/opt/homebrew/lib/python3.11/site-packages/selenium/webdriver/remote/webdriver.py", line 741, in find_element
    return self.execute(Command.FIND_ELEMENT, {"using": by, "value": value})["value"]
           ^^^^^^^^^^^^^^^^^^^^^^^^^^^^^^^^^^^^^^^^^^^^^^^^^^^^^^^^^^^^^^^^^
  File "/opt/homebrew/lib/python3.11/site-packages/selenium/webdriver/remote/webdriver.py", line 347, in execute
    self.error_handler.check_response(response)
  File "/opt/homebrew/lib/python3.11/site-packages/selenium/webdriver/remote/errorhandler.py", line 229, in check_response
    raise exception_class(message, screen, stacktrace)
selenium.common.exceptions.JavascriptException: Message: javascript error: {"status":32,"value":"Unable to locate an element with the xpath expression //span[text()='Voir d'autres profils'] because of the following error:\nSyntaxError: Failed to execute 'evaluate' on 'Document': The string '//span[text()='Voir d'autres profils']' is not a valid XPath expression."}
  (Session info: chrome=125.0.6422.61)
Stacktrace:
0   chromedriver                        0x000000010455a4a0 chromedriver + 4301984
1   chromedriver                        0x0000000104552de8 chromedriver + 4271592
2   chromedriver                        0x000000010418419c chromedriver + 278940
3   chromedriver                        0x000000010418866c chromedriver + 296556
4   chromedriver                        0x000000010418a4e8 chromedriver + 304360
5   chromedriver                        0x000000010418a560 chromedriver + 304480
6   chromedriver                        0x00000001041c63c0 chromedriver + 549824
7   chromedriver                        0x00000001041fec5c chromedriver + 781404
8   chromedriver                        0x00000001041bb004 chromedriver + 503812
9   chromedriver                        0x00000001041bb9ec chromedriver + 506348
10  chromedriver                        0x00000001045224e8 chromedriver + 4072680
11  chromedriver                        0x0000000104526f94 chromedriver + 4091796
12  chromedriver                        0x000000010450972c chromedriver + 3970860
13  chromedriver                        0x000000010452787c chromedriver + 4094076
14  chromedriver                        0x00000001044fc6ac chromedriver + 3917484
15  chromedriver                        0x0000000104544ae0 chromedriver + 4213472
16  chromedriver                        0x0000000104544c5c chromedriver + 4213852
17  chromedriver                        0x00000001045529e0 chromedriver + 4270560
18  libsystem_pthread.dylib             0x00000001992aaf94 _pthread_start + 136
19  libsystem_pthread.dylib             0x00000001992a5d34 thread_start + 8


During handling of the above exception, another exception occurred:

Traceback (most recent call last):
  File "/opt/homebrew/Cellar/python@3.11/3.11.7/Frameworks/Python.framework/Versions/3.11/lib/python3.11/logging/__init__.py", line 1110, in emit
    msg = self.format(record)
          ^^^^^^^^^^^^^^^^^^^
  File "/opt/homebrew/Cellar/python@3.11/3.11.7/Frameworks/Python.framework/Versions/3.11/lib/python3.11/logging/__init__.py", line 953, in format
    return fmt.format(record)
           ^^^^^^^^^^^^^^^^^^
  File "/opt/homebrew/Cellar/python@3.11/3.11.7/Frameworks/Python.framework/Versions/3.11/lib/python3.11/logging/__init__.py", line 687, in format
    record.message = record.getMessage()
                     ^^^^^^^^^^^^^^^^^^^
  File "/opt/homebrew/Cellar/python@3.11/3.11.7/Frameworks/Python.framework/Versions/3.11/lib/python3.11/logging/__init__.py", line 377, in getMessage
    msg = msg % self.args
          ~~~~^~~~~~~~~~~
TypeError: not all arguments converted during string formatting
Call stack:
  File "/Users/frederic/tinder-bot/navigate_bumble.py", line 74, in <module>
    navigate(driver, is_beautiful)
  File "/Users/frederic/tinder-bot/navigate_bumble.py", line 45, in navigate
    logger.info("No match found or error occurred: ", e)
Message: 'No match found or error occurred: '
Arguments: (JavascriptException(),)
2024-05-23 11:41:11,479 - INFO - Pressed Left Arrow Key.

2024-05-23 11:41:11,744 - INFO - Running extract_image_bumble.py...
2024-05-23 11:41:11,744 - INFO - Running script: /Users/frederic/tinder-bot/extract_image_bumble.py with args: []
2024-05-23 11:41:12,432 - INFO - Loading session...
Restoring session: 8345ebf593c38af1d820dbf8fe65b084, http://localhost:53760
Waiting for image element...
Image element found.
Image URL: https://us1.ecdn2.bumbcdn.com/p573/hidden?euri=AAAAAAAAAAIQ.GNGCdGJoeSJS2f-Oc8VdgAMcY4KX1Wqgeg-egqwOhhBzdfeAMHq5het-gFwvgV.gK6Wi7eNDJhcRswZCA2DMw0gnA-jz.-tQA4rk0AB9ZjKRZlwoaUCnWJCwceP2BNEJF1X7kEcAYAZUKd79ZqDRXsgaQL6zWC8N9DgvrxahFErCIF8IJbhv4Rqs0mONwVAtjk3iAbMJpB6aKeaWV23&size=__size__&ck=853a7919fc5a5c88e486e0a4033b45f8&wm_size=72x72&wm_offs=973x1124&h=sXc&gs=j&t=42.1.0.0
Image téléchargée et convertie en JPEG : /Users/frederic/tinder-bot/profile_image_bumble.jpg
L'image est enregistrée à l'emplacement : /Users/frederic/tinder-bot/profile_image_bumble.jpg

2024-05-23 11:41:12,432 - ERROR - 
2024-05-23 11:41:12,432 - INFO - Running evaluation_bumble.py...
2024-05-23 11:41:12,432 - INFO - Running script: /Users/frederic/tinder-bot/evaluation_bumble.py with args: []
2024-05-23 11:41:16,956 - INFO - Evaluating image at: /Users/frederic/tinder-bot/profile_image_bumble.jpg
Detection result: {'request_id': '1716475273,95aad3a9-fa9d-4449-ab88-7d8b0a637b24', 'time_used': 183, 'faces': [{'face_token': '17aed68e04f0c6739d420de8bd504ded', 'face_rectangle': {'top': 728, 'left': 508, 'width': 43, 'height': 43}, 'attributes': {'facequality': {'value': 0.006, 'threshold': 70.1}}}], 'image_id': '9noJtlU/+799knV6e0NaoQ==', 'face_num': 1}
Analyze result: {'time_used': 76, 'request_id': '1716475276,abdde2d8-c355-48ce-a2f9-ca41a2403885', 'faces': [{'attributes': {'gender': {'value': 'Female'}, 'age': {'value': 43}, 'beauty': {'female_score': 42.744, 'male_score': 35.826}}, 'face_rectangle': {'width': 43, 'top': 728, 'left': 508, 'height': 43}, 'face_token': '17aed68e04f0c6739d420de8bd504ded'}]}
Image: Pas Belle (Female Score: 42.744, Male Score: 35.826)

2024-05-23 11:41:16,956 - ERROR - 
2024-05-23 11:41:16,956 - INFO - Evaluation result: is_beautiful=False
2024-05-23 11:41:16,956 - INFO - Running navigate_bumble.py with is_beautiful=False...
2024-05-23 11:41:16,956 - INFO - Running script: /Users/frederic/tinder-bot/navigate_bumble.py with args: ['false']
2024-05-23 11:41:17,284 - INFO - 
2024-05-23 11:41:17,285 - ERROR - 2024-05-23 11:41:17,038 - INFO - is_beautiful: False
2024-05-23 11:41:17,038 - INFO - Loading session...
2024-05-23 11:41:17,038 - INFO - Restoring session: 8345ebf593c38af1d820dbf8fe65b084, http://localhost:53760
--- Logging error ---
Traceback (most recent call last):
  File "/Users/frederic/tinder-bot/navigate_bumble.py", line 38, in navigate
    match_button = WebDriverWait(driver, 5).until(
                   ^^^^^^^^^^^^^^^^^^^^^^^^^^^^^^^
  File "/opt/homebrew/lib/python3.11/site-packages/selenium/webdriver/support/wait.py", line 96, in until
    value = method(self._driver)
            ^^^^^^^^^^^^^^^^^^^^
  File "/opt/homebrew/lib/python3.11/site-packages/selenium/webdriver/support/expected_conditions.py", line 84, in _predicate
    return driver.find_element(*locator)
           ^^^^^^^^^^^^^^^^^^^^^^^^^^^^^
  File "/opt/homebrew/lib/python3.11/site-packages/selenium/webdriver/remote/webdriver.py", line 741, in find_element
    return self.execute(Command.FIND_ELEMENT, {"using": by, "value": value})["value"]
           ^^^^^^^^^^^^^^^^^^^^^^^^^^^^^^^^^^^^^^^^^^^^^^^^^^^^^^^^^^^^^^^^^
  File "/opt/homebrew/lib/python3.11/site-packages/selenium/webdriver/remote/webdriver.py", line 347, in execute
    self.error_handler.check_response(response)
  File "/opt/homebrew/lib/python3.11/site-packages/selenium/webdriver/remote/errorhandler.py", line 229, in check_response
    raise exception_class(message, screen, stacktrace)
selenium.common.exceptions.JavascriptException: Message: javascript error: {"status":32,"value":"Unable to locate an element with the xpath expression //span[text()='Voir d'autres profils'] because of the following error:\nSyntaxError: Failed to execute 'evaluate' on 'Document': The string '//span[text()='Voir d'autres profils']' is not a valid XPath expression."}
  (Session info: chrome=125.0.6422.61)
Stacktrace:
0   chromedriver                        0x000000010455a4a0 chromedriver + 4301984
1   chromedriver                        0x0000000104552de8 chromedriver + 4271592
2   chromedriver                        0x000000010418419c chromedriver + 278940
3   chromedriver                        0x000000010418866c chromedriver + 296556
4   chromedriver                        0x000000010418a4e8 chromedriver + 304360
5   chromedriver                        0x000000010418a560 chromedriver + 304480
6   chromedriver                        0x00000001041c63c0 chromedriver + 549824
7   chromedriver                        0x00000001041fec5c chromedriver + 781404
8   chromedriver                        0x00000001041bb004 chromedriver + 503812
9   chromedriver                        0x00000001041bb9ec chromedriver + 506348
10  chromedriver                        0x00000001045224e8 chromedriver + 4072680
11  chromedriver                        0x0000000104526f94 chromedriver + 4091796
12  chromedriver                        0x000000010450972c chromedriver + 3970860
13  chromedriver                        0x000000010452787c chromedriver + 4094076
14  chromedriver                        0x00000001044fc6ac chromedriver + 3917484
15  chromedriver                        0x0000000104544ae0 chromedriver + 4213472
16  chromedriver                        0x0000000104544c5c chromedriver + 4213852
17  chromedriver                        0x00000001045529e0 chromedriver + 4270560
18  libsystem_pthread.dylib             0x00000001992aaf94 _pthread_start + 136
19  libsystem_pthread.dylib             0x00000001992a5d34 thread_start + 8


During handling of the above exception, another exception occurred:

Traceback (most recent call last):
  File "/opt/homebrew/Cellar/python@3.11/3.11.7/Frameworks/Python.framework/Versions/3.11/lib/python3.11/logging/__init__.py", line 1110, in emit
    msg = self.format(record)
          ^^^^^^^^^^^^^^^^^^^
  File "/opt/homebrew/Cellar/python@3.11/3.11.7/Frameworks/Python.framework/Versions/3.11/lib/python3.11/logging/__init__.py", line 953, in format
    return fmt.format(record)
           ^^^^^^^^^^^^^^^^^^
  File "/opt/homebrew/Cellar/python@3.11/3.11.7/Frameworks/Python.framework/Versions/3.11/lib/python3.11/logging/__init__.py", line 687, in format
    record.message = record.getMessage()
                     ^^^^^^^^^^^^^^^^^^^
  File "/opt/homebrew/Cellar/python@3.11/3.11.7/Frameworks/Python.framework/Versions/3.11/lib/python3.11/logging/__init__.py", line 377, in getMessage
    msg = msg % self.args
          ~~~~^~~~~~~~~~~
TypeError: not all arguments converted during string formatting
Call stack:
  File "/Users/frederic/tinder-bot/navigate_bumble.py", line 74, in <module>
    navigate(driver, is_beautiful)
  File "/Users/frederic/tinder-bot/navigate_bumble.py", line 45, in navigate
    logger.info("No match found or error occurred: ", e)
Message: 'No match found or error occurred: '
Arguments: (JavascriptException(),)
2024-05-23 11:41:17,272 - INFO - Pressed Left Arrow Key.

2024-05-23 11:41:17,560 - INFO - Running extract_image_bumble.py...
2024-05-23 11:41:17,560 - INFO - Running script: /Users/frederic/tinder-bot/extract_image_bumble.py with args: []
2024-05-23 11:41:18,168 - INFO - Loading session...
Restoring session: 8345ebf593c38af1d820dbf8fe65b084, http://localhost:53760
Waiting for image element...
Image element found.
Image URL: https://us1.ecdn2.bumbcdn.com/p521/hidden?euri=AAAAAAAAAAIQwBkqLUWXZxRNhDTzU9C8nQDSKEwvvC0j7.CQ-KiDJUlp-vdGNjnM7WpGoRJl7Hy35xs2PuEma4dMfNuEc358nHcOvtkRwykN3fs-Rx4vwPtYlT4v59otilvdTByH1F0q6.4emjyKCkyXeufnD.G0pVKDaTX6okjA99ckvUAE1LvvPc-4C8OyWQdI8QiaTgDhEON0jgs0MuWHyFUsnXze&size=__size__&ck=ddccef359b32ad4b01876958b07ed593&wm_size=72x72&wm_offs=659x843&h=CsL&gs=j&t=42.1.0.0
Image téléchargée et convertie en JPEG : /Users/frederic/tinder-bot/profile_image_bumble.jpg
L'image est enregistrée à l'emplacement : /Users/frederic/tinder-bot/profile_image_bumble.jpg

2024-05-23 11:41:18,168 - ERROR - 
2024-05-23 11:41:18,168 - INFO - Running evaluation_bumble.py...
2024-05-23 11:41:18,168 - INFO - Running script: /Users/frederic/tinder-bot/evaluation_bumble.py with args: []
2024-05-23 11:41:19,564 - INFO - Evaluating image at: /Users/frederic/tinder-bot/profile_image_bumble.jpg
Detection result: {'request_id': '1716475279,0d339f3c-5bf8-4a41-9f9e-d1f55b1f6eae', 'time_used': 101, 'faces': [], 'image_id': '9wA2NNLcL7VmZW6m0/D2xg==', 'face_num': 0}
Image: Pas Belle (Female Score: 0, Male Score: 0)

2024-05-23 11:41:19,565 - ERROR - 
2024-05-23 11:41:19,565 - INFO - Evaluation result: is_beautiful=False
2024-05-23 11:41:19,565 - INFO - Running navigate_bumble.py with is_beautiful=False...
2024-05-23 11:41:19,565 - INFO - Running script: /Users/frederic/tinder-bot/navigate_bumble.py with args: ['false']
2024-05-23 11:41:19,916 - INFO - 
2024-05-23 11:41:19,916 - ERROR - 2024-05-23 11:41:19,646 - INFO - is_beautiful: False
2024-05-23 11:41:19,646 - INFO - Loading session...
2024-05-23 11:41:19,646 - INFO - Restoring session: 8345ebf593c38af1d820dbf8fe65b084, http://localhost:53760
--- Logging error ---
Traceback (most recent call last):
  File "/Users/frederic/tinder-bot/navigate_bumble.py", line 38, in navigate
    match_button = WebDriverWait(driver, 5).until(
                   ^^^^^^^^^^^^^^^^^^^^^^^^^^^^^^^
  File "/opt/homebrew/lib/python3.11/site-packages/selenium/webdriver/support/wait.py", line 96, in until
    value = method(self._driver)
            ^^^^^^^^^^^^^^^^^^^^
  File "/opt/homebrew/lib/python3.11/site-packages/selenium/webdriver/support/expected_conditions.py", line 84, in _predicate
    return driver.find_element(*locator)
           ^^^^^^^^^^^^^^^^^^^^^^^^^^^^^
  File "/opt/homebrew/lib/python3.11/site-packages/selenium/webdriver/remote/webdriver.py", line 741, in find_element
    return self.execute(Command.FIND_ELEMENT, {"using": by, "value": value})["value"]
           ^^^^^^^^^^^^^^^^^^^^^^^^^^^^^^^^^^^^^^^^^^^^^^^^^^^^^^^^^^^^^^^^^
  File "/opt/homebrew/lib/python3.11/site-packages/selenium/webdriver/remote/webdriver.py", line 347, in execute
    self.error_handler.check_response(response)
  File "/opt/homebrew/lib/python3.11/site-packages/selenium/webdriver/remote/errorhandler.py", line 229, in check_response
    raise exception_class(message, screen, stacktrace)
selenium.common.exceptions.JavascriptException: Message: javascript error: {"status":32,"value":"Unable to locate an element with the xpath expression //span[text()='Voir d'autres profils'] because of the following error:\nSyntaxError: Failed to execute 'evaluate' on 'Document': The string '//span[text()='Voir d'autres profils']' is not a valid XPath expression."}
  (Session info: chrome=125.0.6422.61)
Stacktrace:
0   chromedriver                        0x000000010455a4a0 chromedriver + 4301984
1   chromedriver                        0x0000000104552de8 chromedriver + 4271592
2   chromedriver                        0x000000010418419c chromedriver + 278940
3   chromedriver                        0x000000010418866c chromedriver + 296556
4   chromedriver                        0x000000010418a4e8 chromedriver + 304360
5   chromedriver                        0x000000010418a560 chromedriver + 304480
6   chromedriver                        0x00000001041c63c0 chromedriver + 549824
7   chromedriver                        0x00000001041fec5c chromedriver + 781404
8   chromedriver                        0x00000001041bb004 chromedriver + 503812
9   chromedriver                        0x00000001041bb9ec chromedriver + 506348
10  chromedriver                        0x00000001045224e8 chromedriver + 4072680
11  chromedriver                        0x0000000104526f94 chromedriver + 4091796
12  chromedriver                        0x000000010450972c chromedriver + 3970860
13  chromedriver                        0x000000010452787c chromedriver + 4094076
14  chromedriver                        0x00000001044fc6ac chromedriver + 3917484
15  chromedriver                        0x0000000104544ae0 chromedriver + 4213472
16  chromedriver                        0x0000000104544c5c chromedriver + 4213852
17  chromedriver                        0x00000001045529e0 chromedriver + 4270560
18  libsystem_pthread.dylib             0x00000001992aaf94 _pthread_start + 136
19  libsystem_pthread.dylib             0x00000001992a5d34 thread_start + 8


During handling of the above exception, another exception occurred:

Traceback (most recent call last):
  File "/opt/homebrew/Cellar/python@3.11/3.11.7/Frameworks/Python.framework/Versions/3.11/lib/python3.11/logging/__init__.py", line 1110, in emit
    msg = self.format(record)
          ^^^^^^^^^^^^^^^^^^^
  File "/opt/homebrew/Cellar/python@3.11/3.11.7/Frameworks/Python.framework/Versions/3.11/lib/python3.11/logging/__init__.py", line 953, in format
    return fmt.format(record)
           ^^^^^^^^^^^^^^^^^^
  File "/opt/homebrew/Cellar/python@3.11/3.11.7/Frameworks/Python.framework/Versions/3.11/lib/python3.11/logging/__init__.py", line 687, in format
    record.message = record.getMessage()
                     ^^^^^^^^^^^^^^^^^^^
  File "/opt/homebrew/Cellar/python@3.11/3.11.7/Frameworks/Python.framework/Versions/3.11/lib/python3.11/logging/__init__.py", line 377, in getMessage
    msg = msg % self.args
          ~~~~^~~~~~~~~~~
TypeError: not all arguments converted during string formatting
Call stack:
  File "/Users/frederic/tinder-bot/navigate_bumble.py", line 74, in <module>
    navigate(driver, is_beautiful)
  File "/Users/frederic/tinder-bot/navigate_bumble.py", line 45, in navigate
    logger.info("No match found or error occurred: ", e)
Message: 'No match found or error occurred: '
Arguments: (JavascriptException(),)
2024-05-23 11:41:19,903 - INFO - Pressed Left Arrow Key.

2024-05-23 11:41:20,143 - INFO - Running extract_image_bumble.py...
2024-05-23 11:41:20,143 - INFO - Running script: /Users/frederic/tinder-bot/extract_image_bumble.py with args: []
2024-05-23 11:41:20,990 - INFO - Loading session...
Restoring session: 8345ebf593c38af1d820dbf8fe65b084, http://localhost:53760
Waiting for image element...
Image element found.
Image URL: https://us1.ecdn2.bumbcdn.com/p545/hidden?euri=AAAAAAAAAAIQY0vfRgc9ZFXc1oHBY5lDoABUHQ3HwgCY2TYE9FJKX7pOb4mcengBjLPNKHhEH3AqBIV6xBYu4utguvga4xLDp.2w6FvMbcrooDnd62y-Ci7h3yX5GkDEBoe0xor.yCWS8bbyVGUwShriQ9Sqf1wHIc0cZnVd9oWr6wJoiR-YfWX9.CG3kfYKxMdI-WzQfwpQPYjQBOua-ZNnjayvuBUz&size=__size__&ck=ad73bb60d7db150d6203685a3454c211&wm_size=72x72&wm_offs=973x1323&h=351&gs=j&t=42.1.0.0
Image téléchargée et convertie en JPEG : /Users/frederic/tinder-bot/profile_image_bumble.jpg
L'image est enregistrée à l'emplacement : /Users/frederic/tinder-bot/profile_image_bumble.jpg

2024-05-23 11:41:20,990 - ERROR - 
2024-05-23 11:41:20,990 - INFO - Running evaluation_bumble.py...
2024-05-23 11:41:20,990 - INFO - Running script: /Users/frederic/tinder-bot/evaluation_bumble.py with args: []
2024-05-23 11:41:25,425 - INFO - Evaluating image at: /Users/frederic/tinder-bot/profile_image_bumble.jpg
Detection result: {'request_id': '1716475282,e638a6cd-36e3-4137-857e-a1a47e6f56c4', 'time_used': 140, 'faces': [{'face_token': '4e6ad628feaa20a46a0e57a941679163', 'face_rectangle': {'top': 181, 'left': -153, 'width': 607, 'height': 607}, 'attributes': {'facequality': {'value': 92.136, 'threshold': 70.1}}}], 'image_id': 'lTx+oiGSbwyMQpN0gpgtKA==', 'face_num': 1}
Analyze result: {'time_used': 76, 'request_id': '1716475285,e6381b79-8a3f-48ce-8235-599e11d116d0', 'faces': [{'attributes': {'gender': {'value': 'Female'}, 'age': {'value': 21}, 'beauty': {'female_score': 47.446, 'male_score': 48.225}}, 'face_rectangle': {'width': 607, 'top': 181, 'left': -154, 'height': 607}, 'face_token': '4e6ad628feaa20a46a0e57a941679163'}]}
Image: Pas Belle (Female Score: 47.446, Male Score: 48.225)

2024-05-23 11:41:25,426 - ERROR - 
2024-05-23 11:41:25,426 - INFO - Evaluation result: is_beautiful=False
2024-05-23 11:41:25,426 - INFO - Running navigate_bumble.py with is_beautiful=False...
2024-05-23 11:41:25,426 - INFO - Running script: /Users/frederic/tinder-bot/navigate_bumble.py with args: ['false']
2024-05-23 11:41:25,977 - INFO - 
2024-05-23 11:41:25,977 - ERROR - 2024-05-23 11:41:25,510 - INFO - is_beautiful: False
2024-05-23 11:41:25,510 - INFO - Loading session...
2024-05-23 11:41:25,510 - INFO - Restoring session: 8345ebf593c38af1d820dbf8fe65b084, http://localhost:53760
--- Logging error ---
Traceback (most recent call last):
  File "/Users/frederic/tinder-bot/navigate_bumble.py", line 38, in navigate
    match_button = WebDriverWait(driver, 5).until(
                   ^^^^^^^^^^^^^^^^^^^^^^^^^^^^^^^
  File "/opt/homebrew/lib/python3.11/site-packages/selenium/webdriver/support/wait.py", line 96, in until
    value = method(self._driver)
            ^^^^^^^^^^^^^^^^^^^^
  File "/opt/homebrew/lib/python3.11/site-packages/selenium/webdriver/support/expected_conditions.py", line 84, in _predicate
    return driver.find_element(*locator)
           ^^^^^^^^^^^^^^^^^^^^^^^^^^^^^
  File "/opt/homebrew/lib/python3.11/site-packages/selenium/webdriver/remote/webdriver.py", line 741, in find_element
    return self.execute(Command.FIND_ELEMENT, {"using": by, "value": value})["value"]
           ^^^^^^^^^^^^^^^^^^^^^^^^^^^^^^^^^^^^^^^^^^^^^^^^^^^^^^^^^^^^^^^^^
  File "/opt/homebrew/lib/python3.11/site-packages/selenium/webdriver/remote/webdriver.py", line 347, in execute
    self.error_handler.check_response(response)
  File "/opt/homebrew/lib/python3.11/site-packages/selenium/webdriver/remote/errorhandler.py", line 229, in check_response
    raise exception_class(message, screen, stacktrace)
selenium.common.exceptions.JavascriptException: Message: javascript error: {"status":32,"value":"Unable to locate an element with the xpath expression //span[text()='Voir d'autres profils'] because of the following error:\nSyntaxError: Failed to execute 'evaluate' on 'Document': The string '//span[text()='Voir d'autres profils']' is not a valid XPath expression."}
  (Session info: chrome=125.0.6422.61)
Stacktrace:
0   chromedriver                        0x000000010455a4a0 chromedriver + 4301984
1   chromedriver                        0x0000000104552de8 chromedriver + 4271592
2   chromedriver                        0x000000010418419c chromedriver + 278940
3   chromedriver                        0x000000010418866c chromedriver + 296556
4   chromedriver                        0x000000010418a4e8 chromedriver + 304360
5   chromedriver                        0x000000010418a560 chromedriver + 304480
6   chromedriver                        0x00000001041c63c0 chromedriver + 549824
7   chromedriver                        0x00000001041fec5c chromedriver + 781404
8   chromedriver                        0x00000001041bb004 chromedriver + 503812
9   chromedriver                        0x00000001041bb9ec chromedriver + 506348
10  chromedriver                        0x00000001045224e8 chromedriver + 4072680
11  chromedriver                        0x0000000104526f94 chromedriver + 4091796
12  chromedriver                        0x000000010450972c chromedriver + 3970860
13  chromedriver                        0x000000010452787c chromedriver + 4094076
14  chromedriver                        0x00000001044fc6ac chromedriver + 3917484
15  chromedriver                        0x0000000104544ae0 chromedriver + 4213472
16  chromedriver                        0x0000000104544c5c chromedriver + 4213852
17  chromedriver                        0x00000001045529e0 chromedriver + 4270560
18  libsystem_pthread.dylib             0x00000001992aaf94 _pthread_start + 136
19  libsystem_pthread.dylib             0x00000001992a5d34 thread_start + 8


During handling of the above exception, another exception occurred:

Traceback (most recent call last):
  File "/opt/homebrew/Cellar/python@3.11/3.11.7/Frameworks/Python.framework/Versions/3.11/lib/python3.11/logging/__init__.py", line 1110, in emit
    msg = self.format(record)
          ^^^^^^^^^^^^^^^^^^^
  File "/opt/homebrew/Cellar/python@3.11/3.11.7/Frameworks/Python.framework/Versions/3.11/lib/python3.11/logging/__init__.py", line 953, in format
    return fmt.format(record)
           ^^^^^^^^^^^^^^^^^^
  File "/opt/homebrew/Cellar/python@3.11/3.11.7/Frameworks/Python.framework/Versions/3.11/lib/python3.11/logging/__init__.py", line 687, in format
    record.message = record.getMessage()
                     ^^^^^^^^^^^^^^^^^^^
  File "/opt/homebrew/Cellar/python@3.11/3.11.7/Frameworks/Python.framework/Versions/3.11/lib/python3.11/logging/__init__.py", line 377, in getMessage
    msg = msg % self.args
          ~~~~^~~~~~~~~~~
TypeError: not all arguments converted during string formatting
Call stack:
  File "/Users/frederic/tinder-bot/navigate_bumble.py", line 74, in <module>
    navigate(driver, is_beautiful)
  File "/Users/frederic/tinder-bot/navigate_bumble.py", line 45, in navigate
    logger.info("No match found or error occurred: ", e)
Message: 'No match found or error occurred: '
Arguments: (JavascriptException(),)
2024-05-23 11:41:25,963 - INFO - Pressed Left Arrow Key.

2024-05-23 11:41:26,231 - INFO - Running extract_image_bumble.py...
2024-05-23 11:41:26,231 - INFO - Running script: /Users/frederic/tinder-bot/extract_image_bumble.py with args: []
2024-05-23 11:41:26,885 - INFO - Loading session...
Restoring session: 8345ebf593c38af1d820dbf8fe65b084, http://localhost:53760
Waiting for image element...
Image element found.
Image URL: https://us1.ecdn2.bumbcdn.com/p509/hidden?euri=AAAAAAAAAAIQQKpa.hSI.8i2OYHinOmaVwA77ZDmraXnkXajOXejxqk.9Wgh-yo5XV0ui7FvHDsl8FG.jc31TV.N58UlfDjwH-Unv9qB7ePAevWJJKlLGCS7P72BJaNzavC9KBxeetoUuGKSIkf7plD9fg0SzqSdkgXmJ5cVPys9e5YuNzNckJtmImHEb9M3GELaiGuiGGOyozOchvmsreFr4xItdf3E&size=__size__&ck=c5c5daef74af1e02d9f6f8cae52fd13d&wm_size=72x72&wm_offs=973x1124&h=Ndx&gs=j&t=42.1.0.0
Image téléchargée et convertie en JPEG : /Users/frederic/tinder-bot/profile_image_bumble.jpg
L'image est enregistrée à l'emplacement : /Users/frederic/tinder-bot/profile_image_bumble.jpg

2024-05-23 11:41:26,885 - ERROR - 
2024-05-23 11:41:26,885 - INFO - Running evaluation_bumble.py...
2024-05-23 11:41:26,885 - INFO - Running script: /Users/frederic/tinder-bot/evaluation_bumble.py with args: []
2024-05-23 11:41:31,204 - INFO - Evaluating image at: /Users/frederic/tinder-bot/profile_image_bumble.jpg
Detection result: {'request_id': '1716475288,3229ff8d-f140-4d0c-9d15-f0eaecbfbe26', 'time_used': 138, 'faces': [{'face_token': 'c237ea36661f38da726f90d4af3eaf09', 'face_rectangle': {'top': 414, 'left': 353, 'width': 337, 'height': 337}, 'attributes': {'facequality': {'value': 90.69, 'threshold': 70.1}}}], 'image_id': '2HpdzpVWv7zQo5/dp/Qekw==', 'face_num': 1}
Analyze result: {'time_used': 110, 'request_id': '1716475291,aa2463d9-6799-4a49-a78c-cf24987e61fb', 'faces': [{'attributes': {'gender': {'value': 'Female'}, 'age': {'value': 48}, 'beauty': {'female_score': 52.821, 'male_score': 52.513}}, 'face_rectangle': {'width': 337, 'top': 414, 'left': 353, 'height': 337}, 'face_token': 'c237ea36661f38da726f90d4af3eaf09'}]}
Image: Pas Belle (Female Score: 52.821, Male Score: 52.513)

2024-05-23 11:41:31,204 - ERROR - 
2024-05-23 11:41:31,204 - INFO - Evaluation result: is_beautiful=False
2024-05-23 11:41:31,204 - INFO - Running navigate_bumble.py with is_beautiful=False...
2024-05-23 11:41:31,204 - INFO - Running script: /Users/frederic/tinder-bot/navigate_bumble.py with args: ['false']
2024-05-23 11:41:31,594 - INFO - 
2024-05-23 11:41:31,594 - ERROR - 2024-05-23 11:41:31,288 - INFO - is_beautiful: False
2024-05-23 11:41:31,288 - INFO - Loading session...
2024-05-23 11:41:31,288 - INFO - Restoring session: 8345ebf593c38af1d820dbf8fe65b084, http://localhost:53760
--- Logging error ---
Traceback (most recent call last):
  File "/Users/frederic/tinder-bot/navigate_bumble.py", line 38, in navigate
    match_button = WebDriverWait(driver, 5).until(
                   ^^^^^^^^^^^^^^^^^^^^^^^^^^^^^^^
  File "/opt/homebrew/lib/python3.11/site-packages/selenium/webdriver/support/wait.py", line 96, in until
    value = method(self._driver)
            ^^^^^^^^^^^^^^^^^^^^
  File "/opt/homebrew/lib/python3.11/site-packages/selenium/webdriver/support/expected_conditions.py", line 84, in _predicate
    return driver.find_element(*locator)
           ^^^^^^^^^^^^^^^^^^^^^^^^^^^^^
  File "/opt/homebrew/lib/python3.11/site-packages/selenium/webdriver/remote/webdriver.py", line 741, in find_element
    return self.execute(Command.FIND_ELEMENT, {"using": by, "value": value})["value"]
           ^^^^^^^^^^^^^^^^^^^^^^^^^^^^^^^^^^^^^^^^^^^^^^^^^^^^^^^^^^^^^^^^^
  File "/opt/homebrew/lib/python3.11/site-packages/selenium/webdriver/remote/webdriver.py", line 347, in execute
    self.error_handler.check_response(response)
  File "/opt/homebrew/lib/python3.11/site-packages/selenium/webdriver/remote/errorhandler.py", line 229, in check_response
    raise exception_class(message, screen, stacktrace)
selenium.common.exceptions.JavascriptException: Message: javascript error: {"status":32,"value":"Unable to locate an element with the xpath expression //span[text()='Voir d'autres profils'] because of the following error:\nSyntaxError: Failed to execute 'evaluate' on 'Document': The string '//span[text()='Voir d'autres profils']' is not a valid XPath expression."}
  (Session info: chrome=125.0.6422.61)
Stacktrace:
0   chromedriver                        0x000000010455a4a0 chromedriver + 4301984
1   chromedriver                        0x0000000104552de8 chromedriver + 4271592
2   chromedriver                        0x000000010418419c chromedriver + 278940
3   chromedriver                        0x000000010418866c chromedriver + 296556
4   chromedriver                        0x000000010418a4e8 chromedriver + 304360
5   chromedriver                        0x000000010418a560 chromedriver + 304480
6   chromedriver                        0x00000001041c63c0 chromedriver + 549824
7   chromedriver                        0x00000001041fec5c chromedriver + 781404
8   chromedriver                        0x00000001041bb004 chromedriver + 503812
9   chromedriver                        0x00000001041bb9ec chromedriver + 506348
10  chromedriver                        0x00000001045224e8 chromedriver + 4072680
11  chromedriver                        0x0000000104526f94 chromedriver + 4091796
12  chromedriver                        0x000000010450972c chromedriver + 3970860
13  chromedriver                        0x000000010452787c chromedriver + 4094076
14  chromedriver                        0x00000001044fc6ac chromedriver + 3917484
15  chromedriver                        0x0000000104544ae0 chromedriver + 4213472
16  chromedriver                        0x0000000104544c5c chromedriver + 4213852
17  chromedriver                        0x00000001045529e0 chromedriver + 4270560
18  libsystem_pthread.dylib             0x00000001992aaf94 _pthread_start + 136
19  libsystem_pthread.dylib             0x00000001992a5d34 thread_start + 8


During handling of the above exception, another exception occurred:

Traceback (most recent call last):
  File "/opt/homebrew/Cellar/python@3.11/3.11.7/Frameworks/Python.framework/Versions/3.11/lib/python3.11/logging/__init__.py", line 1110, in emit
    msg = self.format(record)
          ^^^^^^^^^^^^^^^^^^^
  File "/opt/homebrew/Cellar/python@3.11/3.11.7/Frameworks/Python.framework/Versions/3.11/lib/python3.11/logging/__init__.py", line 953, in format
    return fmt.format(record)
           ^^^^^^^^^^^^^^^^^^
  File "/opt/homebrew/Cellar/python@3.11/3.11.7/Frameworks/Python.framework/Versions/3.11/lib/python3.11/logging/__init__.py", line 687, in format
    record.message = record.getMessage()
                     ^^^^^^^^^^^^^^^^^^^
  File "/opt/homebrew/Cellar/python@3.11/3.11.7/Frameworks/Python.framework/Versions/3.11/lib/python3.11/logging/__init__.py", line 377, in getMessage
    msg = msg % self.args
          ~~~~^~~~~~~~~~~
TypeError: not all arguments converted during string formatting
Call stack:
  File "/Users/frederic/tinder-bot/navigate_bumble.py", line 74, in <module>
    navigate(driver, is_beautiful)
  File "/Users/frederic/tinder-bot/navigate_bumble.py", line 45, in navigate
    logger.info("No match found or error occurred: ", e)
Message: 'No match found or error occurred: '
Arguments: (JavascriptException(),)
2024-05-23 11:41:31,582 - INFO - Pressed Left Arrow Key.

2024-05-23 11:41:31,805 - INFO - Running extract_image_bumble.py...
2024-05-23 11:41:31,805 - INFO - Running script: /Users/frederic/tinder-bot/extract_image_bumble.py with args: []
2024-05-23 11:41:32,624 - INFO - Loading session...
Restoring session: 8345ebf593c38af1d820dbf8fe65b084, http://localhost:53760
Waiting for image element...
Image element found.
Image URL: https://us1.ecdn2.bumbcdn.com/p576/hidden?euri=AAAAAAAAAAIQ1SsiKxluPTA6o0oaHffrfQCFdA1CiaurVbfH9JXkVdwZ19kJa3wCtUthO7Vch0qv7RJ38O68clS8bDtEH9.MeHaRH-YiA9DMagCvDg27twovC2jeL8Yyd92hU-4nHV9bbvYd67SS.tLnxju8guI5rKD-i4SuQduv17OkXqHKHaK7IItHK0SQnKk47yQYM-bJQ2I.dbMKLGKx8sE4Ul6v&size=__size__&ck=a5a80dae161bac8b9d4222956ca97a62&wm_size=72x72&wm_offs=973x1321&h=hbv&gs=j&t=42.1.0.0
Image téléchargée et convertie en JPEG : /Users/frederic/tinder-bot/profile_image_bumble.jpg
L'image est enregistrée à l'emplacement : /Users/frederic/tinder-bot/profile_image_bumble.jpg

2024-05-23 11:41:32,624 - ERROR - 
2024-05-23 11:41:32,624 - INFO - Running evaluation_bumble.py...
2024-05-23 11:41:32,624 - INFO - Running script: /Users/frederic/tinder-bot/evaluation_bumble.py with args: []
2024-05-23 11:41:37,184 - INFO - Evaluating image at: /Users/frederic/tinder-bot/profile_image_bumble.jpg
Detection result: {'request_id': '1716475293,18c37b41-a465-47d4-af72-46e2c8e9b30d', 'time_used': 150, 'faces': [{'face_token': '0df340f6b4236280449a3b8be584c9de', 'face_rectangle': {'top': 383, 'left': 311, 'width': 500, 'height': 500}, 'attributes': {'facequality': {'value': 19.6, 'threshold': 70.1}}}], 'image_id': 'W0MTWy2Y1z0K26FPeRXvuw==', 'face_num': 1}
Analyze result: {'time_used': 106, 'request_id': '1716475296,f078f1e7-1f43-44e4-99f3-f012ea30cc2f', 'faces': [{'attributes': {'gender': {'value': 'Female'}, 'age': {'value': 25}, 'beauty': {'female_score': 37.86, 'male_score': 40.338}}, 'face_rectangle': {'width': 500, 'top': 383, 'left': 311, 'height': 500}, 'face_token': '0df340f6b4236280449a3b8be584c9de'}]}
Image: Pas Belle (Female Score: 37.86, Male Score: 40.338)

2024-05-23 11:41:37,185 - ERROR - 
2024-05-23 11:41:37,185 - INFO - Evaluation result: is_beautiful=False
2024-05-23 11:41:37,185 - INFO - Running navigate_bumble.py with is_beautiful=False...
2024-05-23 11:41:37,185 - INFO - Running script: /Users/frederic/tinder-bot/navigate_bumble.py with args: ['false']
2024-05-23 11:41:37,461 - INFO - 
2024-05-23 11:41:37,461 - ERROR - 2024-05-23 11:41:37,265 - INFO - is_beautiful: False
2024-05-23 11:41:37,265 - INFO - Loading session...
2024-05-23 11:41:37,265 - INFO - Restoring session: 8345ebf593c38af1d820dbf8fe65b084, http://localhost:53760
--- Logging error ---
Traceback (most recent call last):
  File "/Users/frederic/tinder-bot/navigate_bumble.py", line 38, in navigate
    match_button = WebDriverWait(driver, 5).until(
                   ^^^^^^^^^^^^^^^^^^^^^^^^^^^^^^^
  File "/opt/homebrew/lib/python3.11/site-packages/selenium/webdriver/support/wait.py", line 96, in until
    value = method(self._driver)
            ^^^^^^^^^^^^^^^^^^^^
  File "/opt/homebrew/lib/python3.11/site-packages/selenium/webdriver/support/expected_conditions.py", line 84, in _predicate
    return driver.find_element(*locator)
           ^^^^^^^^^^^^^^^^^^^^^^^^^^^^^
  File "/opt/homebrew/lib/python3.11/site-packages/selenium/webdriver/remote/webdriver.py", line 741, in find_element
    return self.execute(Command.FIND_ELEMENT, {"using": by, "value": value})["value"]
           ^^^^^^^^^^^^^^^^^^^^^^^^^^^^^^^^^^^^^^^^^^^^^^^^^^^^^^^^^^^^^^^^^
  File "/opt/homebrew/lib/python3.11/site-packages/selenium/webdriver/remote/webdriver.py", line 347, in execute
    self.error_handler.check_response(response)
  File "/opt/homebrew/lib/python3.11/site-packages/selenium/webdriver/remote/errorhandler.py", line 229, in check_response
    raise exception_class(message, screen, stacktrace)
selenium.common.exceptions.JavascriptException: Message: javascript error: {"status":32,"value":"Unable to locate an element with the xpath expression //span[text()='Voir d'autres profils'] because of the following error:\nSyntaxError: Failed to execute 'evaluate' on 'Document': The string '//span[text()='Voir d'autres profils']' is not a valid XPath expression."}
  (Session info: chrome=125.0.6422.61)
Stacktrace:
0   chromedriver                        0x000000010455a4a0 chromedriver + 4301984
1   chromedriver                        0x0000000104552de8 chromedriver + 4271592
2   chromedriver                        0x000000010418419c chromedriver + 278940
3   chromedriver                        0x000000010418866c chromedriver + 296556
4   chromedriver                        0x000000010418a4e8 chromedriver + 304360
5   chromedriver                        0x000000010418a560 chromedriver + 304480
6   chromedriver                        0x00000001041c63c0 chromedriver + 549824
7   chromedriver                        0x00000001041fec5c chromedriver + 781404
8   chromedriver                        0x00000001041bb004 chromedriver + 503812
9   chromedriver                        0x00000001041bb9ec chromedriver + 506348
10  chromedriver                        0x00000001045224e8 chromedriver + 4072680
11  chromedriver                        0x0000000104526f94 chromedriver + 4091796
12  chromedriver                        0x000000010450972c chromedriver + 3970860
13  chromedriver                        0x000000010452787c chromedriver + 4094076
14  chromedriver                        0x00000001044fc6ac chromedriver + 3917484
15  chromedriver                        0x0000000104544ae0 chromedriver + 4213472
16  chromedriver                        0x0000000104544c5c chromedriver + 4213852
17  chromedriver                        0x00000001045529e0 chromedriver + 4270560
18  libsystem_pthread.dylib             0x00000001992aaf94 _pthread_start + 136
19  libsystem_pthread.dylib             0x00000001992a5d34 thread_start + 8


During handling of the above exception, another exception occurred:

Traceback (most recent call last):
  File "/opt/homebrew/Cellar/python@3.11/3.11.7/Frameworks/Python.framework/Versions/3.11/lib/python3.11/logging/__init__.py", line 1110, in emit
    msg = self.format(record)
          ^^^^^^^^^^^^^^^^^^^
  File "/opt/homebrew/Cellar/python@3.11/3.11.7/Frameworks/Python.framework/Versions/3.11/lib/python3.11/logging/__init__.py", line 953, in format
    return fmt.format(record)
           ^^^^^^^^^^^^^^^^^^
  File "/opt/homebrew/Cellar/python@3.11/3.11.7/Frameworks/Python.framework/Versions/3.11/lib/python3.11/logging/__init__.py", line 687, in format
    record.message = record.getMessage()
                     ^^^^^^^^^^^^^^^^^^^
  File "/opt/homebrew/Cellar/python@3.11/3.11.7/Frameworks/Python.framework/Versions/3.11/lib/python3.11/logging/__init__.py", line 377, in getMessage
    msg = msg % self.args
          ~~~~^~~~~~~~~~~
TypeError: not all arguments converted during string formatting
Call stack:
  File "/Users/frederic/tinder-bot/navigate_bumble.py", line 74, in <module>
    navigate(driver, is_beautiful)
  File "/Users/frederic/tinder-bot/navigate_bumble.py", line 45, in navigate
    logger.info("No match found or error occurred: ", e)
Message: 'No match found or error occurred: '
Arguments: (JavascriptException(),)
2024-05-23 11:41:37,447 - INFO - Pressed Left Arrow Key.

2024-05-23 11:41:37,756 - INFO - Running extract_image_bumble.py...
2024-05-23 11:41:37,756 - INFO - Running script: /Users/frederic/tinder-bot/extract_image_bumble.py with args: []
2024-05-23 11:41:38,468 - INFO - Loading session...
Restoring session: 8345ebf593c38af1d820dbf8fe65b084, http://localhost:53760
Waiting for image element...
Image element found.
Image URL: https://us1.ecdn2.bumbcdn.com/p545/hidden?euri=AAAAAAAAAAIQyROemQTnK3XI2w3WqZQMDgCYFvWvDeUV3.FgferiBmODkZ-sJ0ng4LQt-e3hhLoTKsXWqp2D3L.e1vAEInwrf6MmHjsnlaLC8yg60InZrR3WNQ-UC14aZLsME7aW-4AYUwIRI1NwUTFE-Vl0afeIXiotvqdmpyzNjUMQ9bg4JcBErpZtUXxGqNKSf1zJsz9DXkeaXqDLiw0-a5ceLPkC&size=__size__&ck=c7d579aaf174cbfe26a09de5d9b09e8d&wm_size=72x72&wm_offs=973x1323&h=pho&gs=j&t=42.1.0.0
Image téléchargée et convertie en JPEG : /Users/frederic/tinder-bot/profile_image_bumble.jpg
L'image est enregistrée à l'emplacement : /Users/frederic/tinder-bot/profile_image_bumble.jpg

2024-05-23 11:41:38,468 - ERROR - 
2024-05-23 11:41:38,468 - INFO - Running evaluation_bumble.py...
2024-05-23 11:41:38,468 - INFO - Running script: /Users/frederic/tinder-bot/evaluation_bumble.py with args: []
2024-05-23 11:41:39,886 - INFO - Evaluating image at: /Users/frederic/tinder-bot/profile_image_bumble.jpg
Detection result: {'request_id': '1716475299,90172cfd-704b-4a20-9969-661bc59a33c8', 'time_used': 98, 'faces': [], 'image_id': 'YI8YijAJqg9+Ayds+DbNsA==', 'face_num': 0}
Image: Pas Belle (Female Score: 0, Male Score: 0)

2024-05-23 11:41:39,887 - ERROR - 
2024-05-23 11:41:39,887 - INFO - Evaluation result: is_beautiful=False
2024-05-23 11:41:39,887 - INFO - Running navigate_bumble.py with is_beautiful=False...
2024-05-23 11:41:39,887 - INFO - Running script: /Users/frederic/tinder-bot/navigate_bumble.py with args: ['false']
2024-05-23 11:41:40,297 - INFO - 
2024-05-23 11:41:40,297 - ERROR - 2024-05-23 11:41:39,968 - INFO - is_beautiful: False
2024-05-23 11:41:39,968 - INFO - Loading session...
2024-05-23 11:41:39,968 - INFO - Restoring session: 8345ebf593c38af1d820dbf8fe65b084, http://localhost:53760
--- Logging error ---
Traceback (most recent call last):
  File "/Users/frederic/tinder-bot/navigate_bumble.py", line 38, in navigate
    match_button = WebDriverWait(driver, 5).until(
                   ^^^^^^^^^^^^^^^^^^^^^^^^^^^^^^^
  File "/opt/homebrew/lib/python3.11/site-packages/selenium/webdriver/support/wait.py", line 96, in until
    value = method(self._driver)
            ^^^^^^^^^^^^^^^^^^^^
  File "/opt/homebrew/lib/python3.11/site-packages/selenium/webdriver/support/expected_conditions.py", line 84, in _predicate
    return driver.find_element(*locator)
           ^^^^^^^^^^^^^^^^^^^^^^^^^^^^^
  File "/opt/homebrew/lib/python3.11/site-packages/selenium/webdriver/remote/webdriver.py", line 741, in find_element
    return self.execute(Command.FIND_ELEMENT, {"using": by, "value": value})["value"]
           ^^^^^^^^^^^^^^^^^^^^^^^^^^^^^^^^^^^^^^^^^^^^^^^^^^^^^^^^^^^^^^^^^
  File "/opt/homebrew/lib/python3.11/site-packages/selenium/webdriver/remote/webdriver.py", line 347, in execute
    self.error_handler.check_response(response)
  File "/opt/homebrew/lib/python3.11/site-packages/selenium/webdriver/remote/errorhandler.py", line 229, in check_response
    raise exception_class(message, screen, stacktrace)
selenium.common.exceptions.JavascriptException: Message: javascript error: {"status":32,"value":"Unable to locate an element with the xpath expression //span[text()='Voir d'autres profils'] because of the following error:\nSyntaxError: Failed to execute 'evaluate' on 'Document': The string '//span[text()='Voir d'autres profils']' is not a valid XPath expression."}
  (Session info: chrome=125.0.6422.61)
Stacktrace:
0   chromedriver                        0x000000010455a4a0 chromedriver + 4301984
1   chromedriver                        0x0000000104552de8 chromedriver + 4271592
2   chromedriver                        0x000000010418419c chromedriver + 278940
3   chromedriver                        0x000000010418866c chromedriver + 296556
4   chromedriver                        0x000000010418a4e8 chromedriver + 304360
5   chromedriver                        0x000000010418a560 chromedriver + 304480
6   chromedriver                        0x00000001041c63c0 chromedriver + 549824
7   chromedriver                        0x00000001041fec5c chromedriver + 781404
8   chromedriver                        0x00000001041bb004 chromedriver + 503812
9   chromedriver                        0x00000001041bb9ec chromedriver + 506348
10  chromedriver                        0x00000001045224e8 chromedriver + 4072680
11  chromedriver                        0x0000000104526f94 chromedriver + 4091796
12  chromedriver                        0x000000010450972c chromedriver + 3970860
13  chromedriver                        0x000000010452787c chromedriver + 4094076
14  chromedriver                        0x00000001044fc6ac chromedriver + 3917484
15  chromedriver                        0x0000000104544ae0 chromedriver + 4213472
16  chromedriver                        0x0000000104544c5c chromedriver + 4213852
17  chromedriver                        0x00000001045529e0 chromedriver + 4270560
18  libsystem_pthread.dylib             0x00000001992aaf94 _pthread_start + 136
19  libsystem_pthread.dylib             0x00000001992a5d34 thread_start + 8


During handling of the above exception, another exception occurred:

Traceback (most recent call last):
  File "/opt/homebrew/Cellar/python@3.11/3.11.7/Frameworks/Python.framework/Versions/3.11/lib/python3.11/logging/__init__.py", line 1110, in emit
    msg = self.format(record)
          ^^^^^^^^^^^^^^^^^^^
  File "/opt/homebrew/Cellar/python@3.11/3.11.7/Frameworks/Python.framework/Versions/3.11/lib/python3.11/logging/__init__.py", line 953, in format
    return fmt.format(record)
           ^^^^^^^^^^^^^^^^^^
  File "/opt/homebrew/Cellar/python@3.11/3.11.7/Frameworks/Python.framework/Versions/3.11/lib/python3.11/logging/__init__.py", line 687, in format
    record.message = record.getMessage()
                     ^^^^^^^^^^^^^^^^^^^
  File "/opt/homebrew/Cellar/python@3.11/3.11.7/Frameworks/Python.framework/Versions/3.11/lib/python3.11/logging/__init__.py", line 377, in getMessage
    msg = msg % self.args
          ~~~~^~~~~~~~~~~
TypeError: not all arguments converted during string formatting
Call stack:
  File "/Users/frederic/tinder-bot/navigate_bumble.py", line 74, in <module>
    navigate(driver, is_beautiful)
  File "/Users/frederic/tinder-bot/navigate_bumble.py", line 45, in navigate
    logger.info("No match found or error occurred: ", e)
Message: 'No match found or error occurred: '
Arguments: (JavascriptException(),)
2024-05-23 11:41:40,284 - INFO - Pressed Left Arrow Key.

2024-05-23 11:41:40,586 - INFO - Running extract_image_bumble.py...
2024-05-23 11:41:40,586 - INFO - Running script: /Users/frederic/tinder-bot/extract_image_bumble.py with args: []
2024-05-23 11:41:41,213 - INFO - Loading session...
Restoring session: 8345ebf593c38af1d820dbf8fe65b084, http://localhost:53760
Waiting for image element...
Image element found.
Image URL: https://us1.ecdn2.bumbcdn.com/p527/hidden?euri=AAAAAAAAAAIQOFQuZyv502MJdoIZ325qOwCR0jHHX77tYmMAeLEZ08IEbychI2COpF14OfnIp7WclbZtCcEkxcdrYhRbf.M.E3F0wT4CVFL-NiwlZ223zhfCUtmPkiGybRKRWR378AKM6gOTRZasXF996.7.Pd9N7jHIKiRg2ChDuFH2068isEq3lJotHAd0pis8yl7vPJM-mVG8XsQY1Tl2N1BtPStg&size=__size__&ck=9a0c5db4f34f70131202de5cf6523c1e&wm_size=72x72&wm_offs=973x1323&h=3eB&gs=j&t=42.1.0.0
Image téléchargée et convertie en JPEG : /Users/frederic/tinder-bot/profile_image_bumble.jpg
L'image est enregistrée à l'emplacement : /Users/frederic/tinder-bot/profile_image_bumble.jpg

2024-05-23 11:41:41,213 - ERROR - 
2024-05-23 11:41:41,213 - INFO - Running evaluation_bumble.py...
2024-05-23 11:41:41,213 - INFO - Running script: /Users/frederic/tinder-bot/evaluation_bumble.py with args: []
2024-05-23 11:41:45,514 - INFO - Evaluating image at: /Users/frederic/tinder-bot/profile_image_bumble.jpg
Detection result: {'request_id': '1716475302,78dd6d9c-d7b2-4571-87f7-4313abf3153b', 'time_used': 134, 'faces': [{'face_token': '01caab8a5ec9f882dbdb1bb8fe93f6e7', 'face_rectangle': {'top': 535, 'left': 195, 'width': 141, 'height': 141}, 'attributes': {'facequality': {'value': 0.006, 'threshold': 70.1}}}], 'image_id': '46xMwKIfA8NypFQ+xSapmA==', 'face_num': 1}
Analyze result: {'time_used': 107, 'request_id': '1716475305,94ca4581-09a1-4799-a438-ef41fe869979', 'faces': [{'attributes': {'gender': {'value': 'Male'}, 'age': {'value': 26}, 'beauty': {'female_score': 64.735, 'male_score': 62.183}}, 'face_rectangle': {'width': 141, 'top': 535, 'left': 195, 'height': 141}, 'face_token': '01caab8a5ec9f882dbdb1bb8fe93f6e7'}]}
Image: Belle (Female Score: 64.735, Male Score: 62.183)

2024-05-23 11:41:45,515 - ERROR - 
2024-05-23 11:41:45,515 - INFO - Evaluation result: is_beautiful=True
2024-05-23 11:41:45,515 - INFO - Running navigate_bumble.py with is_beautiful=True...
2024-05-23 11:41:45,515 - INFO - Running script: /Users/frederic/tinder-bot/navigate_bumble.py with args: ['true']
2024-05-23 11:41:45,848 - INFO - 
2024-05-23 11:41:45,848 - ERROR - 2024-05-23 11:41:45,594 - INFO - is_beautiful: True
2024-05-23 11:41:45,594 - INFO - Loading session...
2024-05-23 11:41:45,594 - INFO - Restoring session: 8345ebf593c38af1d820dbf8fe65b084, http://localhost:53760
--- Logging error ---
Traceback (most recent call last):
  File "/Users/frederic/tinder-bot/navigate_bumble.py", line 38, in navigate
    match_button = WebDriverWait(driver, 5).until(
                   ^^^^^^^^^^^^^^^^^^^^^^^^^^^^^^^
  File "/opt/homebrew/lib/python3.11/site-packages/selenium/webdriver/support/wait.py", line 96, in until
    value = method(self._driver)
            ^^^^^^^^^^^^^^^^^^^^
  File "/opt/homebrew/lib/python3.11/site-packages/selenium/webdriver/support/expected_conditions.py", line 84, in _predicate
    return driver.find_element(*locator)
           ^^^^^^^^^^^^^^^^^^^^^^^^^^^^^
  File "/opt/homebrew/lib/python3.11/site-packages/selenium/webdriver/remote/webdriver.py", line 741, in find_element
    return self.execute(Command.FIND_ELEMENT, {"using": by, "value": value})["value"]
           ^^^^^^^^^^^^^^^^^^^^^^^^^^^^^^^^^^^^^^^^^^^^^^^^^^^^^^^^^^^^^^^^^
  File "/opt/homebrew/lib/python3.11/site-packages/selenium/webdriver/remote/webdriver.py", line 347, in execute
    self.error_handler.check_response(response)
  File "/opt/homebrew/lib/python3.11/site-packages/selenium/webdriver/remote/errorhandler.py", line 229, in check_response
    raise exception_class(message, screen, stacktrace)
selenium.common.exceptions.JavascriptException: Message: javascript error: {"status":32,"value":"Unable to locate an element with the xpath expression //span[text()='Voir d'autres profils'] because of the following error:\nSyntaxError: Failed to execute 'evaluate' on 'Document': The string '//span[text()='Voir d'autres profils']' is not a valid XPath expression."}
  (Session info: chrome=125.0.6422.61)
Stacktrace:
0   chromedriver                        0x000000010455a4a0 chromedriver + 4301984
1   chromedriver                        0x0000000104552de8 chromedriver + 4271592
2   chromedriver                        0x000000010418419c chromedriver + 278940
3   chromedriver                        0x000000010418866c chromedriver + 296556
4   chromedriver                        0x000000010418a4e8 chromedriver + 304360
5   chromedriver                        0x000000010418a560 chromedriver + 304480
6   chromedriver                        0x00000001041c63c0 chromedriver + 549824
7   chromedriver                        0x00000001041fec5c chromedriver + 781404
8   chromedriver                        0x00000001041bb004 chromedriver + 503812
9   chromedriver                        0x00000001041bb9ec chromedriver + 506348
10  chromedriver                        0x00000001045224e8 chromedriver + 4072680
11  chromedriver                        0x0000000104526f94 chromedriver + 4091796
12  chromedriver                        0x000000010450972c chromedriver + 3970860
13  chromedriver                        0x000000010452787c chromedriver + 4094076
14  chromedriver                        0x00000001044fc6ac chromedriver + 3917484
15  chromedriver                        0x0000000104544ae0 chromedriver + 4213472
16  chromedriver                        0x0000000104544c5c chromedriver + 4213852
17  chromedriver                        0x00000001045529e0 chromedriver + 4270560
18  libsystem_pthread.dylib             0x00000001992aaf94 _pthread_start + 136
19  libsystem_pthread.dylib             0x00000001992a5d34 thread_start + 8


During handling of the above exception, another exception occurred:

Traceback (most recent call last):
  File "/opt/homebrew/Cellar/python@3.11/3.11.7/Frameworks/Python.framework/Versions/3.11/lib/python3.11/logging/__init__.py", line 1110, in emit
    msg = self.format(record)
          ^^^^^^^^^^^^^^^^^^^
  File "/opt/homebrew/Cellar/python@3.11/3.11.7/Frameworks/Python.framework/Versions/3.11/lib/python3.11/logging/__init__.py", line 953, in format
    return fmt.format(record)
           ^^^^^^^^^^^^^^^^^^
  File "/opt/homebrew/Cellar/python@3.11/3.11.7/Frameworks/Python.framework/Versions/3.11/lib/python3.11/logging/__init__.py", line 687, in format
    record.message = record.getMessage()
                     ^^^^^^^^^^^^^^^^^^^
  File "/opt/homebrew/Cellar/python@3.11/3.11.7/Frameworks/Python.framework/Versions/3.11/lib/python3.11/logging/__init__.py", line 377, in getMessage
    msg = msg % self.args
          ~~~~^~~~~~~~~~~
TypeError: not all arguments converted during string formatting
Call stack:
  File "/Users/frederic/tinder-bot/navigate_bumble.py", line 74, in <module>
    navigate(driver, is_beautiful)
  File "/Users/frederic/tinder-bot/navigate_bumble.py", line 45, in navigate
    logger.info("No match found or error occurred: ", e)
Message: 'No match found or error occurred: '
Arguments: (JavascriptException(),)
2024-05-23 11:41:45,833 - INFO - Pressed Right Arrow Key.

2024-05-23 11:41:46,060 - INFO - Running extract_image_bumble.py...
2024-05-23 11:41:46,060 - INFO - Running script: /Users/frederic/tinder-bot/extract_image_bumble.py with args: []
2024-05-23 11:41:46,667 - INFO - Loading session...
Restoring session: 8345ebf593c38af1d820dbf8fe65b084, http://localhost:53760
Waiting for image element...
Image element found.
Image URL: https://am1.ecdn2.bumbcdn.com/p1503/hidden?euri=AAAAAAAAAAIQP2MIxlawqDZLC.rpc5HozQAM1DTLlgSWfcBnlFyfAVWN31OEPVQ6Xo63s9DAI4E9Tjr988z2POzpKhll02hzWTV10U2v6ZWAZ06qp7ndjvurhCgds1FOCeaLG54VFBkfuZ54LyZAkvnIopL7r3Ywopwt3-wdjROYKFT1ukXzLgIPinyyGt1X6kqqmwrQlUQyA4M1I9Ra4vdlhLgUVLwV&size=__size__&ck=37281b4762891acef6249d15abe8f5d9&wm_size=72x72&wm_offs=973x1323&h=-oa&gs=j&t=42.1.0.0
Image téléchargée et convertie en JPEG : /Users/frederic/tinder-bot/profile_image_bumble.jpg
L'image est enregistrée à l'emplacement : /Users/frederic/tinder-bot/profile_image_bumble.jpg

2024-05-23 11:41:46,667 - ERROR - 
2024-05-23 11:41:46,667 - INFO - Running evaluation_bumble.py...
2024-05-23 11:41:46,667 - INFO - Running script: /Users/frederic/tinder-bot/evaluation_bumble.py with args: []
2024-05-23 11:41:51,129 - INFO - Evaluating image at: /Users/frederic/tinder-bot/profile_image_bumble.jpg
Detection result: {'request_id': '1716475308,c0586643-7f93-4f21-9813-a2b32e59336c', 'time_used': 148, 'faces': [{'face_token': '32da6338b76097191870cd5be8e467d4', 'face_rectangle': {'top': 262, 'left': 373, 'width': 319, 'height': 319}, 'attributes': {'facequality': {'value': 68.18, 'threshold': 70.1}}}], 'image_id': 'XzS8lizAVWkQ21tXLFdeJQ==', 'face_num': 1}
Analyze result: {'time_used': 72, 'request_id': '1716475310,9a49c7d4-d84f-4762-b304-cf499db9a89c', 'faces': [{'attributes': {'gender': {'value': 'Female'}, 'age': {'value': 47}, 'beauty': {'female_score': 70.702, 'male_score': 71.361}}, 'face_rectangle': {'width': 319, 'top': 262, 'left': 373, 'height': 319}, 'face_token': '32da6338b76097191870cd5be8e467d4'}]}
Image: Belle (Female Score: 70.702, Male Score: 71.361)

2024-05-23 11:41:51,129 - ERROR - 
2024-05-23 11:41:51,129 - INFO - Evaluation result: is_beautiful=True
2024-05-23 11:41:51,129 - INFO - Running navigate_bumble.py with is_beautiful=True...
2024-05-23 11:41:51,129 - INFO - Running script: /Users/frederic/tinder-bot/navigate_bumble.py with args: ['true']
2024-05-23 11:41:51,408 - INFO - 
2024-05-23 11:41:51,408 - ERROR - 2024-05-23 11:41:51,212 - INFO - is_beautiful: True
2024-05-23 11:41:51,212 - INFO - Loading session...
2024-05-23 11:41:51,212 - INFO - Restoring session: 8345ebf593c38af1d820dbf8fe65b084, http://localhost:53760
--- Logging error ---
Traceback (most recent call last):
  File "/Users/frederic/tinder-bot/navigate_bumble.py", line 38, in navigate
    match_button = WebDriverWait(driver, 5).until(
                   ^^^^^^^^^^^^^^^^^^^^^^^^^^^^^^^
  File "/opt/homebrew/lib/python3.11/site-packages/selenium/webdriver/support/wait.py", line 96, in until
    value = method(self._driver)
            ^^^^^^^^^^^^^^^^^^^^
  File "/opt/homebrew/lib/python3.11/site-packages/selenium/webdriver/support/expected_conditions.py", line 84, in _predicate
    return driver.find_element(*locator)
           ^^^^^^^^^^^^^^^^^^^^^^^^^^^^^
  File "/opt/homebrew/lib/python3.11/site-packages/selenium/webdriver/remote/webdriver.py", line 741, in find_element
    return self.execute(Command.FIND_ELEMENT, {"using": by, "value": value})["value"]
           ^^^^^^^^^^^^^^^^^^^^^^^^^^^^^^^^^^^^^^^^^^^^^^^^^^^^^^^^^^^^^^^^^
  File "/opt/homebrew/lib/python3.11/site-packages/selenium/webdriver/remote/webdriver.py", line 347, in execute
    self.error_handler.check_response(response)
  File "/opt/homebrew/lib/python3.11/site-packages/selenium/webdriver/remote/errorhandler.py", line 229, in check_response
    raise exception_class(message, screen, stacktrace)
selenium.common.exceptions.JavascriptException: Message: javascript error: {"status":32,"value":"Unable to locate an element with the xpath expression //span[text()='Voir d'autres profils'] because of the following error:\nSyntaxError: Failed to execute 'evaluate' on 'Document': The string '//span[text()='Voir d'autres profils']' is not a valid XPath expression."}
  (Session info: chrome=125.0.6422.61)
Stacktrace:
0   chromedriver                        0x000000010455a4a0 chromedriver + 4301984
1   chromedriver                        0x0000000104552de8 chromedriver + 4271592
2   chromedriver                        0x000000010418419c chromedriver + 278940
3   chromedriver                        0x000000010418866c chromedriver + 296556
4   chromedriver                        0x000000010418a4e8 chromedriver + 304360
5   chromedriver                        0x000000010418a560 chromedriver + 304480
6   chromedriver                        0x00000001041c63c0 chromedriver + 549824
7   chromedriver                        0x00000001041fec5c chromedriver + 781404
8   chromedriver                        0x00000001041bb004 chromedriver + 503812
9   chromedriver                        0x00000001041bb9ec chromedriver + 506348
10  chromedriver                        0x00000001045224e8 chromedriver + 4072680
11  chromedriver                        0x0000000104526f94 chromedriver + 4091796
12  chromedriver                        0x000000010450972c chromedriver + 3970860
13  chromedriver                        0x000000010452787c chromedriver + 4094076
14  chromedriver                        0x00000001044fc6ac chromedriver + 3917484
15  chromedriver                        0x0000000104544ae0 chromedriver + 4213472
16  chromedriver                        0x0000000104544c5c chromedriver + 4213852
17  chromedriver                        0x00000001045529e0 chromedriver + 4270560
18  libsystem_pthread.dylib             0x00000001992aaf94 _pthread_start + 136
19  libsystem_pthread.dylib             0x00000001992a5d34 thread_start + 8


During handling of the above exception, another exception occurred:

Traceback (most recent call last):
  File "/opt/homebrew/Cellar/python@3.11/3.11.7/Frameworks/Python.framework/Versions/3.11/lib/python3.11/logging/__init__.py", line 1110, in emit
    msg = self.format(record)
          ^^^^^^^^^^^^^^^^^^^
  File "/opt/homebrew/Cellar/python@3.11/3.11.7/Frameworks/Python.framework/Versions/3.11/lib/python3.11/logging/__init__.py", line 953, in format
    return fmt.format(record)
           ^^^^^^^^^^^^^^^^^^
  File "/opt/homebrew/Cellar/python@3.11/3.11.7/Frameworks/Python.framework/Versions/3.11/lib/python3.11/logging/__init__.py", line 687, in format
    record.message = record.getMessage()
                     ^^^^^^^^^^^^^^^^^^^
  File "/opt/homebrew/Cellar/python@3.11/3.11.7/Frameworks/Python.framework/Versions/3.11/lib/python3.11/logging/__init__.py", line 377, in getMessage
    msg = msg % self.args
          ~~~~^~~~~~~~~~~
TypeError: not all arguments converted during string formatting
Call stack:
  File "/Users/frederic/tinder-bot/navigate_bumble.py", line 74, in <module>
    navigate(driver, is_beautiful)
  File "/Users/frederic/tinder-bot/navigate_bumble.py", line 45, in navigate
    logger.info("No match found or error occurred: ", e)
Message: 'No match found or error occurred: '
Arguments: (JavascriptException(),)
2024-05-23 11:41:51,393 - INFO - Pressed Right Arrow Key.

2024-05-23 11:41:51,699 - INFO - Running extract_image_bumble.py...
2024-05-23 11:41:51,699 - INFO - Running script: /Users/frederic/tinder-bot/extract_image_bumble.py with args: []
2024-05-23 11:41:52,126 - INFO - Loading session...
Restoring session: 8345ebf593c38af1d820dbf8fe65b084, http://localhost:53760
Waiting for image element...
Image element found.
Image URL: https://us1.ecdn2.bumbcdn.com/p522/hidden?euri=AAAAAAAAAAIQIJ.JLkdPZeOYVJFazkuV5AB3Je5QoNlSIWrmJsFDTFml3FIoM36FQ5cH9I.VoHfBPlDViWPHS6XfXBNBTdt1mIcQb.8-oop4mwipuBa3fP3kmN.bHs3hKtS5Ldn6njVAVjWf1cat-g-eWrbcX9whD6U70KFOqBCRjjU2GCLRA5am9hN.FPO9zEM5C-QAFT8FkJtLl29CCd4tNsYspcyW&size=__size__&ck=180b0108a94e25e2d0b02a036c3b8b1d&wm_size=72x72&wm_offs=522x720&h=AQj&gs=j&t=42.1.0.0
Image téléchargée et convertie en JPEG : /Users/frederic/tinder-bot/profile_image_bumble.jpg
L'image est enregistrée à l'emplacement : /Users/frederic/tinder-bot/profile_image_bumble.jpg

2024-05-23 11:41:52,126 - ERROR - 
2024-05-23 11:41:52,126 - INFO - Running evaluation_bumble.py...
2024-05-23 11:41:52,126 - INFO - Running script: /Users/frederic/tinder-bot/evaluation_bumble.py with args: []
2024-05-23 11:41:56,157 - INFO - Evaluating image at: /Users/frederic/tinder-bot/profile_image_bumble.jpg
Detection result: {'request_id': '1716475313,b66e454e-b9b2-4f49-be90-1fc032336310', 'time_used': 78, 'faces': [{'face_token': '1944483849ebb12fbc2f95abcc702b2c', 'face_rectangle': {'top': 246, 'left': 215, 'width': 197, 'height': 197}, 'attributes': {'facequality': {'value': 55.041, 'threshold': 70.1}}}], 'image_id': 'P2YdTUlY5/IdC9ud9CQQaQ==', 'face_num': 1}
Analyze result: {'time_used': 54, 'request_id': '1716475316,9598d83a-de0b-4a08-9416-3c7518344aaf', 'faces': [{'attributes': {'gender': {'value': 'Female'}, 'age': {'value': 41}, 'beauty': {'female_score': 68.821, 'male_score': 59.388}}, 'face_rectangle': {'width': 197, 'top': 246, 'left': 215, 'height': 197}, 'face_token': '1944483849ebb12fbc2f95abcc702b2c'}]}
Image: Belle (Female Score: 68.821, Male Score: 59.388)

2024-05-23 11:41:56,157 - ERROR - 
2024-05-23 11:41:56,157 - INFO - Evaluation result: is_beautiful=True
2024-05-23 11:41:56,157 - INFO - Running navigate_bumble.py with is_beautiful=True...
2024-05-23 11:41:56,157 - INFO - Running script: /Users/frederic/tinder-bot/navigate_bumble.py with args: ['true']
2024-05-23 11:41:56,592 - INFO - 
2024-05-23 11:41:56,592 - ERROR - 2024-05-23 11:41:56,239 - INFO - is_beautiful: True
2024-05-23 11:41:56,239 - INFO - Loading session...
2024-05-23 11:41:56,239 - INFO - Restoring session: 8345ebf593c38af1d820dbf8fe65b084, http://localhost:53760
--- Logging error ---
Traceback (most recent call last):
  File "/Users/frederic/tinder-bot/navigate_bumble.py", line 38, in navigate
    match_button = WebDriverWait(driver, 5).until(
                   ^^^^^^^^^^^^^^^^^^^^^^^^^^^^^^^
  File "/opt/homebrew/lib/python3.11/site-packages/selenium/webdriver/support/wait.py", line 96, in until
    value = method(self._driver)
            ^^^^^^^^^^^^^^^^^^^^
  File "/opt/homebrew/lib/python3.11/site-packages/selenium/webdriver/support/expected_conditions.py", line 84, in _predicate
    return driver.find_element(*locator)
           ^^^^^^^^^^^^^^^^^^^^^^^^^^^^^
  File "/opt/homebrew/lib/python3.11/site-packages/selenium/webdriver/remote/webdriver.py", line 741, in find_element
    return self.execute(Command.FIND_ELEMENT, {"using": by, "value": value})["value"]
           ^^^^^^^^^^^^^^^^^^^^^^^^^^^^^^^^^^^^^^^^^^^^^^^^^^^^^^^^^^^^^^^^^
  File "/opt/homebrew/lib/python3.11/site-packages/selenium/webdriver/remote/webdriver.py", line 347, in execute
    self.error_handler.check_response(response)
  File "/opt/homebrew/lib/python3.11/site-packages/selenium/webdriver/remote/errorhandler.py", line 229, in check_response
    raise exception_class(message, screen, stacktrace)
selenium.common.exceptions.JavascriptException: Message: javascript error: {"status":32,"value":"Unable to locate an element with the xpath expression //span[text()='Voir d'autres profils'] because of the following error:\nSyntaxError: Failed to execute 'evaluate' on 'Document': The string '//span[text()='Voir d'autres profils']' is not a valid XPath expression."}
  (Session info: chrome=125.0.6422.61)
Stacktrace:
0   chromedriver                        0x000000010455a4a0 chromedriver + 4301984
1   chromedriver                        0x0000000104552de8 chromedriver + 4271592
2   chromedriver                        0x000000010418419c chromedriver + 278940
3   chromedriver                        0x000000010418866c chromedriver + 296556
4   chromedriver                        0x000000010418a4e8 chromedriver + 304360
5   chromedriver                        0x000000010418a560 chromedriver + 304480
6   chromedriver                        0x00000001041c63c0 chromedriver + 549824
7   chromedriver                        0x00000001041fec5c chromedriver + 781404
8   chromedriver                        0x00000001041bb004 chromedriver + 503812
9   chromedriver                        0x00000001041bb9ec chromedriver + 506348
10  chromedriver                        0x00000001045224e8 chromedriver + 4072680
11  chromedriver                        0x0000000104526f94 chromedriver + 4091796
12  chromedriver                        0x000000010450972c chromedriver + 3970860
13  chromedriver                        0x000000010452787c chromedriver + 4094076
14  chromedriver                        0x00000001044fc6ac chromedriver + 3917484
15  chromedriver                        0x0000000104544ae0 chromedriver + 4213472
16  chromedriver                        0x0000000104544c5c chromedriver + 4213852
17  chromedriver                        0x00000001045529e0 chromedriver + 4270560
18  libsystem_pthread.dylib             0x00000001992aaf94 _pthread_start + 136
19  libsystem_pthread.dylib             0x00000001992a5d34 thread_start + 8


During handling of the above exception, another exception occurred:

Traceback (most recent call last):
  File "/opt/homebrew/Cellar/python@3.11/3.11.7/Frameworks/Python.framework/Versions/3.11/lib/python3.11/logging/__init__.py", line 1110, in emit
    msg = self.format(record)
          ^^^^^^^^^^^^^^^^^^^
  File "/opt/homebrew/Cellar/python@3.11/3.11.7/Frameworks/Python.framework/Versions/3.11/lib/python3.11/logging/__init__.py", line 953, in format
    return fmt.format(record)
           ^^^^^^^^^^^^^^^^^^
  File "/opt/homebrew/Cellar/python@3.11/3.11.7/Frameworks/Python.framework/Versions/3.11/lib/python3.11/logging/__init__.py", line 687, in format
    record.message = record.getMessage()
                     ^^^^^^^^^^^^^^^^^^^
  File "/opt/homebrew/Cellar/python@3.11/3.11.7/Frameworks/Python.framework/Versions/3.11/lib/python3.11/logging/__init__.py", line 377, in getMessage
    msg = msg % self.args
          ~~~~^~~~~~~~~~~
TypeError: not all arguments converted during string formatting
Call stack:
  File "/Users/frederic/tinder-bot/navigate_bumble.py", line 74, in <module>
    navigate(driver, is_beautiful)
  File "/Users/frederic/tinder-bot/navigate_bumble.py", line 45, in navigate
    logger.info("No match found or error occurred: ", e)
Message: 'No match found or error occurred: '
Arguments: (JavascriptException(),)
2024-05-23 11:41:56,579 - INFO - Pressed Right Arrow Key.

2024-05-23 11:41:56,802 - INFO - Running extract_image_bumble.py...
2024-05-23 11:41:56,802 - INFO - Running script: /Users/frederic/tinder-bot/extract_image_bumble.py with args: []
2024-05-23 11:41:57,362 - INFO - Loading session...
Restoring session: 8345ebf593c38af1d820dbf8fe65b084, http://localhost:53760
Waiting for image element...
Image element found.
Image URL: https://us1.ecdn2.bumbcdn.com/p576/hidden?euri=AAAAAAAAAAIQYWCpDyw8Z2bwdfSFwabz0gDR0hhYUf.ZJyXU1G.HdawnN7rfIqao9-wnNRzFJs6qAC12o3CMND36Au12m-G-1Nf4ABzRZ9Vyilz94bJpswmfK2Mggzs-Vae81BHvxTOAUHsZrkdYQidh3uUVtLFK5pHAu1wrHBws5VTqxRphowKUASPk3NuugWk93cW0IqqJM-x0HHlCvb.rTkkNBKd7&size=__size__&ck=3f240e70807215079028b0282c6254da&wm_size=72x72&wm_offs=973x1322&h=FN9&gs=j&t=42.1.0.0
Image téléchargée et convertie en JPEG : /Users/frederic/tinder-bot/profile_image_bumble.jpg
L'image est enregistrée à l'emplacement : /Users/frederic/tinder-bot/profile_image_bumble.jpg

2024-05-23 11:41:57,362 - ERROR - 
2024-05-23 11:41:57,362 - INFO - Running evaluation_bumble.py...
2024-05-23 11:41:57,362 - INFO - Running script: /Users/frederic/tinder-bot/evaluation_bumble.py with args: []
2024-05-23 11:42:01,676 - INFO - Evaluating image at: /Users/frederic/tinder-bot/profile_image_bumble.jpg
Detection result: {'request_id': '1716475318,e264f7b3-86f9-408f-8a3e-faab54c4298b', 'time_used': 125, 'faces': [{'face_token': '3fd45eb88c811fabc9f4cba45273cbc5', 'face_rectangle': {'top': 175, 'left': 223, 'width': 802, 'height': 802}, 'attributes': {'facequality': {'value': 29.433, 'threshold': 70.1}}}], 'image_id': 'aQuJXusWXiUXG6YSxH6fqQ==', 'face_num': 1}
Analyze result: {'time_used': 109, 'request_id': '1716475321,3c56364b-b478-4dc6-ad33-0668242203c9', 'faces': [{'attributes': {'gender': {'value': 'Female'}, 'age': {'value': 33}, 'beauty': {'female_score': 48.088, 'male_score': 44.679}}, 'face_rectangle': {'width': 802, 'top': 175, 'left': 223, 'height': 802}, 'face_token': '3fd45eb88c811fabc9f4cba45273cbc5'}]}
Image: Pas Belle (Female Score: 48.088, Male Score: 44.679)

2024-05-23 11:42:01,676 - ERROR - 
2024-05-23 11:42:01,677 - INFO - Evaluation result: is_beautiful=False
2024-05-23 11:42:01,677 - INFO - Running navigate_bumble.py with is_beautiful=False...
2024-05-23 11:42:01,677 - INFO - Running script: /Users/frederic/tinder-bot/navigate_bumble.py with args: ['false']
2024-05-23 11:42:02,117 - INFO - 
2024-05-23 11:42:02,117 - ERROR - 2024-05-23 11:42:01,759 - INFO - is_beautiful: False
2024-05-23 11:42:01,760 - INFO - Loading session...
2024-05-23 11:42:01,760 - INFO - Restoring session: 8345ebf593c38af1d820dbf8fe65b084, http://localhost:53760
--- Logging error ---
Traceback (most recent call last):
  File "/Users/frederic/tinder-bot/navigate_bumble.py", line 38, in navigate
    match_button = WebDriverWait(driver, 5).until(
                   ^^^^^^^^^^^^^^^^^^^^^^^^^^^^^^^
  File "/opt/homebrew/lib/python3.11/site-packages/selenium/webdriver/support/wait.py", line 96, in until
    value = method(self._driver)
            ^^^^^^^^^^^^^^^^^^^^
  File "/opt/homebrew/lib/python3.11/site-packages/selenium/webdriver/support/expected_conditions.py", line 84, in _predicate
    return driver.find_element(*locator)
           ^^^^^^^^^^^^^^^^^^^^^^^^^^^^^
  File "/opt/homebrew/lib/python3.11/site-packages/selenium/webdriver/remote/webdriver.py", line 741, in find_element
    return self.execute(Command.FIND_ELEMENT, {"using": by, "value": value})["value"]
           ^^^^^^^^^^^^^^^^^^^^^^^^^^^^^^^^^^^^^^^^^^^^^^^^^^^^^^^^^^^^^^^^^
  File "/opt/homebrew/lib/python3.11/site-packages/selenium/webdriver/remote/webdriver.py", line 347, in execute
    self.error_handler.check_response(response)
  File "/opt/homebrew/lib/python3.11/site-packages/selenium/webdriver/remote/errorhandler.py", line 229, in check_response
    raise exception_class(message, screen, stacktrace)
selenium.common.exceptions.JavascriptException: Message: javascript error: {"status":32,"value":"Unable to locate an element with the xpath expression //span[text()='Voir d'autres profils'] because of the following error:\nSyntaxError: Failed to execute 'evaluate' on 'Document': The string '//span[text()='Voir d'autres profils']' is not a valid XPath expression."}
  (Session info: chrome=125.0.6422.61)
Stacktrace:
0   chromedriver                        0x000000010455a4a0 chromedriver + 4301984
1   chromedriver                        0x0000000104552de8 chromedriver + 4271592
2   chromedriver                        0x000000010418419c chromedriver + 278940
3   chromedriver                        0x000000010418866c chromedriver + 296556
4   chromedriver                        0x000000010418a4e8 chromedriver + 304360
5   chromedriver                        0x000000010418a560 chromedriver + 304480
6   chromedriver                        0x00000001041c63c0 chromedriver + 549824
7   chromedriver                        0x00000001041fec5c chromedriver + 781404
8   chromedriver                        0x00000001041bb004 chromedriver + 503812
9   chromedriver                        0x00000001041bb9ec chromedriver + 506348
10  chromedriver                        0x00000001045224e8 chromedriver + 4072680
11  chromedriver                        0x0000000104526f94 chromedriver + 4091796
12  chromedriver                        0x000000010450972c chromedriver + 3970860
13  chromedriver                        0x000000010452787c chromedriver + 4094076
14  chromedriver                        0x00000001044fc6ac chromedriver + 3917484
15  chromedriver                        0x0000000104544ae0 chromedriver + 4213472
16  chromedriver                        0x0000000104544c5c chromedriver + 4213852
17  chromedriver                        0x00000001045529e0 chromedriver + 4270560
18  libsystem_pthread.dylib             0x00000001992aaf94 _pthread_start + 136
19  libsystem_pthread.dylib             0x00000001992a5d34 thread_start + 8


During handling of the above exception, another exception occurred:

Traceback (most recent call last):
  File "/opt/homebrew/Cellar/python@3.11/3.11.7/Frameworks/Python.framework/Versions/3.11/lib/python3.11/logging/__init__.py", line 1110, in emit
    msg = self.format(record)
          ^^^^^^^^^^^^^^^^^^^
  File "/opt/homebrew/Cellar/python@3.11/3.11.7/Frameworks/Python.framework/Versions/3.11/lib/python3.11/logging/__init__.py", line 953, in format
    return fmt.format(record)
           ^^^^^^^^^^^^^^^^^^
  File "/opt/homebrew/Cellar/python@3.11/3.11.7/Frameworks/Python.framework/Versions/3.11/lib/python3.11/logging/__init__.py", line 687, in format
    record.message = record.getMessage()
                     ^^^^^^^^^^^^^^^^^^^
  File "/opt/homebrew/Cellar/python@3.11/3.11.7/Frameworks/Python.framework/Versions/3.11/lib/python3.11/logging/__init__.py", line 377, in getMessage
    msg = msg % self.args
          ~~~~^~~~~~~~~~~
TypeError: not all arguments converted during string formatting
Call stack:
  File "/Users/frederic/tinder-bot/navigate_bumble.py", line 74, in <module>
    navigate(driver, is_beautiful)
  File "/Users/frederic/tinder-bot/navigate_bumble.py", line 45, in navigate
    logger.info("No match found or error occurred: ", e)
Message: 'No match found or error occurred: '
Arguments: (JavascriptException(),)
2024-05-23 11:42:02,104 - INFO - Pressed Left Arrow Key.

2024-05-23 11:42:02,380 - INFO - Running extract_image_bumble.py...
2024-05-23 11:42:02,380 - INFO - Running script: /Users/frederic/tinder-bot/extract_image_bumble.py with args: []
2024-05-23 11:42:03,021 - INFO - Loading session...
Restoring session: 8345ebf593c38af1d820dbf8fe65b084, http://localhost:53760
Waiting for image element...
Image element found.
Image URL: https://us1.ecdn2.bumbcdn.com/p528/hidden?euri=AAAAAAAAAAIQkTRowOjQa7AEDuh7kWnqgQBHU1b9hnSd-QpiXcfC1neJ1s-VPsEj0HqBhgDa2q1P2VCFyhyT89iBT0zTS1IJ80vEfKiuY0KcSjJW.lM7OqwizqumtZZQ0oE59OZJHQymK9j9CTtXlaS4kaOS7mWLbAEqazHhxX4P8WfiFpHjCRKwjQYGhvXJEmueJT.lrV6ZCvgfnqpW1vd75ua8-4LR&size=__size__&ck=2f59960bdc47c092beae255f4458dd14&wm_size=72x72&wm_offs=973x1103&h=3ER&gs=j&t=42.1.0.0
Image téléchargée et convertie en JPEG : /Users/frederic/tinder-bot/profile_image_bumble.jpg
L'image est enregistrée à l'emplacement : /Users/frederic/tinder-bot/profile_image_bumble.jpg

2024-05-23 11:42:03,021 - ERROR - 
2024-05-23 11:42:03,021 - INFO - Running evaluation_bumble.py...
2024-05-23 11:42:03,021 - INFO - Running script: /Users/frederic/tinder-bot/evaluation_bumble.py with args: []
2024-05-23 11:42:07,099 - INFO - Evaluating image at: /Users/frederic/tinder-bot/profile_image_bumble.jpg
Detection result: {'request_id': '1716475324,37d87bea-ed0d-4285-83d4-3f9c508a3754', 'time_used': 104, 'faces': [{'face_token': '6f9dfc93a873f8f7890b5e905c0bcd4b', 'face_rectangle': {'top': 436, 'left': 371, 'width': 361, 'height': 361}, 'attributes': {'facequality': {'value': 87.897, 'threshold': 70.1}}}], 'image_id': 'Om3BWr8/pkFcdP2BltQOkw==', 'face_num': 1}
Analyze result: {'time_used': 105, 'request_id': '1716475326,f189c68c-81fb-45b8-b2ec-0b5903b9be2d', 'faces': [{'attributes': {'gender': {'value': 'Female'}, 'age': {'value': 53}, 'beauty': {'female_score': 45.534, 'male_score': 43.469}}, 'face_rectangle': {'width': 361, 'top': 436, 'left': 371, 'height': 361}, 'face_token': '6f9dfc93a873f8f7890b5e905c0bcd4b'}]}
Image: Pas Belle (Female Score: 45.534, Male Score: 43.469)

2024-05-23 11:42:07,099 - ERROR - 
2024-05-23 11:42:07,099 - INFO - Evaluation result: is_beautiful=False
2024-05-23 11:42:07,099 - INFO - Running navigate_bumble.py with is_beautiful=False...
2024-05-23 11:42:07,099 - INFO - Running script: /Users/frederic/tinder-bot/navigate_bumble.py with args: ['false']
2024-05-23 11:42:07,675 - INFO - 
2024-05-23 11:42:07,675 - ERROR - 2024-05-23 11:42:07,184 - INFO - is_beautiful: False
2024-05-23 11:42:07,184 - INFO - Loading session...
2024-05-23 11:42:07,184 - INFO - Restoring session: 8345ebf593c38af1d820dbf8fe65b084, http://localhost:53760
--- Logging error ---
Traceback (most recent call last):
  File "/Users/frederic/tinder-bot/navigate_bumble.py", line 38, in navigate
    match_button = WebDriverWait(driver, 5).until(
                   ^^^^^^^^^^^^^^^^^^^^^^^^^^^^^^^
  File "/opt/homebrew/lib/python3.11/site-packages/selenium/webdriver/support/wait.py", line 96, in until
    value = method(self._driver)
            ^^^^^^^^^^^^^^^^^^^^
  File "/opt/homebrew/lib/python3.11/site-packages/selenium/webdriver/support/expected_conditions.py", line 84, in _predicate
    return driver.find_element(*locator)
           ^^^^^^^^^^^^^^^^^^^^^^^^^^^^^
  File "/opt/homebrew/lib/python3.11/site-packages/selenium/webdriver/remote/webdriver.py", line 741, in find_element
    return self.execute(Command.FIND_ELEMENT, {"using": by, "value": value})["value"]
           ^^^^^^^^^^^^^^^^^^^^^^^^^^^^^^^^^^^^^^^^^^^^^^^^^^^^^^^^^^^^^^^^^
  File "/opt/homebrew/lib/python3.11/site-packages/selenium/webdriver/remote/webdriver.py", line 347, in execute
    self.error_handler.check_response(response)
  File "/opt/homebrew/lib/python3.11/site-packages/selenium/webdriver/remote/errorhandler.py", line 229, in check_response
    raise exception_class(message, screen, stacktrace)
selenium.common.exceptions.JavascriptException: Message: javascript error: {"status":32,"value":"Unable to locate an element with the xpath expression //span[text()='Voir d'autres profils'] because of the following error:\nSyntaxError: Failed to execute 'evaluate' on 'Document': The string '//span[text()='Voir d'autres profils']' is not a valid XPath expression."}
  (Session info: chrome=125.0.6422.61)
Stacktrace:
0   chromedriver                        0x000000010455a4a0 chromedriver + 4301984
1   chromedriver                        0x0000000104552de8 chromedriver + 4271592
2   chromedriver                        0x000000010418419c chromedriver + 278940
3   chromedriver                        0x000000010418866c chromedriver + 296556
4   chromedriver                        0x000000010418a4e8 chromedriver + 304360
5   chromedriver                        0x000000010418a560 chromedriver + 304480
6   chromedriver                        0x00000001041c63c0 chromedriver + 549824
7   chromedriver                        0x00000001041fec5c chromedriver + 781404
8   chromedriver                        0x00000001041bb004 chromedriver + 503812
9   chromedriver                        0x00000001041bb9ec chromedriver + 506348
10  chromedriver                        0x00000001045224e8 chromedriver + 4072680
11  chromedriver                        0x0000000104526f94 chromedriver + 4091796
12  chromedriver                        0x000000010450972c chromedriver + 3970860
13  chromedriver                        0x000000010452787c chromedriver + 4094076
14  chromedriver                        0x00000001044fc6ac chromedriver + 3917484
15  chromedriver                        0x0000000104544ae0 chromedriver + 4213472
16  chromedriver                        0x0000000104544c5c chromedriver + 4213852
17  chromedriver                        0x00000001045529e0 chromedriver + 4270560
18  libsystem_pthread.dylib             0x00000001992aaf94 _pthread_start + 136
19  libsystem_pthread.dylib             0x00000001992a5d34 thread_start + 8


During handling of the above exception, another exception occurred:

Traceback (most recent call last):
  File "/opt/homebrew/Cellar/python@3.11/3.11.7/Frameworks/Python.framework/Versions/3.11/lib/python3.11/logging/__init__.py", line 1110, in emit
    msg = self.format(record)
          ^^^^^^^^^^^^^^^^^^^
  File "/opt/homebrew/Cellar/python@3.11/3.11.7/Frameworks/Python.framework/Versions/3.11/lib/python3.11/logging/__init__.py", line 953, in format
    return fmt.format(record)
           ^^^^^^^^^^^^^^^^^^
  File "/opt/homebrew/Cellar/python@3.11/3.11.7/Frameworks/Python.framework/Versions/3.11/lib/python3.11/logging/__init__.py", line 687, in format
    record.message = record.getMessage()
                     ^^^^^^^^^^^^^^^^^^^
  File "/opt/homebrew/Cellar/python@3.11/3.11.7/Frameworks/Python.framework/Versions/3.11/lib/python3.11/logging/__init__.py", line 377, in getMessage
    msg = msg % self.args
          ~~~~^~~~~~~~~~~
TypeError: not all arguments converted during string formatting
Call stack:
  File "/Users/frederic/tinder-bot/navigate_bumble.py", line 74, in <module>
    navigate(driver, is_beautiful)
  File "/Users/frederic/tinder-bot/navigate_bumble.py", line 45, in navigate
    logger.info("No match found or error occurred: ", e)
Message: 'No match found or error occurred: '
Arguments: (JavascriptException(),)
2024-05-23 11:42:07,662 - INFO - Pressed Left Arrow Key.

2024-05-23 11:42:07,896 - INFO - Running extract_image_bumble.py...
2024-05-23 11:42:07,896 - INFO - Running script: /Users/frederic/tinder-bot/extract_image_bumble.py with args: []
2024-05-23 11:42:08,494 - INFO - Loading session...
Restoring session: 8345ebf593c38af1d820dbf8fe65b084, http://localhost:53760
Waiting for image element...
Image element found.
Image URL: https://us1.ecdn2.bumbcdn.com/p534/hidden?euri=AAAAAAAAAAIQ8R.4GxmqBJJG0hZCkFLEAADAQ6N5m3mediP98TFM4hfMwJ0vDB3OG3edQCj3nbIBMWXF78kwc7TJtCs1dS93-bczjYL.sQsiLN8WPRDX4Qr3vZdeUypzkUQdvTEKJ8N4jD6uq-D7IvCs6NdowL6FVArugywYB4OnYYDM92aPm378nB0-zZqn52zmeaxYkFyagS.bNa5AlOXYyWuTmh09&size=__size__&ck=cfaa2bd2ef0346a23b6f65267596f85c&wm_size=72x72&wm_offs=643x747&h=KVd&gs=j&t=42.1.0.0
Image téléchargée et convertie en JPEG : /Users/frederic/tinder-bot/profile_image_bumble.jpg
L'image est enregistrée à l'emplacement : /Users/frederic/tinder-bot/profile_image_bumble.jpg

2024-05-23 11:42:08,494 - ERROR - 
2024-05-23 11:42:08,494 - INFO - Running evaluation_bumble.py...
2024-05-23 11:42:08,494 - INFO - Running script: /Users/frederic/tinder-bot/evaluation_bumble.py with args: []
