2024-05-21 12:09:59,638 - INFO - Le processus commencera dans 3 secondes.
2024-05-21 12:10:04,876 - INFO - Fermeture de Google Chrome...
2024-05-21 12:10:09,917 - INFO - Google Chrome est fermé.
2024-05-21 12:10:09,919 - INFO - Running open_bumble.py...
2024-05-21 12:10:09,929 - INFO - Waiting for session to be ready...
2024-05-21 12:10:50,011 - INFO - Session is ready. Starting extraction and evaluation process...
2024-05-21 12:11:00,016 - INFO - Running extract_image_bumble.py...
2024-05-21 12:11:00,017 - INFO - Running script: /Users/frederic/tinder-bot/extract_image_bumble.py with args: []
2024-05-21 12:11:00,645 - INFO - Loading session...
Restoring session: 21e9521c4ab550bcf067ca9b1c334625, http://localhost:60305
Waiting for image element...
Image element found.
Image URL: https://us1.ecdn2.bumbcdn.com/p510/hidden?euri=AAAAAAAAAAIQzw6a0rGJtKbxS1n0Mk8H5wA06JrEwi.ud7PQXuoC7AFEEleIQQPW5aILabCkOvC7C5kzZnkFJRjxVliFecJzUqwdpl6.qqSs6p.sw9qW5XsFmuH6KtHfhpKypW2EPTHkZWoh1LTVNOUuqogx9kMlez07nGJJ8C8usvO1lRX-aMbIaKsFL-go8ylEu7WW6iSXj3n3MRHdgl6g7Iv8Gc6F&size=__size__&ck=ce4563694d4ee02579048bceac07cca6&wm_size=72x72&wm_offs=973x1323&h=fKQ&gs=j&t=42.1.0.0
Image téléchargée et convertie en JPEG : /Users/frederic/tinder-bot/profile_image_bumble.jpg
L'image est enregistrée à l'emplacement : /Users/frederic/tinder-bot/profile_image_bumble.jpg

2024-05-21 12:11:00,645 - ERROR - 
2024-05-21 12:11:00,645 - INFO - Running evaluation_bumble.py...
2024-05-21 12:11:00,645 - INFO - Running script: /Users/frederic/tinder-bot/evaluation_bumble.py with args: []
2024-05-21 12:11:05,150 - INFO - Evaluating image at: /Users/frederic/tinder-bot/profile_image_bumble.jpg
Detection result: {'request_id': '1716304262,1af0f199-61b8-43c9-9e47-bc216c40df1c', 'time_used': 168, 'faces': [{'face_token': '8cc7f93b87df3ab64db037afe036bda3', 'face_rectangle': {'top': 442, 'left': 452, 'width': 170, 'height': 170}, 'attributes': {'facequality': {'value': 68.046, 'threshold': 70.1}}}], 'image_id': 'HV+gKXjFofkwimpK/UTo3g==', 'face_num': 1}
Analyze result: {'time_used': 99, 'request_id': '1716304265,b7f8f8ea-03ca-4ee7-bfbe-b48ec5bdf7cc', 'faces': [{'attributes': {'gender': {'value': 'Female'}, 'age': {'value': 20}, 'beauty': {'female_score': 70.352, 'male_score': 69.036}}, 'face_rectangle': {'width': 170, 'top': 442, 'left': 452, 'height': 170}, 'face_token': '8cc7f93b87df3ab64db037afe036bda3'}]}
Image: Belle (Female Score: 70.352, Male Score: 69.036)

2024-05-21 12:11:05,150 - ERROR - 
2024-05-21 12:11:05,150 - INFO - Evaluation result: is_beautiful=True
2024-05-21 12:11:05,150 - INFO - Running navigate_bumble.py with is_beautiful=True...
2024-05-21 12:11:05,150 - INFO - Running script: /Users/frederic/tinder-bot/navigate_bumble.py with args: ['true']
2024-05-21 12:11:05,553 - INFO - 
2024-05-21 12:11:05,553 - ERROR - 2024-05-21 12:11:05,236 - INFO - is_beautiful: True
2024-05-21 12:11:05,237 - INFO - Loading session...
2024-05-21 12:11:05,237 - INFO - Restoring session: 21e9521c4ab550bcf067ca9b1c334625, http://localhost:60305
--- Logging error ---
Traceback (most recent call last):
  File "/Users/frederic/tinder-bot/navigate_bumble.py", line 38, in navigate
    match_button = WebDriverWait(driver, 5).until(
                   ^^^^^^^^^^^^^^^^^^^^^^^^^^^^^^^
  File "/opt/homebrew/lib/python3.11/site-packages/selenium/webdriver/support/wait.py", line 96, in until
    value = method(self._driver)
            ^^^^^^^^^^^^^^^^^^^^
  File "/opt/homebrew/lib/python3.11/site-packages/selenium/webdriver/support/expected_conditions.py", line 84, in _predicate
    return driver.find_element(*locator)
           ^^^^^^^^^^^^^^^^^^^^^^^^^^^^^
  File "/opt/homebrew/lib/python3.11/site-packages/selenium/webdriver/remote/webdriver.py", line 741, in find_element
    return self.execute(Command.FIND_ELEMENT, {"using": by, "value": value})["value"]
           ^^^^^^^^^^^^^^^^^^^^^^^^^^^^^^^^^^^^^^^^^^^^^^^^^^^^^^^^^^^^^^^^^
  File "/opt/homebrew/lib/python3.11/site-packages/selenium/webdriver/remote/webdriver.py", line 347, in execute
    self.error_handler.check_response(response)
  File "/opt/homebrew/lib/python3.11/site-packages/selenium/webdriver/remote/errorhandler.py", line 229, in check_response
    raise exception_class(message, screen, stacktrace)
selenium.common.exceptions.JavascriptException: Message: javascript error: {"status":32,"value":"Unable to locate an element with the xpath expression //span[text()='Voir d'autres profils'] because of the following error:\nSyntaxError: Failed to execute 'evaluate' on 'Document': The string '//span[text()='Voir d'autres profils']' is not a valid XPath expression."}
  (Session info: chrome=125.0.6422.61)
Stacktrace:
0   chromedriver                        0x0000000102e0e4a0 chromedriver + 4301984
1   chromedriver                        0x0000000102e06de8 chromedriver + 4271592
2   chromedriver                        0x0000000102a3819c chromedriver + 278940
3   chromedriver                        0x0000000102a3c66c chromedriver + 296556
4   chromedriver                        0x0000000102a3e4e8 chromedriver + 304360
5   chromedriver                        0x0000000102a3e560 chromedriver + 304480
6   chromedriver                        0x0000000102a7a3c0 chromedriver + 549824
7   chromedriver                        0x0000000102ab2c5c chromedriver + 781404
8   chromedriver                        0x0000000102a6f004 chromedriver + 503812
9   chromedriver                        0x0000000102a6f9ec chromedriver + 506348
10  chromedriver                        0x0000000102dd64e8 chromedriver + 4072680
11  chromedriver                        0x0000000102ddaf94 chromedriver + 4091796
12  chromedriver                        0x0000000102dbd72c chromedriver + 3970860
13  chromedriver                        0x0000000102ddb87c chromedriver + 4094076
14  chromedriver                        0x0000000102db06ac chromedriver + 3917484
15  chromedriver                        0x0000000102df8ae0 chromedriver + 4213472
16  chromedriver                        0x0000000102df8c5c chromedriver + 4213852
17  chromedriver                        0x0000000102e069e0 chromedriver + 4270560
18  libsystem_pthread.dylib             0x00000001992aaf94 _pthread_start + 136
19  libsystem_pthread.dylib             0x00000001992a5d34 thread_start + 8


During handling of the above exception, another exception occurred:

Traceback (most recent call last):
  File "/opt/homebrew/Cellar/python@3.11/3.11.7/Frameworks/Python.framework/Versions/3.11/lib/python3.11/logging/__init__.py", line 1110, in emit
    msg = self.format(record)
          ^^^^^^^^^^^^^^^^^^^
  File "/opt/homebrew/Cellar/python@3.11/3.11.7/Frameworks/Python.framework/Versions/3.11/lib/python3.11/logging/__init__.py", line 953, in format
    return fmt.format(record)
           ^^^^^^^^^^^^^^^^^^
  File "/opt/homebrew/Cellar/python@3.11/3.11.7/Frameworks/Python.framework/Versions/3.11/lib/python3.11/logging/__init__.py", line 687, in format
    record.message = record.getMessage()
                     ^^^^^^^^^^^^^^^^^^^
  File "/opt/homebrew/Cellar/python@3.11/3.11.7/Frameworks/Python.framework/Versions/3.11/lib/python3.11/logging/__init__.py", line 377, in getMessage
    msg = msg % self.args
          ~~~~^~~~~~~~~~~
TypeError: not all arguments converted during string formatting
Call stack:
  File "/Users/frederic/tinder-bot/navigate_bumble.py", line 74, in <module>
    navigate(driver, is_beautiful)
  File "/Users/frederic/tinder-bot/navigate_bumble.py", line 45, in navigate
    logger.info("No match found or error occurred: ", e)
Message: 'No match found or error occurred: '
Arguments: (JavascriptException(),)
2024-05-21 12:11:05,541 - INFO - Pressed Right Arrow Key.

2024-05-21 12:11:05,770 - INFO - Running extract_image_bumble.py...
2024-05-21 12:11:05,770 - INFO - Running script: /Users/frederic/tinder-bot/extract_image_bumble.py with args: []
2024-05-21 12:11:06,354 - INFO - Loading session...
Restoring session: 21e9521c4ab550bcf067ca9b1c334625, http://localhost:60305
Waiting for image element...
Image element found.
Image URL: https://us1.ecdn2.bumbcdn.com/p541/hidden?euri=AAAAAAAAAAIQa96sNqx27Utsccm1rNIlGABTrMHNcAMl-IbbPWINtHIiXA4tUD.EaXnso9-QF16.J7ZTjNyLInDEqvGI5oDZ2886ygzc4qSaaun7gDb43dd1nqE3VmtT-nT6LIO6AvqjVAOl.TTBqy-6H9dVq-769gFf4nkok33RfFVZ.5uiLOK1Sa0l3AkKJlMJxlj-NdRqPHsoGYvZpLB9pt1dY7ut&size=__size__&ck=5cb7267f3712a1752965f6d19f53f0d9&wm_size=72x72&wm_offs=973x1124&h=aKL&gs=j&t=42.1.0.0
Image téléchargée et convertie en JPEG : /Users/frederic/tinder-bot/profile_image_bumble.jpg
L'image est enregistrée à l'emplacement : /Users/frederic/tinder-bot/profile_image_bumble.jpg

2024-05-21 12:11:06,354 - ERROR - 
2024-05-21 12:11:06,354 - INFO - Running evaluation_bumble.py...
2024-05-21 12:11:06,354 - INFO - Running script: /Users/frederic/tinder-bot/evaluation_bumble.py with args: []
2024-05-21 12:11:10,631 - INFO - Evaluating image at: /Users/frederic/tinder-bot/profile_image_bumble.jpg
Detection result: {'request_id': '1716304267,2e7271dd-18dc-48a9-818f-e1b7799e555d', 'time_used': 116, 'faces': [{'face_token': 'dc3639aa7c721d096ab1ed363482257d', 'face_rectangle': {'top': 145, 'left': 539, 'width': 123, 'height': 123}, 'attributes': {'facequality': {'value': 74.756, 'threshold': 70.1}}}], 'image_id': '/VLZWw5+Nd8J8oyawbP57w==', 'face_num': 1}
Analyze result: {'time_used': 95, 'request_id': '1716304270,d8190de6-6a32-4de3-9c2f-39a65cf257f8', 'faces': [{'attributes': {'gender': {'value': 'Female'}, 'age': {'value': 23}, 'beauty': {'female_score': 38.71, 'male_score': 35.057}}, 'face_rectangle': {'width': 123, 'top': 145, 'left': 539, 'height': 123}, 'face_token': 'dc3639aa7c721d096ab1ed363482257d'}]}
Image: Pas Belle (Female Score: 38.71, Male Score: 35.057)

2024-05-21 12:11:10,631 - ERROR - 
2024-05-21 12:11:10,631 - INFO - Evaluation result: is_beautiful=False
2024-05-21 12:11:10,631 - INFO - Running navigate_bumble.py with is_beautiful=False...
2024-05-21 12:11:10,631 - INFO - Running script: /Users/frederic/tinder-bot/navigate_bumble.py with args: ['false']
2024-05-21 12:11:10,943 - INFO - 
2024-05-21 12:11:10,943 - ERROR - 2024-05-21 12:11:10,711 - INFO - is_beautiful: False
2024-05-21 12:11:10,711 - INFO - Loading session...
2024-05-21 12:11:10,711 - INFO - Restoring session: 21e9521c4ab550bcf067ca9b1c334625, http://localhost:60305
--- Logging error ---
Traceback (most recent call last):
  File "/Users/frederic/tinder-bot/navigate_bumble.py", line 38, in navigate
    match_button = WebDriverWait(driver, 5).until(
                   ^^^^^^^^^^^^^^^^^^^^^^^^^^^^^^^
  File "/opt/homebrew/lib/python3.11/site-packages/selenium/webdriver/support/wait.py", line 96, in until
    value = method(self._driver)
            ^^^^^^^^^^^^^^^^^^^^
  File "/opt/homebrew/lib/python3.11/site-packages/selenium/webdriver/support/expected_conditions.py", line 84, in _predicate
    return driver.find_element(*locator)
           ^^^^^^^^^^^^^^^^^^^^^^^^^^^^^
  File "/opt/homebrew/lib/python3.11/site-packages/selenium/webdriver/remote/webdriver.py", line 741, in find_element
    return self.execute(Command.FIND_ELEMENT, {"using": by, "value": value})["value"]
           ^^^^^^^^^^^^^^^^^^^^^^^^^^^^^^^^^^^^^^^^^^^^^^^^^^^^^^^^^^^^^^^^^
  File "/opt/homebrew/lib/python3.11/site-packages/selenium/webdriver/remote/webdriver.py", line 347, in execute
    self.error_handler.check_response(response)
  File "/opt/homebrew/lib/python3.11/site-packages/selenium/webdriver/remote/errorhandler.py", line 229, in check_response
    raise exception_class(message, screen, stacktrace)
selenium.common.exceptions.JavascriptException: Message: javascript error: {"status":32,"value":"Unable to locate an element with the xpath expression //span[text()='Voir d'autres profils'] because of the following error:\nSyntaxError: Failed to execute 'evaluate' on 'Document': The string '//span[text()='Voir d'autres profils']' is not a valid XPath expression."}
  (Session info: chrome=125.0.6422.61)
Stacktrace:
0   chromedriver                        0x0000000102e0e4a0 chromedriver + 4301984
1   chromedriver                        0x0000000102e06de8 chromedriver + 4271592
2   chromedriver                        0x0000000102a3819c chromedriver + 278940
3   chromedriver                        0x0000000102a3c66c chromedriver + 296556
4   chromedriver                        0x0000000102a3e4e8 chromedriver + 304360
5   chromedriver                        0x0000000102a3e560 chromedriver + 304480
6   chromedriver                        0x0000000102a7a3c0 chromedriver + 549824
7   chromedriver                        0x0000000102ab2c5c chromedriver + 781404
8   chromedriver                        0x0000000102a6f004 chromedriver + 503812
9   chromedriver                        0x0000000102a6f9ec chromedriver + 506348
10  chromedriver                        0x0000000102dd64e8 chromedriver + 4072680
11  chromedriver                        0x0000000102ddaf94 chromedriver + 4091796
12  chromedriver                        0x0000000102dbd72c chromedriver + 3970860
13  chromedriver                        0x0000000102ddb87c chromedriver + 4094076
14  chromedriver                        0x0000000102db06ac chromedriver + 3917484
15  chromedriver                        0x0000000102df8ae0 chromedriver + 4213472
16  chromedriver                        0x0000000102df8c5c chromedriver + 4213852
17  chromedriver                        0x0000000102e069e0 chromedriver + 4270560
18  libsystem_pthread.dylib             0x00000001992aaf94 _pthread_start + 136
19  libsystem_pthread.dylib             0x00000001992a5d34 thread_start + 8


During handling of the above exception, another exception occurred:

Traceback (most recent call last):
  File "/opt/homebrew/Cellar/python@3.11/3.11.7/Frameworks/Python.framework/Versions/3.11/lib/python3.11/logging/__init__.py", line 1110, in emit
    msg = self.format(record)
          ^^^^^^^^^^^^^^^^^^^
  File "/opt/homebrew/Cellar/python@3.11/3.11.7/Frameworks/Python.framework/Versions/3.11/lib/python3.11/logging/__init__.py", line 953, in format
    return fmt.format(record)
           ^^^^^^^^^^^^^^^^^^
  File "/opt/homebrew/Cellar/python@3.11/3.11.7/Frameworks/Python.framework/Versions/3.11/lib/python3.11/logging/__init__.py", line 687, in format
    record.message = record.getMessage()
                     ^^^^^^^^^^^^^^^^^^^
  File "/opt/homebrew/Cellar/python@3.11/3.11.7/Frameworks/Python.framework/Versions/3.11/lib/python3.11/logging/__init__.py", line 377, in getMessage
    msg = msg % self.args
          ~~~~^~~~~~~~~~~
TypeError: not all arguments converted during string formatting
Call stack:
  File "/Users/frederic/tinder-bot/navigate_bumble.py", line 74, in <module>
    navigate(driver, is_beautiful)
  File "/Users/frederic/tinder-bot/navigate_bumble.py", line 45, in navigate
    logger.info("No match found or error occurred: ", e)
Message: 'No match found or error occurred: '
Arguments: (JavascriptException(),)
2024-05-21 12:11:10,925 - INFO - Pressed Left Arrow Key.

2024-05-21 12:11:11,161 - INFO - Running extract_image_bumble.py...
2024-05-21 12:11:11,161 - INFO - Running script: /Users/frederic/tinder-bot/extract_image_bumble.py with args: []
2024-05-21 12:11:11,619 - INFO - Loading session...
Restoring session: 21e9521c4ab550bcf067ca9b1c334625, http://localhost:60305
Waiting for image element...
Image element found.
Image URL: https://us1.ecdn2.bumbcdn.com/p514/hidden?euri=AAAAAAAAAAIQdUS.Pex9AG7jjDYDBoqhsAAHCF904yAOie-tUWxotlgLTiWJbMNXgg21QGX2w5z3Jr3UEZXFhozX8y8xKoaXLaQi9gn.AWp2p3VgdIOgZOVrgDNjijcRRJpa67EjX675BVSWc1nxgoBbbln-5hiNwnGNXlNYegLDnnEvoHiWY-PV1yGzbm.k..C38U0uDhBpFUwvUUQvHABbRgzrJjju&size=__size__&ck=0e7c2ccc756e43498217fb560aeacc63&wm_size=72x72&wm_offs=781x1066&h=MHG&gs=j&t=42.1.0.0
Image téléchargée et convertie en JPEG : /Users/frederic/tinder-bot/profile_image_bumble.jpg
L'image est enregistrée à l'emplacement : /Users/frederic/tinder-bot/profile_image_bumble.jpg

2024-05-21 12:11:11,619 - ERROR - 
2024-05-21 12:11:11,619 - INFO - Running evaluation_bumble.py...
2024-05-21 12:11:11,619 - INFO - Running script: /Users/frederic/tinder-bot/evaluation_bumble.py with args: []
2024-05-21 12:11:15,716 - INFO - Evaluating image at: /Users/frederic/tinder-bot/profile_image_bumble.jpg
Detection result: {'request_id': '1716304273,d5dc6ef5-02d7-412c-9655-7c69fe7c9960', 'time_used': 86, 'faces': [{'face_token': '9668e73d51d35fb49bdee3c7f04876ec', 'face_rectangle': {'top': 182, 'left': 341, 'width': 155, 'height': 155}, 'attributes': {'facequality': {'value': 88.801, 'threshold': 70.1}}}], 'image_id': '/0PRSPwZkl+uUrUcezRxEw==', 'face_num': 1}
Analyze result: {'time_used': 97, 'request_id': '1716304275,a7a62555-8bcd-45f7-9b2a-08e3d86fb502', 'faces': [{'attributes': {'gender': {'value': 'Female'}, 'age': {'value': 41}, 'beauty': {'female_score': 45.074, 'male_score': 48.63}}, 'face_rectangle': {'width': 155, 'top': 182, 'left': 341, 'height': 155}, 'face_token': '9668e73d51d35fb49bdee3c7f04876ec'}]}
Image: Pas Belle (Female Score: 45.074, Male Score: 48.63)

2024-05-21 12:11:15,716 - ERROR - 
2024-05-21 12:11:15,716 - INFO - Evaluation result: is_beautiful=False
2024-05-21 12:11:15,716 - INFO - Running navigate_bumble.py with is_beautiful=False...
2024-05-21 12:11:15,716 - INFO - Running script: /Users/frederic/tinder-bot/navigate_bumble.py with args: ['false']
2024-05-21 12:11:16,235 - INFO - 
2024-05-21 12:11:16,236 - ERROR - 2024-05-21 12:11:15,795 - INFO - is_beautiful: False
2024-05-21 12:11:15,795 - INFO - Loading session...
2024-05-21 12:11:15,795 - INFO - Restoring session: 21e9521c4ab550bcf067ca9b1c334625, http://localhost:60305
--- Logging error ---
Traceback (most recent call last):
  File "/Users/frederic/tinder-bot/navigate_bumble.py", line 38, in navigate
    match_button = WebDriverWait(driver, 5).until(
                   ^^^^^^^^^^^^^^^^^^^^^^^^^^^^^^^
  File "/opt/homebrew/lib/python3.11/site-packages/selenium/webdriver/support/wait.py", line 96, in until
    value = method(self._driver)
            ^^^^^^^^^^^^^^^^^^^^
  File "/opt/homebrew/lib/python3.11/site-packages/selenium/webdriver/support/expected_conditions.py", line 84, in _predicate
    return driver.find_element(*locator)
           ^^^^^^^^^^^^^^^^^^^^^^^^^^^^^
  File "/opt/homebrew/lib/python3.11/site-packages/selenium/webdriver/remote/webdriver.py", line 741, in find_element
    return self.execute(Command.FIND_ELEMENT, {"using": by, "value": value})["value"]
           ^^^^^^^^^^^^^^^^^^^^^^^^^^^^^^^^^^^^^^^^^^^^^^^^^^^^^^^^^^^^^^^^^
  File "/opt/homebrew/lib/python3.11/site-packages/selenium/webdriver/remote/webdriver.py", line 347, in execute
    self.error_handler.check_response(response)
  File "/opt/homebrew/lib/python3.11/site-packages/selenium/webdriver/remote/errorhandler.py", line 229, in check_response
    raise exception_class(message, screen, stacktrace)
selenium.common.exceptions.JavascriptException: Message: javascript error: {"status":32,"value":"Unable to locate an element with the xpath expression //span[text()='Voir d'autres profils'] because of the following error:\nSyntaxError: Failed to execute 'evaluate' on 'Document': The string '//span[text()='Voir d'autres profils']' is not a valid XPath expression."}
  (Session info: chrome=125.0.6422.61)
Stacktrace:
0   chromedriver                        0x0000000102e0e4a0 chromedriver + 4301984
1   chromedriver                        0x0000000102e06de8 chromedriver + 4271592
2   chromedriver                        0x0000000102a3819c chromedriver + 278940
3   chromedriver                        0x0000000102a3c66c chromedriver + 296556
4   chromedriver                        0x0000000102a3e4e8 chromedriver + 304360
5   chromedriver                        0x0000000102a3e560 chromedriver + 304480
6   chromedriver                        0x0000000102a7a3c0 chromedriver + 549824
7   chromedriver                        0x0000000102ab2c5c chromedriver + 781404
8   chromedriver                        0x0000000102a6f004 chromedriver + 503812
9   chromedriver                        0x0000000102a6f9ec chromedriver + 506348
10  chromedriver                        0x0000000102dd64e8 chromedriver + 4072680
11  chromedriver                        0x0000000102ddaf94 chromedriver + 4091796
12  chromedriver                        0x0000000102dbd72c chromedriver + 3970860
13  chromedriver                        0x0000000102ddb87c chromedriver + 4094076
14  chromedriver                        0x0000000102db06ac chromedriver + 3917484
15  chromedriver                        0x0000000102df8ae0 chromedriver + 4213472
16  chromedriver                        0x0000000102df8c5c chromedriver + 4213852
17  chromedriver                        0x0000000102e069e0 chromedriver + 4270560
18  libsystem_pthread.dylib             0x00000001992aaf94 _pthread_start + 136
19  libsystem_pthread.dylib             0x00000001992a5d34 thread_start + 8


During handling of the above exception, another exception occurred:

Traceback (most recent call last):
  File "/opt/homebrew/Cellar/python@3.11/3.11.7/Frameworks/Python.framework/Versions/3.11/lib/python3.11/logging/__init__.py", line 1110, in emit
    msg = self.format(record)
          ^^^^^^^^^^^^^^^^^^^
  File "/opt/homebrew/Cellar/python@3.11/3.11.7/Frameworks/Python.framework/Versions/3.11/lib/python3.11/logging/__init__.py", line 953, in format
    return fmt.format(record)
           ^^^^^^^^^^^^^^^^^^
  File "/opt/homebrew/Cellar/python@3.11/3.11.7/Frameworks/Python.framework/Versions/3.11/lib/python3.11/logging/__init__.py", line 687, in format
    record.message = record.getMessage()
                     ^^^^^^^^^^^^^^^^^^^
  File "/opt/homebrew/Cellar/python@3.11/3.11.7/Frameworks/Python.framework/Versions/3.11/lib/python3.11/logging/__init__.py", line 377, in getMessage
    msg = msg % self.args
          ~~~~^~~~~~~~~~~
TypeError: not all arguments converted during string formatting
Call stack:
  File "/Users/frederic/tinder-bot/navigate_bumble.py", line 74, in <module>
    navigate(driver, is_beautiful)
  File "/Users/frederic/tinder-bot/navigate_bumble.py", line 45, in navigate
    logger.info("No match found or error occurred: ", e)
Message: 'No match found or error occurred: '
Arguments: (JavascriptException(),)
2024-05-21 12:11:16,225 - INFO - Pressed Left Arrow Key.

2024-05-21 12:11:16,520 - INFO - Running extract_image_bumble.py...
2024-05-21 12:11:16,520 - INFO - Running script: /Users/frederic/tinder-bot/extract_image_bumble.py with args: []
2024-05-21 12:11:17,213 - INFO - Loading session...
Restoring session: 21e9521c4ab550bcf067ca9b1c334625, http://localhost:60305
Waiting for image element...
Image element found.
Image URL: https://us1.ecdn2.bumbcdn.com/p509/hidden?euri=AAAAAAAAAAIQ3701sGoh9LpKvOyLygo5NAC0myVuUQAwmCxNiO5aB-ZiVUHiRIurwpAKfv2La6A9EsUJ9rPzk82ReF5U.FFePXZGPdoh..eBRLUnM5iXQhAF3ZhNhVbIRv3d3E0MRKAWZT6R1lQ7QDc4Gh.2RRtNF1CtrxTGl79QBnXP64kh1i.32WY.WdLKosthYx9UvbVSRyO7Qhrt0zCIsxfKZEo-&size=__size__&ck=263ccf7962df86bcb15541d71f27f516&wm_size=72x72&wm_offs=973x1125&h=kvk&gs=j&t=42.1.0.0
Image téléchargée et convertie en JPEG : /Users/frederic/tinder-bot/profile_image_bumble.jpg
L'image est enregistrée à l'emplacement : /Users/frederic/tinder-bot/profile_image_bumble.jpg

2024-05-21 12:11:17,213 - ERROR - 
2024-05-21 12:11:17,213 - INFO - Running evaluation_bumble.py...
2024-05-21 12:11:17,213 - INFO - Running script: /Users/frederic/tinder-bot/evaluation_bumble.py with args: []
2024-05-21 12:11:21,335 - INFO - Evaluating image at: /Users/frederic/tinder-bot/profile_image_bumble.jpg
Detection result: {'request_id': '1716304278,b3496c2b-d545-4895-9f81-c055b1bea15e', 'time_used': 166, 'faces': [{'face_token': '609c31b7772968934656734f781ef23a', 'face_rectangle': {'top': 208, 'left': 362, 'width': 318, 'height': 318}, 'attributes': {'facequality': {'value': 54.826, 'threshold': 70.1}}}], 'image_id': 'HJeuLSQ7Wp77/Zz8DLzlnw==', 'face_num': 1}
Analyze result: {'time_used': 98, 'request_id': '1716304281,b31b37de-025f-4301-bffc-57f82bb0f944', 'faces': [{'attributes': {'gender': {'value': 'Female'}, 'age': {'value': 51}, 'beauty': {'female_score': 34.315, 'male_score': 36.842}}, 'face_rectangle': {'width': 318, 'top': 208, 'left': 362, 'height': 318}, 'face_token': '609c31b7772968934656734f781ef23a'}]}
Image: Pas Belle (Female Score: 34.315, Male Score: 36.842)

2024-05-21 12:11:21,336 - ERROR - 
2024-05-21 12:11:21,336 - INFO - Evaluation result: is_beautiful=False
2024-05-21 12:11:21,336 - INFO - Running navigate_bumble.py with is_beautiful=False...
2024-05-21 12:11:21,336 - INFO - Running script: /Users/frederic/tinder-bot/navigate_bumble.py with args: ['false']
2024-05-21 12:11:21,846 - INFO - 
2024-05-21 12:11:21,846 - ERROR - 2024-05-21 12:11:21,415 - INFO - is_beautiful: False
2024-05-21 12:11:21,416 - INFO - Loading session...
2024-05-21 12:11:21,416 - INFO - Restoring session: 21e9521c4ab550bcf067ca9b1c334625, http://localhost:60305
--- Logging error ---
Traceback (most recent call last):
  File "/Users/frederic/tinder-bot/navigate_bumble.py", line 38, in navigate
    match_button = WebDriverWait(driver, 5).until(
                   ^^^^^^^^^^^^^^^^^^^^^^^^^^^^^^^
  File "/opt/homebrew/lib/python3.11/site-packages/selenium/webdriver/support/wait.py", line 96, in until
    value = method(self._driver)
            ^^^^^^^^^^^^^^^^^^^^
  File "/opt/homebrew/lib/python3.11/site-packages/selenium/webdriver/support/expected_conditions.py", line 84, in _predicate
    return driver.find_element(*locator)
           ^^^^^^^^^^^^^^^^^^^^^^^^^^^^^
  File "/opt/homebrew/lib/python3.11/site-packages/selenium/webdriver/remote/webdriver.py", line 741, in find_element
    return self.execute(Command.FIND_ELEMENT, {"using": by, "value": value})["value"]
           ^^^^^^^^^^^^^^^^^^^^^^^^^^^^^^^^^^^^^^^^^^^^^^^^^^^^^^^^^^^^^^^^^
  File "/opt/homebrew/lib/python3.11/site-packages/selenium/webdriver/remote/webdriver.py", line 347, in execute
    self.error_handler.check_response(response)
  File "/opt/homebrew/lib/python3.11/site-packages/selenium/webdriver/remote/errorhandler.py", line 229, in check_response
    raise exception_class(message, screen, stacktrace)
selenium.common.exceptions.JavascriptException: Message: javascript error: {"status":32,"value":"Unable to locate an element with the xpath expression //span[text()='Voir d'autres profils'] because of the following error:\nSyntaxError: Failed to execute 'evaluate' on 'Document': The string '//span[text()='Voir d'autres profils']' is not a valid XPath expression."}
  (Session info: chrome=125.0.6422.61)
Stacktrace:
0   chromedriver                        0x0000000102e0e4a0 chromedriver + 4301984
1   chromedriver                        0x0000000102e06de8 chromedriver + 4271592
2   chromedriver                        0x0000000102a3819c chromedriver + 278940
3   chromedriver                        0x0000000102a3c66c chromedriver + 296556
4   chromedriver                        0x0000000102a3e4e8 chromedriver + 304360
5   chromedriver                        0x0000000102a3e560 chromedriver + 304480
6   chromedriver                        0x0000000102a7a3c0 chromedriver + 549824
7   chromedriver                        0x0000000102ab2c5c chromedriver + 781404
8   chromedriver                        0x0000000102a6f004 chromedriver + 503812
9   chromedriver                        0x0000000102a6f9ec chromedriver + 506348
10  chromedriver                        0x0000000102dd64e8 chromedriver + 4072680
11  chromedriver                        0x0000000102ddaf94 chromedriver + 4091796
12  chromedriver                        0x0000000102dbd72c chromedriver + 3970860
13  chromedriver                        0x0000000102ddb87c chromedriver + 4094076
14  chromedriver                        0x0000000102db06ac chromedriver + 3917484
15  chromedriver                        0x0000000102df8ae0 chromedriver + 4213472
16  chromedriver                        0x0000000102df8c5c chromedriver + 4213852
17  chromedriver                        0x0000000102e069e0 chromedriver + 4270560
18  libsystem_pthread.dylib             0x00000001992aaf94 _pthread_start + 136
19  libsystem_pthread.dylib             0x00000001992a5d34 thread_start + 8


During handling of the above exception, another exception occurred:

Traceback (most recent call last):
  File "/opt/homebrew/Cellar/python@3.11/3.11.7/Frameworks/Python.framework/Versions/3.11/lib/python3.11/logging/__init__.py", line 1110, in emit
    msg = self.format(record)
          ^^^^^^^^^^^^^^^^^^^
  File "/opt/homebrew/Cellar/python@3.11/3.11.7/Frameworks/Python.framework/Versions/3.11/lib/python3.11/logging/__init__.py", line 953, in format
    return fmt.format(record)
           ^^^^^^^^^^^^^^^^^^
  File "/opt/homebrew/Cellar/python@3.11/3.11.7/Frameworks/Python.framework/Versions/3.11/lib/python3.11/logging/__init__.py", line 687, in format
    record.message = record.getMessage()
                     ^^^^^^^^^^^^^^^^^^^
  File "/opt/homebrew/Cellar/python@3.11/3.11.7/Frameworks/Python.framework/Versions/3.11/lib/python3.11/logging/__init__.py", line 377, in getMessage
    msg = msg % self.args
          ~~~~^~~~~~~~~~~
TypeError: not all arguments converted during string formatting
Call stack:
  File "/Users/frederic/tinder-bot/navigate_bumble.py", line 74, in <module>
    navigate(driver, is_beautiful)
  File "/Users/frederic/tinder-bot/navigate_bumble.py", line 45, in navigate
    logger.info("No match found or error occurred: ", e)
Message: 'No match found or error occurred: '
Arguments: (JavascriptException(),)
2024-05-21 12:11:21,835 - INFO - Pressed Left Arrow Key.

2024-05-21 12:11:22,067 - INFO - Running extract_image_bumble.py...
2024-05-21 12:11:22,067 - INFO - Running script: /Users/frederic/tinder-bot/extract_image_bumble.py with args: []
2024-05-21 12:11:22,579 - INFO - Loading session...
Restoring session: 21e9521c4ab550bcf067ca9b1c334625, http://localhost:60305
Waiting for image element...
Image element found.
Image URL: https://us1.ecdn2.bumbcdn.com/p542/hidden?euri=AAAAAAAAAAIQzmwWgyJsrdozant-9A440AB1SipzOVITzFFLXEErHZXzcW7RbJqXn.Sfk2xGZoYlAdQxtYJ27VcHxF-Qw4A0ay3tj415bQbWlCgyCaXiX.UvhHL7r9nuFcoCU49LA70Ea24RFVrqmaUQ3EI37PuNOGEH577v.KuhX7ZR978AoBVQVGTYdWvXxXY2QG6dUGd5ePgrnN12dybqVP2EZh2F&size=__size__&ck=929717872123b81d3a23a5cb25263c2c&wm_size=72x72&wm_offs=922x1253&h=Q-c&gs=j&t=42.1.0.0
Image téléchargée et convertie en JPEG : /Users/frederic/tinder-bot/profile_image_bumble.jpg
L'image est enregistrée à l'emplacement : /Users/frederic/tinder-bot/profile_image_bumble.jpg

2024-05-21 12:11:22,579 - ERROR - 
2024-05-21 12:11:22,579 - INFO - Running evaluation_bumble.py...
2024-05-21 12:11:22,579 - INFO - Running script: /Users/frederic/tinder-bot/evaluation_bumble.py with args: []
2024-05-21 12:11:27,060 - INFO - Evaluating image at: /Users/frederic/tinder-bot/profile_image_bumble.jpg
Detection result: {'request_id': '1716304284,6596ca42-e2db-476b-b265-e61c52ae9c9c', 'time_used': 139, 'faces': [{'face_token': 'bc2e2edcd17b4495f4efb03190a56bcd', 'face_rectangle': {'top': 583, 'left': 607, 'width': 58, 'height': 58}, 'attributes': {'facequality': {'value': 0.006, 'threshold': 70.1}}}, {'face_token': 'edbbef9cf77c9c90121a3503f4959f54', 'face_rectangle': {'top': 556, 'left': 674, 'width': 57, 'height': 57}, 'attributes': {'facequality': {'value': 0.006, 'threshold': 70.1}}}, {'face_token': '5727a4c8491b58c65ba2facde0ed7c21', 'face_rectangle': {'top': 579, 'left': 238, 'width': 48, 'height': 48}, 'attributes': {'facequality': {'value': 0.006, 'threshold': 70.1}}}, {'face_token': '3d20ee1bbf1ba399dca060a9ead99e91', 'face_rectangle': {'top': 690, 'left': 471, 'width': 39, 'height': 39}, 'attributes': {'facequality': {'value': 0.006, 'threshold': 70.1}}}, {'face_token': '5102fbb68a9c2221fe29bf8895dc353b', 'face_rectangle': {'top': 717, 'left': 897, 'width': 36, 'height': 36}, 'attributes': {'facequality': {'value': 0.006, 'threshold': 70.1}}}], 'image_id': 'R76ZoCVoI2XKtY9Tyr3pwQ==', 'face_num': 5}
Analyze result: {'time_used': 296, 'request_id': '1716304286,40094e95-e932-491b-95db-b6dd9c5287d0', 'faces': [{'attributes': {'gender': {'value': 'Male'}, 'age': {'value': 62}, 'beauty': {'female_score': 46.839, 'male_score': 49.562}}, 'face_rectangle': {'width': 58, 'top': 583, 'left': 607, 'height': 58}, 'face_token': 'bc2e2edcd17b4495f4efb03190a56bcd'}, {'attributes': {'gender': {'value': 'Male'}, 'age': {'value': 52}, 'beauty': {'female_score': 50.513, 'male_score': 54.759}}, 'face_rectangle': {'width': 57, 'top': 556, 'left': 674, 'height': 57}, 'face_token': 'edbbef9cf77c9c90121a3503f4959f54'}, {'attributes': {'gender': {'value': 'Male'}, 'age': {'value': 27}, 'beauty': {'female_score': 52.482, 'male_score': 44.548}}, 'face_rectangle': {'width': 48, 'top': 579, 'left': 238, 'height': 48}, 'face_token': '5727a4c8491b58c65ba2facde0ed7c21'}, {'attributes': {'gender': {'value': 'Male'}, 'age': {'value': 41}, 'beauty': {'female_score': 53.838, 'male_score': 56.939}}, 'face_rectangle': {'width': 39, 'top': 690, 'left': 471, 'height': 39}, 'face_token': '3d20ee1bbf1ba399dca060a9ead99e91'}, {'attributes': {'gender': {'value': 'Male'}, 'age': {'value': 44}, 'beauty': {'female_score': 54.878, 'male_score': 57.055}}, 'face_rectangle': {'width': 36, 'top': 717, 'left': 897, 'height': 36}, 'face_token': '5102fbb68a9c2221fe29bf8895dc353b'}]}
Image: Pas Belle (Female Score: 46.839, Male Score: 49.562)

2024-05-21 12:11:27,061 - ERROR - 
2024-05-21 12:11:27,061 - INFO - Evaluation result: is_beautiful=False
2024-05-21 12:11:27,061 - INFO - Running navigate_bumble.py with is_beautiful=False...
2024-05-21 12:11:27,061 - INFO - Running script: /Users/frederic/tinder-bot/navigate_bumble.py with args: ['false']
2024-05-21 12:11:27,485 - INFO - 
2024-05-21 12:11:27,485 - ERROR - 2024-05-21 12:11:27,141 - INFO - is_beautiful: False
2024-05-21 12:11:27,141 - INFO - Loading session...
2024-05-21 12:11:27,141 - INFO - Restoring session: 21e9521c4ab550bcf067ca9b1c334625, http://localhost:60305
--- Logging error ---
Traceback (most recent call last):
  File "/Users/frederic/tinder-bot/navigate_bumble.py", line 38, in navigate
    match_button = WebDriverWait(driver, 5).until(
                   ^^^^^^^^^^^^^^^^^^^^^^^^^^^^^^^
  File "/opt/homebrew/lib/python3.11/site-packages/selenium/webdriver/support/wait.py", line 96, in until
    value = method(self._driver)
            ^^^^^^^^^^^^^^^^^^^^
  File "/opt/homebrew/lib/python3.11/site-packages/selenium/webdriver/support/expected_conditions.py", line 84, in _predicate
    return driver.find_element(*locator)
           ^^^^^^^^^^^^^^^^^^^^^^^^^^^^^
  File "/opt/homebrew/lib/python3.11/site-packages/selenium/webdriver/remote/webdriver.py", line 741, in find_element
    return self.execute(Command.FIND_ELEMENT, {"using": by, "value": value})["value"]
           ^^^^^^^^^^^^^^^^^^^^^^^^^^^^^^^^^^^^^^^^^^^^^^^^^^^^^^^^^^^^^^^^^
  File "/opt/homebrew/lib/python3.11/site-packages/selenium/webdriver/remote/webdriver.py", line 347, in execute
    self.error_handler.check_response(response)
  File "/opt/homebrew/lib/python3.11/site-packages/selenium/webdriver/remote/errorhandler.py", line 229, in check_response
    raise exception_class(message, screen, stacktrace)
selenium.common.exceptions.JavascriptException: Message: javascript error: {"status":32,"value":"Unable to locate an element with the xpath expression //span[text()='Voir d'autres profils'] because of the following error:\nSyntaxError: Failed to execute 'evaluate' on 'Document': The string '//span[text()='Voir d'autres profils']' is not a valid XPath expression."}
  (Session info: chrome=125.0.6422.61)
Stacktrace:
0   chromedriver                        0x0000000102e0e4a0 chromedriver + 4301984
1   chromedriver                        0x0000000102e06de8 chromedriver + 4271592
2   chromedriver                        0x0000000102a3819c chromedriver + 278940
3   chromedriver                        0x0000000102a3c66c chromedriver + 296556
4   chromedriver                        0x0000000102a3e4e8 chromedriver + 304360
5   chromedriver                        0x0000000102a3e560 chromedriver + 304480
6   chromedriver                        0x0000000102a7a3c0 chromedriver + 549824
7   chromedriver                        0x0000000102ab2c5c chromedriver + 781404
8   chromedriver                        0x0000000102a6f004 chromedriver + 503812
9   chromedriver                        0x0000000102a6f9ec chromedriver + 506348
10  chromedriver                        0x0000000102dd64e8 chromedriver + 4072680
11  chromedriver                        0x0000000102ddaf94 chromedriver + 4091796
12  chromedriver                        0x0000000102dbd72c chromedriver + 3970860
13  chromedriver                        0x0000000102ddb87c chromedriver + 4094076
14  chromedriver                        0x0000000102db06ac chromedriver + 3917484
15  chromedriver                        0x0000000102df8ae0 chromedriver + 4213472
16  chromedriver                        0x0000000102df8c5c chromedriver + 4213852
17  chromedriver                        0x0000000102e069e0 chromedriver + 4270560
18  libsystem_pthread.dylib             0x00000001992aaf94 _pthread_start + 136
19  libsystem_pthread.dylib             0x00000001992a5d34 thread_start + 8


During handling of the above exception, another exception occurred:

Traceback (most recent call last):
  File "/opt/homebrew/Cellar/python@3.11/3.11.7/Frameworks/Python.framework/Versions/3.11/lib/python3.11/logging/__init__.py", line 1110, in emit
    msg = self.format(record)
          ^^^^^^^^^^^^^^^^^^^
  File "/opt/homebrew/Cellar/python@3.11/3.11.7/Frameworks/Python.framework/Versions/3.11/lib/python3.11/logging/__init__.py", line 953, in format
    return fmt.format(record)
           ^^^^^^^^^^^^^^^^^^
  File "/opt/homebrew/Cellar/python@3.11/3.11.7/Frameworks/Python.framework/Versions/3.11/lib/python3.11/logging/__init__.py", line 687, in format
    record.message = record.getMessage()
                     ^^^^^^^^^^^^^^^^^^^
  File "/opt/homebrew/Cellar/python@3.11/3.11.7/Frameworks/Python.framework/Versions/3.11/lib/python3.11/logging/__init__.py", line 377, in getMessage
    msg = msg % self.args
          ~~~~^~~~~~~~~~~
TypeError: not all arguments converted during string formatting
Call stack:
  File "/Users/frederic/tinder-bot/navigate_bumble.py", line 74, in <module>
    navigate(driver, is_beautiful)
  File "/Users/frederic/tinder-bot/navigate_bumble.py", line 45, in navigate
    logger.info("No match found or error occurred: ", e)
Message: 'No match found or error occurred: '
Arguments: (JavascriptException(),)
2024-05-21 12:11:27,464 - INFO - Pressed Left Arrow Key.

2024-05-21 12:11:27,713 - INFO - Running extract_image_bumble.py...
2024-05-21 12:11:27,713 - INFO - Running script: /Users/frederic/tinder-bot/extract_image_bumble.py with args: []
2024-05-21 12:11:28,355 - INFO - Loading session...
Restoring session: 21e9521c4ab550bcf067ca9b1c334625, http://localhost:60305
Waiting for image element...
Image element found.
Image URL: https://us1.ecdn2.bumbcdn.com/p576/hidden?euri=AAAAAAAAAAIQythTyDPkUiq.ymlHS4tStAAYoCaHTw9q3bxMeukp7pR00xm2z8Ah.VEkt.PLNPJFsQtjXt-PiUIwMKSi4.351QXemV1Fob1yhjzDGdolc.Np7DxKtGNuhB25mO.ILvnkkvUFYOC.ouKq.89xUa9RODJRgOqdHLYV5iPxZH9rxO7wwYJqM7.zukI5Dar0m.75v4.-4s3pkue6bWI4Qj4Q&size=__size__&ck=6d56d1e17efb6597b318c439b4c66e6c&wm_size=72x72&wm_offs=973x1219&h=2VX&gs=j&t=42.1.0.0
Image téléchargée et convertie en JPEG : /Users/frederic/tinder-bot/profile_image_bumble.jpg
L'image est enregistrée à l'emplacement : /Users/frederic/tinder-bot/profile_image_bumble.jpg

2024-05-21 12:11:28,355 - ERROR - 
2024-05-21 12:11:28,355 - INFO - Running evaluation_bumble.py...
2024-05-21 12:11:28,355 - INFO - Running script: /Users/frederic/tinder-bot/evaluation_bumble.py with args: []
2024-05-21 12:11:32,652 - INFO - Evaluating image at: /Users/frederic/tinder-bot/profile_image_bumble.jpg
Detection result: {'request_id': '1716304289,614bbeab-b2c2-4d4e-90d8-30946ca266e2', 'time_used': 148, 'faces': [{'face_token': '7f33929310775d02a21016b0b045e89a', 'face_rectangle': {'top': 299, 'left': 603, 'width': 72, 'height': 72}, 'attributes': {'facequality': {'value': 0.006, 'threshold': 70.1}}}], 'image_id': '00CJse8h3AqNeoCkRsbe2w==', 'face_num': 1}
Analyze result: {'time_used': 113, 'request_id': '1716304292,26c57248-6c85-4d72-a7ad-6701ecb7a1d2', 'faces': [{'attributes': {'gender': {'value': 'Female'}, 'age': {'value': 29}, 'beauty': {'female_score': 69.71, 'male_score': 71.077}}, 'face_rectangle': {'width': 72, 'top': 299, 'left': 603, 'height': 72}, 'face_token': '7f33929310775d02a21016b0b045e89a'}]}
Image: Belle (Female Score: 69.71, Male Score: 71.077)

2024-05-21 12:11:32,653 - ERROR - 
2024-05-21 12:11:32,653 - INFO - Evaluation result: is_beautiful=True
2024-05-21 12:11:32,653 - INFO - Running navigate_bumble.py with is_beautiful=True...
2024-05-21 12:11:32,653 - INFO - Running script: /Users/frederic/tinder-bot/navigate_bumble.py with args: ['true']
2024-05-21 12:11:33,204 - INFO - 
2024-05-21 12:11:33,205 - ERROR - 2024-05-21 12:11:32,733 - INFO - is_beautiful: True
2024-05-21 12:11:32,733 - INFO - Loading session...
2024-05-21 12:11:32,733 - INFO - Restoring session: 21e9521c4ab550bcf067ca9b1c334625, http://localhost:60305
--- Logging error ---
Traceback (most recent call last):
  File "/Users/frederic/tinder-bot/navigate_bumble.py", line 38, in navigate
    match_button = WebDriverWait(driver, 5).until(
                   ^^^^^^^^^^^^^^^^^^^^^^^^^^^^^^^
  File "/opt/homebrew/lib/python3.11/site-packages/selenium/webdriver/support/wait.py", line 96, in until
    value = method(self._driver)
            ^^^^^^^^^^^^^^^^^^^^
  File "/opt/homebrew/lib/python3.11/site-packages/selenium/webdriver/support/expected_conditions.py", line 84, in _predicate
    return driver.find_element(*locator)
           ^^^^^^^^^^^^^^^^^^^^^^^^^^^^^
  File "/opt/homebrew/lib/python3.11/site-packages/selenium/webdriver/remote/webdriver.py", line 741, in find_element
    return self.execute(Command.FIND_ELEMENT, {"using": by, "value": value})["value"]
           ^^^^^^^^^^^^^^^^^^^^^^^^^^^^^^^^^^^^^^^^^^^^^^^^^^^^^^^^^^^^^^^^^
  File "/opt/homebrew/lib/python3.11/site-packages/selenium/webdriver/remote/webdriver.py", line 347, in execute
    self.error_handler.check_response(response)
  File "/opt/homebrew/lib/python3.11/site-packages/selenium/webdriver/remote/errorhandler.py", line 229, in check_response
    raise exception_class(message, screen, stacktrace)
selenium.common.exceptions.JavascriptException: Message: javascript error: {"status":32,"value":"Unable to locate an element with the xpath expression //span[text()='Voir d'autres profils'] because of the following error:\nSyntaxError: Failed to execute 'evaluate' on 'Document': The string '//span[text()='Voir d'autres profils']' is not a valid XPath expression."}
  (Session info: chrome=125.0.6422.61)
Stacktrace:
0   chromedriver                        0x0000000102e0e4a0 chromedriver + 4301984
1   chromedriver                        0x0000000102e06de8 chromedriver + 4271592
2   chromedriver                        0x0000000102a3819c chromedriver + 278940
3   chromedriver                        0x0000000102a3c66c chromedriver + 296556
4   chromedriver                        0x0000000102a3e4e8 chromedriver + 304360
5   chromedriver                        0x0000000102a3e560 chromedriver + 304480
6   chromedriver                        0x0000000102a7a3c0 chromedriver + 549824
7   chromedriver                        0x0000000102ab2c5c chromedriver + 781404
8   chromedriver                        0x0000000102a6f004 chromedriver + 503812
9   chromedriver                        0x0000000102a6f9ec chromedriver + 506348
10  chromedriver                        0x0000000102dd64e8 chromedriver + 4072680
11  chromedriver                        0x0000000102ddaf94 chromedriver + 4091796
12  chromedriver                        0x0000000102dbd72c chromedriver + 3970860
13  chromedriver                        0x0000000102ddb87c chromedriver + 4094076
14  chromedriver                        0x0000000102db06ac chromedriver + 3917484
15  chromedriver                        0x0000000102df8ae0 chromedriver + 4213472
16  chromedriver                        0x0000000102df8c5c chromedriver + 4213852
17  chromedriver                        0x0000000102e069e0 chromedriver + 4270560
18  libsystem_pthread.dylib             0x00000001992aaf94 _pthread_start + 136
19  libsystem_pthread.dylib             0x00000001992a5d34 thread_start + 8


During handling of the above exception, another exception occurred:

Traceback (most recent call last):
  File "/opt/homebrew/Cellar/python@3.11/3.11.7/Frameworks/Python.framework/Versions/3.11/lib/python3.11/logging/__init__.py", line 1110, in emit
    msg = self.format(record)
          ^^^^^^^^^^^^^^^^^^^
  File "/opt/homebrew/Cellar/python@3.11/3.11.7/Frameworks/Python.framework/Versions/3.11/lib/python3.11/logging/__init__.py", line 953, in format
    return fmt.format(record)
           ^^^^^^^^^^^^^^^^^^
  File "/opt/homebrew/Cellar/python@3.11/3.11.7/Frameworks/Python.framework/Versions/3.11/lib/python3.11/logging/__init__.py", line 687, in format
    record.message = record.getMessage()
                     ^^^^^^^^^^^^^^^^^^^
  File "/opt/homebrew/Cellar/python@3.11/3.11.7/Frameworks/Python.framework/Versions/3.11/lib/python3.11/logging/__init__.py", line 377, in getMessage
    msg = msg % self.args
          ~~~~^~~~~~~~~~~
TypeError: not all arguments converted during string formatting
Call stack:
  File "/Users/frederic/tinder-bot/navigate_bumble.py", line 74, in <module>
    navigate(driver, is_beautiful)
  File "/Users/frederic/tinder-bot/navigate_bumble.py", line 45, in navigate
    logger.info("No match found or error occurred: ", e)
Message: 'No match found or error occurred: '
Arguments: (JavascriptException(),)
2024-05-21 12:11:33,194 - INFO - Pressed Right Arrow Key.

2024-05-21 12:11:33,476 - INFO - Running extract_image_bumble.py...
2024-05-21 12:11:33,476 - INFO - Running script: /Users/frederic/tinder-bot/extract_image_bumble.py with args: []
2024-05-21 12:11:34,238 - INFO - Loading session...
Restoring session: 21e9521c4ab550bcf067ca9b1c334625, http://localhost:60305
Waiting for image element...
Image element found.
Image URL: https://us1.ecdn2.bumbcdn.com/p549/hidden?euri=AAAAAAAAAAIQTGUG3LNc5iYoWKnKZl-W0gAGEklVBvyS1MDJl6ENQrcoGIbTdNoKySgSWp7gnBlMxsA7kebWwqDFRIhEO2JtuJnV8hSziG4V.dBBjTuvGcJpI8smh6iSlWlxnL9pRS52HACXz7siTOlwyfOkD8Pyv4.kwbqpy9v89wLM5eoNiWWGZDz9iO5c0ICG3.VRB3kuxoWG80lhxBFnCXujuOvI&size=__size__&ck=b5b9bd4a4a841e29d744e099cce1fddb&wm_size=72x72&wm_offs=973x1124&h=Uhc&gs=j&t=42.1.0.0
Image téléchargée et convertie en JPEG : /Users/frederic/tinder-bot/profile_image_bumble.jpg
L'image est enregistrée à l'emplacement : /Users/frederic/tinder-bot/profile_image_bumble.jpg

2024-05-21 12:11:34,239 - ERROR - 
2024-05-21 12:11:34,239 - INFO - Running evaluation_bumble.py...
2024-05-21 12:11:34,239 - INFO - Running script: /Users/frederic/tinder-bot/evaluation_bumble.py with args: []
2024-05-21 12:11:38,675 - INFO - Evaluating image at: /Users/frederic/tinder-bot/profile_image_bumble.jpg
Detection result: {'request_id': '1716304295,507bfe92-1d5c-4a55-b9c1-beb2fa8c1cf1', 'time_used': 129, 'faces': [{'face_token': '591edda6d8292f2f193716789cdc99ee', 'face_rectangle': {'top': 161, 'left': 498, 'width': 150, 'height': 150}, 'attributes': {'facequality': {'value': 0.006, 'threshold': 70.1}}}], 'image_id': 'siyorAH+dRegcskrsyKLzQ==', 'face_num': 1}
Analyze result: {'time_used': 75, 'request_id': '1716304298,4c07a8fb-8325-4692-a99a-d8255b0b3558', 'faces': [{'attributes': {'gender': {'value': 'Female'}, 'age': {'value': 41}, 'beauty': {'female_score': 63.435, 'male_score': 65.573}}, 'face_rectangle': {'width': 150, 'top': 161, 'left': 498, 'height': 150}, 'face_token': '591edda6d8292f2f193716789cdc99ee'}]}
Image: Belle (Female Score: 63.435, Male Score: 65.573)

2024-05-21 12:11:38,676 - ERROR - 
2024-05-21 12:11:38,676 - INFO - Evaluation result: is_beautiful=True
2024-05-21 12:11:38,676 - INFO - Running navigate_bumble.py with is_beautiful=True...
2024-05-21 12:11:38,676 - INFO - Running script: /Users/frederic/tinder-bot/navigate_bumble.py with args: ['true']
2024-05-21 12:11:39,073 - INFO - 
2024-05-21 12:11:39,073 - ERROR - 2024-05-21 12:11:38,755 - INFO - is_beautiful: True
2024-05-21 12:11:38,755 - INFO - Loading session...
2024-05-21 12:11:38,755 - INFO - Restoring session: 21e9521c4ab550bcf067ca9b1c334625, http://localhost:60305
--- Logging error ---
Traceback (most recent call last):
  File "/Users/frederic/tinder-bot/navigate_bumble.py", line 38, in navigate
    match_button = WebDriverWait(driver, 5).until(
                   ^^^^^^^^^^^^^^^^^^^^^^^^^^^^^^^
  File "/opt/homebrew/lib/python3.11/site-packages/selenium/webdriver/support/wait.py", line 96, in until
    value = method(self._driver)
            ^^^^^^^^^^^^^^^^^^^^
  File "/opt/homebrew/lib/python3.11/site-packages/selenium/webdriver/support/expected_conditions.py", line 84, in _predicate
    return driver.find_element(*locator)
           ^^^^^^^^^^^^^^^^^^^^^^^^^^^^^
  File "/opt/homebrew/lib/python3.11/site-packages/selenium/webdriver/remote/webdriver.py", line 741, in find_element
    return self.execute(Command.FIND_ELEMENT, {"using": by, "value": value})["value"]
           ^^^^^^^^^^^^^^^^^^^^^^^^^^^^^^^^^^^^^^^^^^^^^^^^^^^^^^^^^^^^^^^^^
  File "/opt/homebrew/lib/python3.11/site-packages/selenium/webdriver/remote/webdriver.py", line 347, in execute
    self.error_handler.check_response(response)
  File "/opt/homebrew/lib/python3.11/site-packages/selenium/webdriver/remote/errorhandler.py", line 229, in check_response
    raise exception_class(message, screen, stacktrace)
selenium.common.exceptions.JavascriptException: Message: javascript error: {"status":32,"value":"Unable to locate an element with the xpath expression //span[text()='Voir d'autres profils'] because of the following error:\nSyntaxError: Failed to execute 'evaluate' on 'Document': The string '//span[text()='Voir d'autres profils']' is not a valid XPath expression."}
  (Session info: chrome=125.0.6422.61)
Stacktrace:
0   chromedriver                        0x0000000102e0e4a0 chromedriver + 4301984
1   chromedriver                        0x0000000102e06de8 chromedriver + 4271592
2   chromedriver                        0x0000000102a3819c chromedriver + 278940
3   chromedriver                        0x0000000102a3c66c chromedriver + 296556
4   chromedriver                        0x0000000102a3e4e8 chromedriver + 304360
5   chromedriver                        0x0000000102a3e560 chromedriver + 304480
6   chromedriver                        0x0000000102a7a3c0 chromedriver + 549824
7   chromedriver                        0x0000000102ab2c5c chromedriver + 781404
8   chromedriver                        0x0000000102a6f004 chromedriver + 503812
9   chromedriver                        0x0000000102a6f9ec chromedriver + 506348
10  chromedriver                        0x0000000102dd64e8 chromedriver + 4072680
11  chromedriver                        0x0000000102ddaf94 chromedriver + 4091796
12  chromedriver                        0x0000000102dbd72c chromedriver + 3970860
13  chromedriver                        0x0000000102ddb87c chromedriver + 4094076
14  chromedriver                        0x0000000102db06ac chromedriver + 3917484
15  chromedriver                        0x0000000102df8ae0 chromedriver + 4213472
16  chromedriver                        0x0000000102df8c5c chromedriver + 4213852
17  chromedriver                        0x0000000102e069e0 chromedriver + 4270560
18  libsystem_pthread.dylib             0x00000001992aaf94 _pthread_start + 136
19  libsystem_pthread.dylib             0x00000001992a5d34 thread_start + 8


During handling of the above exception, another exception occurred:

Traceback (most recent call last):
  File "/opt/homebrew/Cellar/python@3.11/3.11.7/Frameworks/Python.framework/Versions/3.11/lib/python3.11/logging/__init__.py", line 1110, in emit
    msg = self.format(record)
          ^^^^^^^^^^^^^^^^^^^
  File "/opt/homebrew/Cellar/python@3.11/3.11.7/Frameworks/Python.framework/Versions/3.11/lib/python3.11/logging/__init__.py", line 953, in format
    return fmt.format(record)
           ^^^^^^^^^^^^^^^^^^
  File "/opt/homebrew/Cellar/python@3.11/3.11.7/Frameworks/Python.framework/Versions/3.11/lib/python3.11/logging/__init__.py", line 687, in format
    record.message = record.getMessage()
                     ^^^^^^^^^^^^^^^^^^^
  File "/opt/homebrew/Cellar/python@3.11/3.11.7/Frameworks/Python.framework/Versions/3.11/lib/python3.11/logging/__init__.py", line 377, in getMessage
    msg = msg % self.args
          ~~~~^~~~~~~~~~~
TypeError: not all arguments converted during string formatting
Call stack:
  File "/Users/frederic/tinder-bot/navigate_bumble.py", line 74, in <module>
    navigate(driver, is_beautiful)
  File "/Users/frederic/tinder-bot/navigate_bumble.py", line 45, in navigate
    logger.info("No match found or error occurred: ", e)
Message: 'No match found or error occurred: '
Arguments: (JavascriptException(),)
2024-05-21 12:11:39,062 - INFO - Pressed Right Arrow Key.

2024-05-21 12:11:39,281 - INFO - Running extract_image_bumble.py...
2024-05-21 12:11:39,281 - INFO - Running script: /Users/frederic/tinder-bot/extract_image_bumble.py with args: []
2024-05-21 12:11:39,848 - INFO - Loading session...
Restoring session: 21e9521c4ab550bcf067ca9b1c334625, http://localhost:60305
Waiting for image element...
Image element found.
Image URL: https://us1.ecdn2.bumbcdn.com/p565/hidden?euri=AAAAAAAAAAIQDuCTvMxcdvZRJ58q-v8NtQB-EbRtysUBcFUY.SwwOTG-8nGjG7MBtP-1Bl4dyFJQ8wokvsQOV5D4DpaiS4ZrllTyeKDycJ23LHQdaEP1JK0WEI01grrYgFO7ZcP4Oye4rfnDZMe-namdjDY.mCus8DgrDLRGob3heTosvIAD9Azal0pQAqIktW.ePjLO.6yM1PvhMFHXWqBSJTSGXPkE&size=__size__&ck=e6484f87dc27d78b5c19534755c124b1&wm_size=72x72&wm_offs=973x1320&h=_MO&gs=j&t=42.1.0.0
Image téléchargée et convertie en JPEG : /Users/frederic/tinder-bot/profile_image_bumble.jpg
L'image est enregistrée à l'emplacement : /Users/frederic/tinder-bot/profile_image_bumble.jpg

2024-05-21 12:11:39,849 - ERROR - 
2024-05-21 12:11:39,849 - INFO - Running evaluation_bumble.py...
2024-05-21 12:11:39,849 - INFO - Running script: /Users/frederic/tinder-bot/evaluation_bumble.py with args: []
2024-05-21 12:11:44,325 - INFO - Evaluating image at: /Users/frederic/tinder-bot/profile_image_bumble.jpg
Detection result: {'request_id': '1716304301,8eca8d22-268c-4a8f-a9aa-2e951b963e82', 'time_used': 163, 'faces': [{'face_token': '87e031e401e641124776370d9311d32a', 'face_rectangle': {'top': 331, 'left': 367, 'width': 385, 'height': 385}, 'attributes': {'facequality': {'value': 0.296, 'threshold': 70.1}}}], 'image_id': '5MKHoPw6awLkyTMJhTXsoA==', 'face_num': 1}
Analyze result: {'time_used': 91, 'request_id': '1716304304,c085ea66-b162-4acf-8f0f-277c27fcc0a9', 'faces': [{'attributes': {'gender': {'value': 'Female'}, 'age': {'value': 23}, 'beauty': {'female_score': 79.662, 'male_score': 80.82}}, 'face_rectangle': {'width': 385, 'top': 331, 'left': 367, 'height': 385}, 'face_token': '87e031e401e641124776370d9311d32a'}]}
Image: Belle (Female Score: 79.662, Male Score: 80.82)

2024-05-21 12:11:44,325 - ERROR - 
2024-05-21 12:11:44,325 - INFO - Evaluation result: is_beautiful=True
2024-05-21 12:11:44,325 - INFO - Running navigate_bumble.py with is_beautiful=True...
2024-05-21 12:11:44,325 - INFO - Running script: /Users/frederic/tinder-bot/navigate_bumble.py with args: ['true']
2024-05-21 12:11:44,641 - INFO - 
2024-05-21 12:11:44,641 - ERROR - 2024-05-21 12:11:44,404 - INFO - is_beautiful: True
2024-05-21 12:11:44,404 - INFO - Loading session...
2024-05-21 12:11:44,404 - INFO - Restoring session: 21e9521c4ab550bcf067ca9b1c334625, http://localhost:60305
--- Logging error ---
Traceback (most recent call last):
  File "/Users/frederic/tinder-bot/navigate_bumble.py", line 38, in navigate
    match_button = WebDriverWait(driver, 5).until(
                   ^^^^^^^^^^^^^^^^^^^^^^^^^^^^^^^
  File "/opt/homebrew/lib/python3.11/site-packages/selenium/webdriver/support/wait.py", line 96, in until
    value = method(self._driver)
            ^^^^^^^^^^^^^^^^^^^^
  File "/opt/homebrew/lib/python3.11/site-packages/selenium/webdriver/support/expected_conditions.py", line 84, in _predicate
    return driver.find_element(*locator)
           ^^^^^^^^^^^^^^^^^^^^^^^^^^^^^
  File "/opt/homebrew/lib/python3.11/site-packages/selenium/webdriver/remote/webdriver.py", line 741, in find_element
    return self.execute(Command.FIND_ELEMENT, {"using": by, "value": value})["value"]
           ^^^^^^^^^^^^^^^^^^^^^^^^^^^^^^^^^^^^^^^^^^^^^^^^^^^^^^^^^^^^^^^^^
  File "/opt/homebrew/lib/python3.11/site-packages/selenium/webdriver/remote/webdriver.py", line 347, in execute
    self.error_handler.check_response(response)
  File "/opt/homebrew/lib/python3.11/site-packages/selenium/webdriver/remote/errorhandler.py", line 229, in check_response
    raise exception_class(message, screen, stacktrace)
selenium.common.exceptions.JavascriptException: Message: javascript error: {"status":32,"value":"Unable to locate an element with the xpath expression //span[text()='Voir d'autres profils'] because of the following error:\nSyntaxError: Failed to execute 'evaluate' on 'Document': The string '//span[text()='Voir d'autres profils']' is not a valid XPath expression."}
  (Session info: chrome=125.0.6422.61)
Stacktrace:
0   chromedriver                        0x0000000102e0e4a0 chromedriver + 4301984
1   chromedriver                        0x0000000102e06de8 chromedriver + 4271592
2   chromedriver                        0x0000000102a3819c chromedriver + 278940
3   chromedriver                        0x0000000102a3c66c chromedriver + 296556
4   chromedriver                        0x0000000102a3e4e8 chromedriver + 304360
5   chromedriver                        0x0000000102a3e560 chromedriver + 304480
6   chromedriver                        0x0000000102a7a3c0 chromedriver + 549824
7   chromedriver                        0x0000000102ab2c5c chromedriver + 781404
8   chromedriver                        0x0000000102a6f004 chromedriver + 503812
9   chromedriver                        0x0000000102a6f9ec chromedriver + 506348
10  chromedriver                        0x0000000102dd64e8 chromedriver + 4072680
11  chromedriver                        0x0000000102ddaf94 chromedriver + 4091796
12  chromedriver                        0x0000000102dbd72c chromedriver + 3970860
13  chromedriver                        0x0000000102ddb87c chromedriver + 4094076
14  chromedriver                        0x0000000102db06ac chromedriver + 3917484
15  chromedriver                        0x0000000102df8ae0 chromedriver + 4213472
16  chromedriver                        0x0000000102df8c5c chromedriver + 4213852
17  chromedriver                        0x0000000102e069e0 chromedriver + 4270560
18  libsystem_pthread.dylib             0x00000001992aaf94 _pthread_start + 136
19  libsystem_pthread.dylib             0x00000001992a5d34 thread_start + 8


During handling of the above exception, another exception occurred:

Traceback (most recent call last):
  File "/opt/homebrew/Cellar/python@3.11/3.11.7/Frameworks/Python.framework/Versions/3.11/lib/python3.11/logging/__init__.py", line 1110, in emit
    msg = self.format(record)
          ^^^^^^^^^^^^^^^^^^^
  File "/opt/homebrew/Cellar/python@3.11/3.11.7/Frameworks/Python.framework/Versions/3.11/lib/python3.11/logging/__init__.py", line 953, in format
    return fmt.format(record)
           ^^^^^^^^^^^^^^^^^^
  File "/opt/homebrew/Cellar/python@3.11/3.11.7/Frameworks/Python.framework/Versions/3.11/lib/python3.11/logging/__init__.py", line 687, in format
    record.message = record.getMessage()
                     ^^^^^^^^^^^^^^^^^^^
  File "/opt/homebrew/Cellar/python@3.11/3.11.7/Frameworks/Python.framework/Versions/3.11/lib/python3.11/logging/__init__.py", line 377, in getMessage
    msg = msg % self.args
          ~~~~^~~~~~~~~~~
TypeError: not all arguments converted during string formatting
Call stack:
  File "/Users/frederic/tinder-bot/navigate_bumble.py", line 74, in <module>
    navigate(driver, is_beautiful)
  File "/Users/frederic/tinder-bot/navigate_bumble.py", line 45, in navigate
    logger.info("No match found or error occurred: ", e)
Message: 'No match found or error occurred: '
Arguments: (JavascriptException(),)
2024-05-21 12:11:44,623 - INFO - Pressed Right Arrow Key.

2024-05-21 12:11:44,887 - INFO - Running extract_image_bumble.py...
2024-05-21 12:11:44,887 - INFO - Running script: /Users/frederic/tinder-bot/extract_image_bumble.py with args: []
2024-05-21 12:11:45,409 - INFO - Loading session...
Restoring session: 21e9521c4ab550bcf067ca9b1c334625, http://localhost:60305
Waiting for image element...
Image element found.
Image URL: https://us1.ecdn2.bumbcdn.com/p534/hidden?euri=AAAAAAAAAAIQVlaxf9DZ1YgFMEa-Ao2sFgCi.SQOeS3ouD1YJ15LEdirZFBi8EF6iR8l4XIPXV408J9RTai-YbYJOyhivN9TJhh28eGjPtZ9.Hkfj3txrf.iQS7LYJaT6ElewU5lrZGwaMulvEtnJwgbn5W0BVbiFUEqmz2fGdV0pUPAVR6H8jEP9yK95OImonS3RRPaePt5tsJQ2TvT5yrzRkJeMgtg&size=__size__&ck=5359718bfa8acd17c0fcf7b86278bd72&wm_size=72x72&wm_offs=823x1523&h=kT4&gs=j&t=42.1.0.0
Image téléchargée et convertie en JPEG : /Users/frederic/tinder-bot/profile_image_bumble.jpg
L'image est enregistrée à l'emplacement : /Users/frederic/tinder-bot/profile_image_bumble.jpg

2024-05-21 12:11:45,410 - ERROR - 
2024-05-21 12:11:45,410 - INFO - Running evaluation_bumble.py...
2024-05-21 12:11:45,410 - INFO - Running script: /Users/frederic/tinder-bot/evaluation_bumble.py with args: []
2024-05-21 12:11:49,683 - INFO - Evaluating image at: /Users/frederic/tinder-bot/profile_image_bumble.jpg
Detection result: {'request_id': '1716304306,8b3e7b16-6e1c-4937-a814-42be4269f828', 'time_used': 142, 'faces': [{'face_token': 'a5be48e2ad6582718c9bb97feb39ce94', 'face_rectangle': {'top': 464, 'left': 261, 'width': 293, 'height': 293}, 'attributes': {'facequality': {'value': 80.132, 'threshold': 70.1}}}], 'image_id': 'gabi/QmWFUKfcRRJNlRVQA==', 'face_num': 1}
Analyze result: {'time_used': 67, 'request_id': '1716304309,0998ece4-0cc1-49d6-859e-79d242c56c49', 'faces': [{'attributes': {'gender': {'value': 'Female'}, 'age': {'value': 31}, 'beauty': {'female_score': 71.605, 'male_score': 66.335}}, 'face_rectangle': {'width': 293, 'top': 464, 'left': 261, 'height': 293}, 'face_token': 'a5be48e2ad6582718c9bb97feb39ce94'}]}
Image: Belle (Female Score: 71.605, Male Score: 66.335)

2024-05-21 12:11:49,684 - ERROR - 
2024-05-21 12:11:49,684 - INFO - Evaluation result: is_beautiful=True
2024-05-21 12:11:49,684 - INFO - Running navigate_bumble.py with is_beautiful=True...
2024-05-21 12:11:49,684 - INFO - Running script: /Users/frederic/tinder-bot/navigate_bumble.py with args: ['true']
2024-05-21 12:11:50,082 - INFO - 
2024-05-21 12:11:50,083 - ERROR - 2024-05-21 12:11:49,764 - INFO - is_beautiful: True
2024-05-21 12:11:49,764 - INFO - Loading session...
2024-05-21 12:11:49,764 - INFO - Restoring session: 21e9521c4ab550bcf067ca9b1c334625, http://localhost:60305
--- Logging error ---
Traceback (most recent call last):
  File "/Users/frederic/tinder-bot/navigate_bumble.py", line 38, in navigate
    match_button = WebDriverWait(driver, 5).until(
                   ^^^^^^^^^^^^^^^^^^^^^^^^^^^^^^^
  File "/opt/homebrew/lib/python3.11/site-packages/selenium/webdriver/support/wait.py", line 96, in until
    value = method(self._driver)
            ^^^^^^^^^^^^^^^^^^^^
  File "/opt/homebrew/lib/python3.11/site-packages/selenium/webdriver/support/expected_conditions.py", line 84, in _predicate
    return driver.find_element(*locator)
           ^^^^^^^^^^^^^^^^^^^^^^^^^^^^^
  File "/opt/homebrew/lib/python3.11/site-packages/selenium/webdriver/remote/webdriver.py", line 741, in find_element
    return self.execute(Command.FIND_ELEMENT, {"using": by, "value": value})["value"]
           ^^^^^^^^^^^^^^^^^^^^^^^^^^^^^^^^^^^^^^^^^^^^^^^^^^^^^^^^^^^^^^^^^
  File "/opt/homebrew/lib/python3.11/site-packages/selenium/webdriver/remote/webdriver.py", line 347, in execute
    self.error_handler.check_response(response)
  File "/opt/homebrew/lib/python3.11/site-packages/selenium/webdriver/remote/errorhandler.py", line 229, in check_response
    raise exception_class(message, screen, stacktrace)
selenium.common.exceptions.JavascriptException: Message: javascript error: {"status":32,"value":"Unable to locate an element with the xpath expression //span[text()='Voir d'autres profils'] because of the following error:\nSyntaxError: Failed to execute 'evaluate' on 'Document': The string '//span[text()='Voir d'autres profils']' is not a valid XPath expression."}
  (Session info: chrome=125.0.6422.61)
Stacktrace:
0   chromedriver                        0x0000000102e0e4a0 chromedriver + 4301984
1   chromedriver                        0x0000000102e06de8 chromedriver + 4271592
2   chromedriver                        0x0000000102a3819c chromedriver + 278940
3   chromedriver                        0x0000000102a3c66c chromedriver + 296556
4   chromedriver                        0x0000000102a3e4e8 chromedriver + 304360
5   chromedriver                        0x0000000102a3e560 chromedriver + 304480
6   chromedriver                        0x0000000102a7a3c0 chromedriver + 549824
7   chromedriver                        0x0000000102ab2c5c chromedriver + 781404
8   chromedriver                        0x0000000102a6f004 chromedriver + 503812
9   chromedriver                        0x0000000102a6f9ec chromedriver + 506348
10  chromedriver                        0x0000000102dd64e8 chromedriver + 4072680
11  chromedriver                        0x0000000102ddaf94 chromedriver + 4091796
12  chromedriver                        0x0000000102dbd72c chromedriver + 3970860
13  chromedriver                        0x0000000102ddb87c chromedriver + 4094076
14  chromedriver                        0x0000000102db06ac chromedriver + 3917484
15  chromedriver                        0x0000000102df8ae0 chromedriver + 4213472
16  chromedriver                        0x0000000102df8c5c chromedriver + 4213852
17  chromedriver                        0x0000000102e069e0 chromedriver + 4270560
18  libsystem_pthread.dylib             0x00000001992aaf94 _pthread_start + 136
19  libsystem_pthread.dylib             0x00000001992a5d34 thread_start + 8


During handling of the above exception, another exception occurred:

Traceback (most recent call last):
  File "/opt/homebrew/Cellar/python@3.11/3.11.7/Frameworks/Python.framework/Versions/3.11/lib/python3.11/logging/__init__.py", line 1110, in emit
    msg = self.format(record)
          ^^^^^^^^^^^^^^^^^^^
  File "/opt/homebrew/Cellar/python@3.11/3.11.7/Frameworks/Python.framework/Versions/3.11/lib/python3.11/logging/__init__.py", line 953, in format
    return fmt.format(record)
           ^^^^^^^^^^^^^^^^^^
  File "/opt/homebrew/Cellar/python@3.11/3.11.7/Frameworks/Python.framework/Versions/3.11/lib/python3.11/logging/__init__.py", line 687, in format
    record.message = record.getMessage()
                     ^^^^^^^^^^^^^^^^^^^
  File "/opt/homebrew/Cellar/python@3.11/3.11.7/Frameworks/Python.framework/Versions/3.11/lib/python3.11/logging/__init__.py", line 377, in getMessage
    msg = msg % self.args
          ~~~~^~~~~~~~~~~
TypeError: not all arguments converted during string formatting
Call stack:
  File "/Users/frederic/tinder-bot/navigate_bumble.py", line 74, in <module>
    navigate(driver, is_beautiful)
  File "/Users/frederic/tinder-bot/navigate_bumble.py", line 45, in navigate
    logger.info("No match found or error occurred: ", e)
Message: 'No match found or error occurred: '
Arguments: (JavascriptException(),)
2024-05-21 12:11:50,070 - INFO - Pressed Right Arrow Key.

2024-05-21 12:11:50,288 - INFO - Running extract_image_bumble.py...
2024-05-21 12:11:50,288 - INFO - Running script: /Users/frederic/tinder-bot/extract_image_bumble.py with args: []
2024-05-21 12:11:50,750 - INFO - Loading session...
Restoring session: 21e9521c4ab550bcf067ca9b1c334625, http://localhost:60305
Waiting for image element...
Image element found.
Image URL: https://us1.ecdn2.bumbcdn.com/p526/hidden?euri=AAAAAAAAAAIQE0F1zfL6BAdv7x8GZd0TyAAjqCSF3z06xujvtxfbiBdjzpQTMOvW45Wbs0DTttWvXIlJxEQbjccV1MHzUHl-.CA817Ywf99sOmoolBIkfWIC1wBGD01OyTdofgx0zu1GvkwPo32LQ.fTASo1y5KrholJAuVg5VOZRyImlnkc7C6AbBMecBhMrrCRXCgrlf8RgASEP1zikeBtHH8UxABq&size=__size__&ck=1d87d3d751faa6b5c4c31a77a094b8ca&wm_size=72x72&wm_offs=823x1523&h=guv&gs=j&t=42.1.0.0
Image téléchargée et convertie en JPEG : /Users/frederic/tinder-bot/profile_image_bumble.jpg
L'image est enregistrée à l'emplacement : /Users/frederic/tinder-bot/profile_image_bumble.jpg

2024-05-21 12:11:50,750 - ERROR - 
2024-05-21 12:11:50,750 - INFO - Running evaluation_bumble.py...
2024-05-21 12:11:50,750 - INFO - Running script: /Users/frederic/tinder-bot/evaluation_bumble.py with args: []
2024-05-21 12:11:55,040 - INFO - Evaluating image at: /Users/frederic/tinder-bot/profile_image_bumble.jpg
Detection result: {'request_id': '1716304312,84cc6c6a-793d-4da9-8b8d-fc95a7157e0e', 'time_used': 120, 'faces': [{'face_token': 'be700c74166acfe1c05d55614dca2897', 'face_rectangle': {'top': 615, 'left': 408, 'width': 95, 'height': 95}, 'attributes': {'facequality': {'value': 91.568, 'threshold': 70.1}}}], 'image_id': 'GoBLEi7hYwSLUg7j/sy/BA==', 'face_num': 1}
Analyze result: {'time_used': 118, 'request_id': '1716304315,f0b460c1-e426-493a-ba1a-2460a22497de', 'faces': [{'attributes': {'gender': {'value': 'Female'}, 'age': {'value': 37}, 'beauty': {'female_score': 56.635, 'male_score': 52.876}}, 'face_rectangle': {'width': 95, 'top': 615, 'left': 408, 'height': 95}, 'face_token': 'be700c74166acfe1c05d55614dca2897'}]}
Image: Pas Belle (Female Score: 56.635, Male Score: 52.876)

2024-05-21 12:11:55,040 - ERROR - 
2024-05-21 12:11:55,040 - INFO - Evaluation result: is_beautiful=False
2024-05-21 12:11:55,040 - INFO - Running navigate_bumble.py with is_beautiful=False...
2024-05-21 12:11:55,040 - INFO - Running script: /Users/frederic/tinder-bot/navigate_bumble.py with args: ['false']
2024-05-21 12:11:55,488 - INFO - 
2024-05-21 12:11:55,488 - ERROR - 2024-05-21 12:11:55,123 - INFO - is_beautiful: False
2024-05-21 12:11:55,123 - INFO - Loading session...
2024-05-21 12:11:55,123 - INFO - Restoring session: 21e9521c4ab550bcf067ca9b1c334625, http://localhost:60305
--- Logging error ---
Traceback (most recent call last):
  File "/Users/frederic/tinder-bot/navigate_bumble.py", line 38, in navigate
    match_button = WebDriverWait(driver, 5).until(
                   ^^^^^^^^^^^^^^^^^^^^^^^^^^^^^^^
  File "/opt/homebrew/lib/python3.11/site-packages/selenium/webdriver/support/wait.py", line 96, in until
    value = method(self._driver)
            ^^^^^^^^^^^^^^^^^^^^
  File "/opt/homebrew/lib/python3.11/site-packages/selenium/webdriver/support/expected_conditions.py", line 84, in _predicate
    return driver.find_element(*locator)
           ^^^^^^^^^^^^^^^^^^^^^^^^^^^^^
  File "/opt/homebrew/lib/python3.11/site-packages/selenium/webdriver/remote/webdriver.py", line 741, in find_element
    return self.execute(Command.FIND_ELEMENT, {"using": by, "value": value})["value"]
           ^^^^^^^^^^^^^^^^^^^^^^^^^^^^^^^^^^^^^^^^^^^^^^^^^^^^^^^^^^^^^^^^^
  File "/opt/homebrew/lib/python3.11/site-packages/selenium/webdriver/remote/webdriver.py", line 347, in execute
    self.error_handler.check_response(response)
  File "/opt/homebrew/lib/python3.11/site-packages/selenium/webdriver/remote/errorhandler.py", line 229, in check_response
    raise exception_class(message, screen, stacktrace)
selenium.common.exceptions.JavascriptException: Message: javascript error: {"status":32,"value":"Unable to locate an element with the xpath expression //span[text()='Voir d'autres profils'] because of the following error:\nSyntaxError: Failed to execute 'evaluate' on 'Document': The string '//span[text()='Voir d'autres profils']' is not a valid XPath expression."}
  (Session info: chrome=125.0.6422.61)
Stacktrace:
0   chromedriver                        0x0000000102e0e4a0 chromedriver + 4301984
1   chromedriver                        0x0000000102e06de8 chromedriver + 4271592
2   chromedriver                        0x0000000102a3819c chromedriver + 278940
3   chromedriver                        0x0000000102a3c66c chromedriver + 296556
4   chromedriver                        0x0000000102a3e4e8 chromedriver + 304360
5   chromedriver                        0x0000000102a3e560 chromedriver + 304480
6   chromedriver                        0x0000000102a7a3c0 chromedriver + 549824
7   chromedriver                        0x0000000102ab2c5c chromedriver + 781404
8   chromedriver                        0x0000000102a6f004 chromedriver + 503812
9   chromedriver                        0x0000000102a6f9ec chromedriver + 506348
10  chromedriver                        0x0000000102dd64e8 chromedriver + 4072680
11  chromedriver                        0x0000000102ddaf94 chromedriver + 4091796
12  chromedriver                        0x0000000102dbd72c chromedriver + 3970860
13  chromedriver                        0x0000000102ddb87c chromedriver + 4094076
14  chromedriver                        0x0000000102db06ac chromedriver + 3917484
15  chromedriver                        0x0000000102df8ae0 chromedriver + 4213472
16  chromedriver                        0x0000000102df8c5c chromedriver + 4213852
17  chromedriver                        0x0000000102e069e0 chromedriver + 4270560
18  libsystem_pthread.dylib             0x00000001992aaf94 _pthread_start + 136
19  libsystem_pthread.dylib             0x00000001992a5d34 thread_start + 8


During handling of the above exception, another exception occurred:

Traceback (most recent call last):
  File "/opt/homebrew/Cellar/python@3.11/3.11.7/Frameworks/Python.framework/Versions/3.11/lib/python3.11/logging/__init__.py", line 1110, in emit
    msg = self.format(record)
          ^^^^^^^^^^^^^^^^^^^
  File "/opt/homebrew/Cellar/python@3.11/3.11.7/Frameworks/Python.framework/Versions/3.11/lib/python3.11/logging/__init__.py", line 953, in format
    return fmt.format(record)
           ^^^^^^^^^^^^^^^^^^
  File "/opt/homebrew/Cellar/python@3.11/3.11.7/Frameworks/Python.framework/Versions/3.11/lib/python3.11/logging/__init__.py", line 687, in format
    record.message = record.getMessage()
                     ^^^^^^^^^^^^^^^^^^^
  File "/opt/homebrew/Cellar/python@3.11/3.11.7/Frameworks/Python.framework/Versions/3.11/lib/python3.11/logging/__init__.py", line 377, in getMessage
    msg = msg % self.args
          ~~~~^~~~~~~~~~~
TypeError: not all arguments converted during string formatting
Call stack:
  File "/Users/frederic/tinder-bot/navigate_bumble.py", line 74, in <module>
    navigate(driver, is_beautiful)
  File "/Users/frederic/tinder-bot/navigate_bumble.py", line 45, in navigate
    logger.info("No match found or error occurred: ", e)
Message: 'No match found or error occurred: '
Arguments: (JavascriptException(),)
2024-05-21 12:11:55,478 - INFO - Pressed Left Arrow Key.

2024-05-21 12:11:55,711 - INFO - Running extract_image_bumble.py...
2024-05-21 12:11:55,711 - INFO - Running script: /Users/frederic/tinder-bot/extract_image_bumble.py with args: []
2024-05-21 12:11:56,673 - INFO - Loading session...
Restoring session: 21e9521c4ab550bcf067ca9b1c334625, http://localhost:60305
Waiting for image element...
Image element found.
Image URL: https://us1.ecdn2.bumbcdn.com/p524/hidden?euri=AAAAAAAAAAIQhg5NBaqpXv8hmKLgzsrlNQDZM0FqzihQ6NtekEUFfmc3nKqmoQ3c.itWymqMv3DO7JzLRNDBPcX-mTvtY5YPyR6PdqrWFtfl5jZ9N-0lSY3.SiydTGl30DBC9qiKpyNZV-ELnAy6rYhdj7ch9mLQp-clGkigkrLk1.iEJAEyv33n3oZSkJpROm0MN75b7f3ftkEHrMhgjaMEmrJMKNJU&size=__size__&ck=616ab8d6db75932bfc464af2eaf0b3bd&wm_size=72x72&wm_offs=973x1323&h=hs6&gs=j&t=42.1.0.0
Image téléchargée et convertie en JPEG : /Users/frederic/tinder-bot/profile_image_bumble.jpg
L'image est enregistrée à l'emplacement : /Users/frederic/tinder-bot/profile_image_bumble.jpg

2024-05-21 12:11:56,673 - ERROR - 
2024-05-21 12:11:56,673 - INFO - Running evaluation_bumble.py...
2024-05-21 12:11:56,673 - INFO - Running script: /Users/frederic/tinder-bot/evaluation_bumble.py with args: []
